root - ERROR - Error while using ARMA method on ship_pt: ZTRD, prod_hierarchy: TEST, part_number: CORONA
root - ERROR - Traceback (most recent call last):
  File "/Users/adityabharadwaj/Desktop/time-series-Apr10/time-series-forecasts/time-forecast-app/src/processing/process.py", line 116, in run
    rmse_arma, mape_arma, pred_arma = algo_obj.arma_calculate()
  File "/Users/adityabharadwaj/Desktop/time-series-Apr10/time-series-forecasts/time-forecast-app/src/processing/algorithms.py", line 274, in arma_calculate
    model_fit = model.fit(disp=0)
  File "/Users/adityabharadwaj/Dev/time-forecast-app/lib/python3.6/site-packages/statsmodels/tsa/arima_model.py", line 999, in fit
    callback=callback, **kwargs)
  File "/Users/adityabharadwaj/Dev/time-forecast-app/lib/python3.6/site-packages/statsmodels/base/model.py", line 526, in fit
    full_output=full_output)
  File "/Users/adityabharadwaj/Dev/time-forecast-app/lib/python3.6/site-packages/statsmodels/base/optimizer.py", line 218, in _fit
    hess=hessian)
  File "/Users/adityabharadwaj/Dev/time-forecast-app/lib/python3.6/site-packages/statsmodels/base/optimizer.py", line 440, in _fit_lbfgs
    **extra_kwargs)
  File "/Users/adityabharadwaj/Dev/time-forecast-app/lib/python3.6/site-packages/scipy/optimize/lbfgsb.py", line 199, in fmin_l_bfgs_b
    **opts)
  File "/Users/adityabharadwaj/Dev/time-forecast-app/lib/python3.6/site-packages/scipy/optimize/lbfgsb.py", line 345, in _minimize_lbfgsb
    f, g = func_and_grad(x)
  File "/Users/adityabharadwaj/Dev/time-forecast-app/lib/python3.6/site-packages/scipy/optimize/lbfgsb.py", line 290, in func_and_grad
    f = fun(x, *args)
  File "/Users/adityabharadwaj/Dev/time-forecast-app/lib/python3.6/site-packages/scipy/optimize/optimize.py", line 327, in function_wrapper
    return function(*(wrapper_args + args))
  File "/Users/adityabharadwaj/Dev/time-forecast-app/lib/python3.6/site-packages/statsmodels/base/model.py", line 500, in f
    return -self.loglike(params, *args) / nobs
  File "/Users/adityabharadwaj/Dev/time-forecast-app/lib/python3.6/site-packages/statsmodels/tsa/arima_model.py", line 810, in loglike
    return self.loglike_kalman(params, set_sigma2)
  File "/Users/adityabharadwaj/Dev/time-forecast-app/lib/python3.6/site-packages/statsmodels/tsa/arima_model.py", line 820, in loglike_kalman
    return KalmanFilter.loglike(params, self, set_sigma2)
  File "/Users/adityabharadwaj/Dev/time-forecast-app/lib/python3.6/site-packages/statsmodels/tsa/kalmanf/kalmanfilter.py", line 220, in loglike
    Z_mat, R_mat, T_mat)
  File "statsmodels/tsa/kalmanf/kalman_loglike.pyx", line 331, in statsmodels.tsa.kalmanf.kalman_loglike.kalman_loglike_double
  File "statsmodels/tsa/kalmanf/kalman_loglike.pyx", line 62, in statsmodels.tsa.kalmanf.kalman_loglike.kalman_filter_double
  File "<__array_function__ internals>", line 6, in pinv
  File "/Users/adityabharadwaj/Dev/time-forecast-app/lib/python3.6/site-packages/numpy/linalg/linalg.py", line 1961, in pinv
    u, s, vt = svd(a, full_matrices=False, hermitian=hermitian)
  File "<__array_function__ internals>", line 6, in svd
  File "/Users/adityabharadwaj/Dev/time-forecast-app/lib/python3.6/site-packages/numpy/linalg/linalg.py", line 1626, in svd
    u, s, vh = gufunc(a, signature=signature, extobj=extobj)
  File "/Users/adityabharadwaj/Dev/time-forecast-app/lib/python3.6/site-packages/numpy/linalg/linalg.py", line 106, in _raise_linalgerror_svd_nonconvergence
    raise LinAlgError("SVD did not converge")
numpy.linalg.LinAlgError: SVD did not converge

root - ERROR - Error while using ARMA method on ship_pt: ZTRD, prod_hierarchy: TEST, part_number: CORONA
root - ERROR - Traceback (most recent call last):
  File "/Users/adityabharadwaj/Desktop/time-series-Apr10/time-series-forecasts/time-forecast-app/src/processing/process.py", line 116, in run
    rmse_arma, mape_arma, pred_arma = algo_obj.arma_calculate()
  File "/Users/adityabharadwaj/Desktop/time-series-Apr10/time-series-forecasts/time-forecast-app/src/processing/algorithms.py", line 274, in arma_calculate
    model_fit = model.fit(disp=0)
  File "/Users/adityabharadwaj/Dev/time-forecast-app/lib/python3.6/site-packages/statsmodels/tsa/arima_model.py", line 999, in fit
    callback=callback, **kwargs)
  File "/Users/adityabharadwaj/Dev/time-forecast-app/lib/python3.6/site-packages/statsmodels/base/model.py", line 526, in fit
    full_output=full_output)
  File "/Users/adityabharadwaj/Dev/time-forecast-app/lib/python3.6/site-packages/statsmodels/base/optimizer.py", line 218, in _fit
    hess=hessian)
  File "/Users/adityabharadwaj/Dev/time-forecast-app/lib/python3.6/site-packages/statsmodels/base/optimizer.py", line 440, in _fit_lbfgs
    **extra_kwargs)
  File "/Users/adityabharadwaj/Dev/time-forecast-app/lib/python3.6/site-packages/scipy/optimize/lbfgsb.py", line 199, in fmin_l_bfgs_b
    **opts)
  File "/Users/adityabharadwaj/Dev/time-forecast-app/lib/python3.6/site-packages/scipy/optimize/lbfgsb.py", line 345, in _minimize_lbfgsb
    f, g = func_and_grad(x)
  File "/Users/adityabharadwaj/Dev/time-forecast-app/lib/python3.6/site-packages/scipy/optimize/lbfgsb.py", line 290, in func_and_grad
    f = fun(x, *args)
  File "/Users/adityabharadwaj/Dev/time-forecast-app/lib/python3.6/site-packages/scipy/optimize/optimize.py", line 327, in function_wrapper
    return function(*(wrapper_args + args))
  File "/Users/adityabharadwaj/Dev/time-forecast-app/lib/python3.6/site-packages/statsmodels/base/model.py", line 500, in f
    return -self.loglike(params, *args) / nobs
  File "/Users/adityabharadwaj/Dev/time-forecast-app/lib/python3.6/site-packages/statsmodels/tsa/arima_model.py", line 810, in loglike
    return self.loglike_kalman(params, set_sigma2)
  File "/Users/adityabharadwaj/Dev/time-forecast-app/lib/python3.6/site-packages/statsmodels/tsa/arima_model.py", line 820, in loglike_kalman
    return KalmanFilter.loglike(params, self, set_sigma2)
  File "/Users/adityabharadwaj/Dev/time-forecast-app/lib/python3.6/site-packages/statsmodels/tsa/kalmanf/kalmanfilter.py", line 220, in loglike
    Z_mat, R_mat, T_mat)
  File "statsmodels/tsa/kalmanf/kalman_loglike.pyx", line 331, in statsmodels.tsa.kalmanf.kalman_loglike.kalman_loglike_double
  File "statsmodels/tsa/kalmanf/kalman_loglike.pyx", line 62, in statsmodels.tsa.kalmanf.kalman_loglike.kalman_filter_double
  File "<__array_function__ internals>", line 6, in pinv
  File "/Users/adityabharadwaj/Dev/time-forecast-app/lib/python3.6/site-packages/numpy/linalg/linalg.py", line 1961, in pinv
    u, s, vt = svd(a, full_matrices=False, hermitian=hermitian)
  File "<__array_function__ internals>", line 6, in svd
  File "/Users/adityabharadwaj/Dev/time-forecast-app/lib/python3.6/site-packages/numpy/linalg/linalg.py", line 1626, in svd
    u, s, vh = gufunc(a, signature=signature, extobj=extobj)
  File "/Users/adityabharadwaj/Dev/time-forecast-app/lib/python3.6/site-packages/numpy/linalg/linalg.py", line 106, in _raise_linalgerror_svd_nonconvergence
    raise LinAlgError("SVD did not converge")
numpy.linalg.LinAlgError: SVD did not converge

django.request - ERROR - Internal Server Error: /process/181
Traceback (most recent call last):
  File "/Users/adityabharadwaj/Dev/time-forecast-app/lib/python3.6/site-packages/django/core/handlers/exception.py", line 34, in inner
    response = get_response(request)
  File "/Users/adityabharadwaj/Dev/time-forecast-app/lib/python3.6/site-packages/django/core/handlers/base.py", line 115, in _get_response
    response = self.process_exception_by_middleware(e, request)
  File "/Users/adityabharadwaj/Dev/time-forecast-app/lib/python3.6/site-packages/django/core/handlers/base.py", line 113, in _get_response
    response = wrapped_callback(request, *callback_args, **callback_kwargs)
  File "/Users/adityabharadwaj/Desktop/time-series-Apr10/time-series-forecasts/time-forecast-app/src/processing/views.py", line 14, in processing_view
    if Process.run(input):
  File "/Users/adityabharadwaj/Desktop/time-series-Apr10/time-series-forecasts/time-forecast-app/src/processing/process.py", line 244, in run
    'forecast.csv', output_file)
  File "/Users/adityabharadwaj/Dev/time-forecast-app/lib/python3.6/site-packages/django/db/models/fields/files.py", line 87, in save
    self.name = self.storage.save(name, content, max_length=self.field.max_length)
  File "/Users/adityabharadwaj/Dev/time-forecast-app/lib/python3.6/site-packages/django/core/files/storage.py", line 52, in save
    return self._save(name, content)
  File "/Users/adityabharadwaj/Dev/time-forecast-app/lib/python3.6/site-packages/storages/backends/s3boto3.py", line 547, in _save
    obj.upload_fileobj(content, ExtraArgs=params)
  File "/Users/adityabharadwaj/Dev/time-forecast-app/lib/python3.6/site-packages/boto3/s3/inject.py", line 621, in object_upload_fileobj
    ExtraArgs=ExtraArgs, Callback=Callback, Config=Config)
  File "/Users/adityabharadwaj/Dev/time-forecast-app/lib/python3.6/site-packages/boto3/s3/inject.py", line 539, in upload_fileobj
    return future.result()
  File "/Users/adityabharadwaj/Dev/time-forecast-app/lib/python3.6/site-packages/s3transfer/futures.py", line 106, in result
    return self._coordinator.result()
  File "/Users/adityabharadwaj/Dev/time-forecast-app/lib/python3.6/site-packages/s3transfer/futures.py", line 265, in result
    raise self._exception
  File "/Users/adityabharadwaj/Dev/time-forecast-app/lib/python3.6/site-packages/s3transfer/tasks.py", line 126, in __call__
    return self._execute_main(kwargs)
  File "/Users/adityabharadwaj/Dev/time-forecast-app/lib/python3.6/site-packages/s3transfer/tasks.py", line 150, in _execute_main
    return_value = self._main(**kwargs)
  File "/Users/adityabharadwaj/Dev/time-forecast-app/lib/python3.6/site-packages/s3transfer/upload.py", line 692, in _main
    client.put_object(Bucket=bucket, Key=key, Body=body, **extra_args)
  File "/Users/adityabharadwaj/Dev/time-forecast-app/lib/python3.6/site-packages/botocore/client.py", line 316, in _api_call
    return self._make_api_call(operation_name, kwargs)
  File "/Users/adityabharadwaj/Dev/time-forecast-app/lib/python3.6/site-packages/botocore/client.py", line 626, in _make_api_call
    raise error_class(parsed_response, operation_name)
botocore.exceptions.ClientError: An error occurred (BadDigest) when calling the PutObject operation (reached max retries: 4): The Content-MD5 you specified did not match what we received.
