root - ERROR - Error while using ARMA on ship_pt: ZTRD10037401, prod_hierarchy: ZTRD, part_number: 10037401
root - ERROR - Traceback (most recent call last):
  File "/home/aditya_user/time-forecast-app/processing/process.py", line 62, in run
    rmse, mape, pred = algo_obj.get_predictions_rmse_mape(algo_name)
  File "/home/aditya_user/time-forecast-app/processing/algorithms.py", line 136, in get_predictions_rmse_mape
    model_fit = model.fit(disp=0)
  File "/home/aditya_user/time-forecast-app/venv/lib/python3.7/site-packages/statsmodels/tsa/arima_model.py", line 986, in fit
    start_ar_lags)
  File "/home/aditya_user/time-forecast-app/venv/lib/python3.7/site-packages/statsmodels/tsa/arima_model.py", line 577, in _fit_start_params
    start_params = self._fit_start_params_hr(order, start_ar_lags)
  File "/home/aditya_user/time-forecast-app/venv/lib/python3.7/site-packages/statsmodels/tsa/arima_model.py", line 562, in _fit_start_params_hr
    raise ValueError("The computed initial MA coefficients are not "
ValueError: The computed initial MA coefficients are not invertible
You should induce invertibility, choose a different model order, or you can
pass your own start_params.

django.request - ERROR - Internal Server Error: /process/322
Traceback (most recent call last):
  File "/home/aditya_user/time-forecast-app/venv/lib/python3.7/site-packages/django/core/handlers/exception.py", line 34, in inner
    response = get_response(request)
  File "/home/aditya_user/time-forecast-app/venv/lib/python3.7/site-packages/django/core/handlers/base.py", line 115, in _get_response
    response = self.process_exception_by_middleware(e, request)
  File "/home/aditya_user/time-forecast-app/venv/lib/python3.7/site-packages/django/core/handlers/base.py", line 113, in _get_response
    response = wrapped_callback(request, *callback_args, **callback_kwargs)
  File "/home/aditya_user/time-forecast-app/venv/lib/python3.7/site-packages/django/contrib/auth/decorators.py", line 21, in _wrapped_view
    return view_func(request, *args, **kwargs)
  File "/home/aditya_user/time-forecast-app/processing/views.py", line 15, in processing_view
    if Process.run(input):
  File "/home/aditya_user/time-forecast-app/processing/process.py", line 250, in run
    top5 = algo_obj.rankTopAlgorithms(algo_obj.rmse_pred)
  File "/home/aditya_user/time-forecast-app/processing/algorithms.py", line 46, in rankTopAlgorithms
    min_rmse = min(rmse_list)
ValueError: min() arg is an empty sequence
django.request - WARNING - Not Found: /favicon.ico
django.security.DisallowedHost - ERROR - Invalid HTTP_HOST header: 'ip.ws.126.net:443'. You may need to add 'ip.ws.126.net' to ALLOWED_HOSTS.
django.request - WARNING - Bad Request: /
django.security.DisallowedHost - ERROR - Invalid HTTP_HOST header: '127.0.0.1'. You may need to add '127.0.0.1' to ALLOWED_HOSTS.
django.request - WARNING - Bad Request: /cgi-bin/mainfunction.cgi
django.request - WARNING - Not Found: /hudson
django.security.DisallowedHost - ERROR - Invalid HTTP_HOST header: 'li1038-174.members.linode.com'. You may need to add 'li1038-174.members.linode.com' to ALLOWED_HOSTS.
django.request - WARNING - Bad Request: /
django.request - WARNING - Not Found: /favicon.ico
django.request - WARNING - Not Found: /favicon.ico
django.request - WARNING - Not Found: /favicon.ico
django.request - WARNING - Not Found: /favicon.ico
django.request - WARNING - Not Found: /favicon.ico
django.request - WARNING - Not Found: /login/adityagator.github.io
django.request - WARNING - Not Found: /favicon.ico
django.request - WARNING - Not Found: /favicon.ico
django.request - WARNING - Not Found: /favicon.ico
django.request - WARNING - Not Found: /favicon.ico
django.request - WARNING - Not Found: /favicon.ico
django.request - WARNING - Not Found: /favicon.ico
django.request - WARNING - Not Found: /favicon.ico
root - ERROR - Exception raised during clustering:
root - ERROR - Traceback (most recent call last):
  File "/home/aditya_user/time-forecast-app/processing/cluster.py", line 18, in run
    raise Exception("Input file must contain at least 3 rows for clustering.")
Exception: Input file must contain at least 3 rows for clustering.

django.request - ERROR - Internal Server Error: /process/325
Traceback (most recent call last):
  File "/home/aditya_user/time-forecast-app/venv/lib/python3.7/site-packages/django/core/handlers/exception.py", line 34, in inner
    response = get_response(request)
  File "/home/aditya_user/time-forecast-app/venv/lib/python3.7/site-packages/django/core/handlers/base.py", line 115, in _get_response
    response = self.process_exception_by_middleware(e, request)
  File "/home/aditya_user/time-forecast-app/venv/lib/python3.7/site-packages/django/core/handlers/base.py", line 113, in _get_response
    response = wrapped_callback(request, *callback_args, **callback_kwargs)
  File "/home/aditya_user/time-forecast-app/venv/lib/python3.7/site-packages/django/contrib/auth/decorators.py", line 21, in _wrapped_view
    return view_func(request, *args, **kwargs)
  File "/home/aditya_user/time-forecast-app/processing/views.py", line 15, in processing_view
    if Process.run(input):
  File "/home/aditya_user/time-forecast-app/processing/process.py", line 44, in run
    vol_cluster, int_cluster, vol_count, int_count = Cluster.run(dict_data)
  File "/home/aditya_user/time-forecast-app/processing/cluster.py", line 81, in run
    return final_vol_dict, final_int_dict, vol_dict, int_dict
UnboundLocalError: local variable 'int_dict' referenced before assignment
django.request - WARNING - Not Found: /favicon.ico
root - ERROR - Error while using ARMA on ship_pt: ZTRD, prod_hierarchy: 1 A I E, part_number: 10030450
root - ERROR - Traceback (most recent call last):
  File "/home/aditya_user/time-forecast-app/processing/process.py", line 62, in run
    rmse, mape, pred = algo_obj.get_predictions_rmse_mape(algo_name)
  File "/home/aditya_user/time-forecast-app/processing/algorithms.py", line 136, in get_predictions_rmse_mape
    model_fit = model.fit(disp=0)
  File "/home/aditya_user/time-forecast-app/venv/lib/python3.7/site-packages/statsmodels/tsa/arima_model.py", line 999, in fit
    callback=callback, **kwargs)
  File "/home/aditya_user/time-forecast-app/venv/lib/python3.7/site-packages/statsmodels/base/model.py", line 526, in fit
    full_output=full_output)
  File "/home/aditya_user/time-forecast-app/venv/lib/python3.7/site-packages/statsmodels/base/optimizer.py", line 218, in _fit
    hess=hessian)
  File "/home/aditya_user/time-forecast-app/venv/lib/python3.7/site-packages/statsmodels/base/optimizer.py", line 440, in _fit_lbfgs
    **extra_kwargs)
  File "/home/aditya_user/time-forecast-app/venv/lib/python3.7/site-packages/scipy/optimize/lbfgsb.py", line 199, in fmin_l_bfgs_b
    **opts)
  File "/home/aditya_user/time-forecast-app/venv/lib/python3.7/site-packages/scipy/optimize/lbfgsb.py", line 345, in _minimize_lbfgsb
    f, g = func_and_grad(x)
  File "/home/aditya_user/time-forecast-app/venv/lib/python3.7/site-packages/scipy/optimize/lbfgsb.py", line 290, in func_and_grad
    f = fun(x, *args)
  File "/home/aditya_user/time-forecast-app/venv/lib/python3.7/site-packages/scipy/optimize/optimize.py", line 327, in function_wrapper
    return function(*(wrapper_args + args))
  File "/home/aditya_user/time-forecast-app/venv/lib/python3.7/site-packages/statsmodels/base/model.py", line 500, in f
    return -self.loglike(params, *args) / nobs
  File "/home/aditya_user/time-forecast-app/venv/lib/python3.7/site-packages/statsmodels/tsa/arima_model.py", line 810, in loglike
    return self.loglike_kalman(params, set_sigma2)
  File "/home/aditya_user/time-forecast-app/venv/lib/python3.7/site-packages/statsmodels/tsa/arima_model.py", line 820, in loglike_kalman
    return KalmanFilter.loglike(params, self, set_sigma2)
  File "/home/aditya_user/time-forecast-app/venv/lib/python3.7/site-packages/statsmodels/tsa/kalmanf/kalmanfilter.py", line 220, in loglike
    Z_mat, R_mat, T_mat)
  File "statsmodels/tsa/kalmanf/kalman_loglike.pyx", line 331, in statsmodels.tsa.kalmanf.kalman_loglike.kalman_loglike_double
  File "statsmodels/tsa/kalmanf/kalman_loglike.pyx", line 62, in statsmodels.tsa.kalmanf.kalman_loglike.kalman_filter_double
  File "<__array_function__ internals>", line 6, in pinv
  File "/home/aditya_user/time-forecast-app/venv/lib/python3.7/site-packages/numpy/linalg/linalg.py", line 1961, in pinv
    u, s, vt = svd(a, full_matrices=False, hermitian=hermitian)
  File "<__array_function__ internals>", line 6, in svd
  File "/home/aditya_user/time-forecast-app/venv/lib/python3.7/site-packages/numpy/linalg/linalg.py", line 1626, in svd
    u, s, vh = gufunc(a, signature=signature, extobj=extobj)
  File "/home/aditya_user/time-forecast-app/venv/lib/python3.7/site-packages/numpy/linalg/linalg.py", line 106, in _raise_linalgerror_svd_nonconvergence
    raise LinAlgError("SVD did not converge")
numpy.linalg.LinAlgError: SVD did not converge

django.request - WARNING - Not Found: /favicon.ico
django.request - WARNING - Not Found: /favicon.ico
root - ERROR - Error while using ARMA on ship_pt: ZTRD, prod_hierarchy: 1 A I E, part_number: 10030450
root - ERROR - Traceback (most recent call last):
  File "/home/aditya_user/time-forecast-app/processing/process.py", line 62, in run
    rmse, mape, pred = algo_obj.get_predictions_rmse_mape(algo_name)
  File "/home/aditya_user/time-forecast-app/processing/algorithms.py", line 136, in get_predictions_rmse_mape
    model_fit = model.fit(disp=0)
  File "/home/aditya_user/time-forecast-app/venv/lib/python3.7/site-packages/statsmodels/tsa/arima_model.py", line 999, in fit
    callback=callback, **kwargs)
  File "/home/aditya_user/time-forecast-app/venv/lib/python3.7/site-packages/statsmodels/base/model.py", line 526, in fit
    full_output=full_output)
  File "/home/aditya_user/time-forecast-app/venv/lib/python3.7/site-packages/statsmodels/base/optimizer.py", line 218, in _fit
    hess=hessian)
  File "/home/aditya_user/time-forecast-app/venv/lib/python3.7/site-packages/statsmodels/base/optimizer.py", line 440, in _fit_lbfgs
    **extra_kwargs)
  File "/home/aditya_user/time-forecast-app/venv/lib/python3.7/site-packages/scipy/optimize/lbfgsb.py", line 199, in fmin_l_bfgs_b
    **opts)
  File "/home/aditya_user/time-forecast-app/venv/lib/python3.7/site-packages/scipy/optimize/lbfgsb.py", line 345, in _minimize_lbfgsb
    f, g = func_and_grad(x)
  File "/home/aditya_user/time-forecast-app/venv/lib/python3.7/site-packages/scipy/optimize/lbfgsb.py", line 290, in func_and_grad
    f = fun(x, *args)
  File "/home/aditya_user/time-forecast-app/venv/lib/python3.7/site-packages/scipy/optimize/optimize.py", line 327, in function_wrapper
    return function(*(wrapper_args + args))
  File "/home/aditya_user/time-forecast-app/venv/lib/python3.7/site-packages/statsmodels/base/model.py", line 500, in f
    return -self.loglike(params, *args) / nobs
  File "/home/aditya_user/time-forecast-app/venv/lib/python3.7/site-packages/statsmodels/tsa/arima_model.py", line 810, in loglike
    return self.loglike_kalman(params, set_sigma2)
  File "/home/aditya_user/time-forecast-app/venv/lib/python3.7/site-packages/statsmodels/tsa/arima_model.py", line 820, in loglike_kalman
    return KalmanFilter.loglike(params, self, set_sigma2)
  File "/home/aditya_user/time-forecast-app/venv/lib/python3.7/site-packages/statsmodels/tsa/kalmanf/kalmanfilter.py", line 220, in loglike
    Z_mat, R_mat, T_mat)
  File "statsmodels/tsa/kalmanf/kalman_loglike.pyx", line 331, in statsmodels.tsa.kalmanf.kalman_loglike.kalman_loglike_double
  File "statsmodels/tsa/kalmanf/kalman_loglike.pyx", line 62, in statsmodels.tsa.kalmanf.kalman_loglike.kalman_filter_double
  File "<__array_function__ internals>", line 6, in pinv
  File "/home/aditya_user/time-forecast-app/venv/lib/python3.7/site-packages/numpy/linalg/linalg.py", line 1961, in pinv
    u, s, vt = svd(a, full_matrices=False, hermitian=hermitian)
  File "<__array_function__ internals>", line 6, in svd
  File "/home/aditya_user/time-forecast-app/venv/lib/python3.7/site-packages/numpy/linalg/linalg.py", line 1626, in svd
    u, s, vh = gufunc(a, signature=signature, extobj=extobj)
  File "/home/aditya_user/time-forecast-app/venv/lib/python3.7/site-packages/numpy/linalg/linalg.py", line 106, in _raise_linalgerror_svd_nonconvergence
    raise LinAlgError("SVD did not converge")
numpy.linalg.LinAlgError: SVD did not converge

django.request - WARNING - Not Found: /favicon.ico
django.request - WARNING - Not Found: /favicon.ico
django.request - WARNING - Not Found: /favicon.ico
django.request - WARNING - Not Found: /favicon.ico
django.request - ERROR - Internal Server Error: /process/329
Traceback (most recent call last):
  File "/home/aditya_user/time-forecast-app/venv/lib/python3.7/site-packages/django/core/handlers/exception.py", line 34, in inner
    response = get_response(request)
  File "/home/aditya_user/time-forecast-app/venv/lib/python3.7/site-packages/django/core/handlers/base.py", line 115, in _get_response
    response = self.process_exception_by_middleware(e, request)
  File "/home/aditya_user/time-forecast-app/venv/lib/python3.7/site-packages/django/core/handlers/base.py", line 113, in _get_response
    response = wrapped_callback(request, *callback_args, **callback_kwargs)
  File "/home/aditya_user/time-forecast-app/venv/lib/python3.7/site-packages/django/contrib/auth/decorators.py", line 21, in _wrapped_view
    return view_func(request, *args, **kwargs)
  File "/home/aditya_user/time-forecast-app/processing/views.py", line 15, in processing_view
    if Process.run(input):
  File "/home/aditya_user/time-forecast-app/processing/process.py", line 34, in run
    dict_data = FileOperations.read_file(file=input_file)
  File "/home/aditya_user/time-forecast-app/processing/file_operations.py", line 14, in read_file
    data = list(csv_reader)
  File "/usr/lib/python3.7/codecs.py", line 322, in decode
    (result, consumed) = self._buffer_decode(data, self.errors, final)
UnicodeDecodeError: 'utf-8' codec can't decode byte 0xe3 in position 14: invalid continuation byte
django.request - ERROR - Internal Server Error: /process/330
Traceback (most recent call last):
  File "/home/aditya_user/time-forecast-app/venv/lib/python3.7/site-packages/django/core/handlers/exception.py", line 34, in inner
    response = get_response(request)
  File "/home/aditya_user/time-forecast-app/venv/lib/python3.7/site-packages/django/core/handlers/base.py", line 115, in _get_response
    response = self.process_exception_by_middleware(e, request)
  File "/home/aditya_user/time-forecast-app/venv/lib/python3.7/site-packages/django/core/handlers/base.py", line 113, in _get_response
    response = wrapped_callback(request, *callback_args, **callback_kwargs)
  File "/home/aditya_user/time-forecast-app/venv/lib/python3.7/site-packages/django/contrib/auth/decorators.py", line 21, in _wrapped_view
    return view_func(request, *args, **kwargs)
  File "/home/aditya_user/time-forecast-app/processing/views.py", line 15, in processing_view
    if Process.run(input):
  File "/home/aditya_user/time-forecast-app/processing/process.py", line 34, in run
    dict_data = FileOperations.read_file(file=input_file)
  File "/home/aditya_user/time-forecast-app/processing/file_operations.py", line 14, in read_file
    data = list(csv_reader)
  File "/usr/lib/python3.7/codecs.py", line 322, in decode
    (result, consumed) = self._buffer_decode(data, self.errors, final)
UnicodeDecodeError: 'utf-8' codec can't decode byte 0xe3 in position 14: invalid continuation byte
django.request - ERROR - Internal Server Error: /process/331
Traceback (most recent call last):
  File "/home/aditya_user/time-forecast-app/venv/lib/python3.7/site-packages/django/core/handlers/exception.py", line 34, in inner
    response = get_response(request)
  File "/home/aditya_user/time-forecast-app/venv/lib/python3.7/site-packages/django/core/handlers/base.py", line 115, in _get_response
    response = self.process_exception_by_middleware(e, request)
  File "/home/aditya_user/time-forecast-app/venv/lib/python3.7/site-packages/django/core/handlers/base.py", line 113, in _get_response
    response = wrapped_callback(request, *callback_args, **callback_kwargs)
  File "/home/aditya_user/time-forecast-app/venv/lib/python3.7/site-packages/django/contrib/auth/decorators.py", line 21, in _wrapped_view
    return view_func(request, *args, **kwargs)
  File "/home/aditya_user/time-forecast-app/processing/views.py", line 15, in processing_view
    if Process.run(input):
  File "/home/aditya_user/time-forecast-app/processing/process.py", line 34, in run
    dict_data = FileOperations.read_file(file=input_file)
  File "/home/aditya_user/time-forecast-app/processing/file_operations.py", line 14, in read_file
    data = list(csv_reader)
  File "/usr/lib/python3.7/codecs.py", line 322, in decode
    (result, consumed) = self._buffer_decode(data, self.errors, final)
UnicodeDecodeError: 'utf-8' codec can't decode byte 0xe3 in position 14: invalid continuation byte
django.request - WARNING - Not Found: /favicon.ico
django.request - ERROR - Internal Server Error: /process/332
Traceback (most recent call last):
  File "/home/aditya_user/time-forecast-app/venv/lib/python3.7/site-packages/django/core/handlers/exception.py", line 34, in inner
    response = get_response(request)
  File "/home/aditya_user/time-forecast-app/venv/lib/python3.7/site-packages/django/core/handlers/base.py", line 115, in _get_response
    response = self.process_exception_by_middleware(e, request)
  File "/home/aditya_user/time-forecast-app/venv/lib/python3.7/site-packages/django/core/handlers/base.py", line 113, in _get_response
    response = wrapped_callback(request, *callback_args, **callback_kwargs)
  File "/home/aditya_user/time-forecast-app/venv/lib/python3.7/site-packages/django/contrib/auth/decorators.py", line 21, in _wrapped_view
    return view_func(request, *args, **kwargs)
  File "/home/aditya_user/time-forecast-app/processing/views.py", line 15, in processing_view
    if Process.run(input):
  File "/home/aditya_user/time-forecast-app/processing/process.py", line 34, in run
    dict_data = FileOperations.read_file(file=input_file)
  File "/home/aditya_user/time-forecast-app/processing/file_operations.py", line 14, in read_file
    data = list(csv_reader)
  File "/usr/lib/python3.7/codecs.py", line 322, in decode
    (result, consumed) = self._buffer_decode(data, self.errors, final)
UnicodeDecodeError: 'utf-8' codec can't decode byte 0xe3 in position 14: invalid continuation byte
django.request - WARNING - Not Found: /favicon.ico
django.request - ERROR - Internal Server Error: /process/333
Traceback (most recent call last):
  File "/home/aditya_user/time-forecast-app/venv/lib/python3.7/site-packages/django/core/handlers/exception.py", line 34, in inner
    response = get_response(request)
  File "/home/aditya_user/time-forecast-app/venv/lib/python3.7/site-packages/django/core/handlers/base.py", line 115, in _get_response
    response = self.process_exception_by_middleware(e, request)
  File "/home/aditya_user/time-forecast-app/venv/lib/python3.7/site-packages/django/core/handlers/base.py", line 113, in _get_response
    response = wrapped_callback(request, *callback_args, **callback_kwargs)
  File "/home/aditya_user/time-forecast-app/venv/lib/python3.7/site-packages/django/contrib/auth/decorators.py", line 21, in _wrapped_view
    return view_func(request, *args, **kwargs)
  File "/home/aditya_user/time-forecast-app/processing/views.py", line 15, in processing_view
    if Process.run(input):
  File "/home/aditya_user/time-forecast-app/processing/process.py", line 34, in run
    dict_data = FileOperations.read_file(file=input_file)
  File "/home/aditya_user/time-forecast-app/processing/file_operations.py", line 14, in read_file
    data = list(csv_reader)
  File "/usr/lib/python3.7/codecs.py", line 322, in decode
    (result, consumed) = self._buffer_decode(data, self.errors, final)
UnicodeDecodeError: 'utf-8' codec can't decode byte 0xe3 in position 14: invalid continuation byte
root - ERROR - Error while using ARMA on ship_pt: ZTRD, prod_hierarchy: 1 A I E, part_number: 10030450
root - ERROR - Traceback (most recent call last):
  File "/home/aditya_user/time-forecast-app/processing/process.py", line 62, in run
    rmse, mape, pred = algo_obj.get_predictions_rmse_mape(algo_name)
  File "/home/aditya_user/time-forecast-app/processing/algorithms.py", line 136, in get_predictions_rmse_mape
    model_fit = model.fit(disp=0)
  File "/home/aditya_user/time-forecast-app/venv/lib/python3.7/site-packages/statsmodels/tsa/arima_model.py", line 999, in fit
    callback=callback, **kwargs)
  File "/home/aditya_user/time-forecast-app/venv/lib/python3.7/site-packages/statsmodels/base/model.py", line 526, in fit
    full_output=full_output)
  File "/home/aditya_user/time-forecast-app/venv/lib/python3.7/site-packages/statsmodels/base/optimizer.py", line 218, in _fit
    hess=hessian)
  File "/home/aditya_user/time-forecast-app/venv/lib/python3.7/site-packages/statsmodels/base/optimizer.py", line 440, in _fit_lbfgs
    **extra_kwargs)
  File "/home/aditya_user/time-forecast-app/venv/lib/python3.7/site-packages/scipy/optimize/lbfgsb.py", line 199, in fmin_l_bfgs_b
    **opts)
  File "/home/aditya_user/time-forecast-app/venv/lib/python3.7/site-packages/scipy/optimize/lbfgsb.py", line 345, in _minimize_lbfgsb
    f, g = func_and_grad(x)
  File "/home/aditya_user/time-forecast-app/venv/lib/python3.7/site-packages/scipy/optimize/lbfgsb.py", line 290, in func_and_grad
    f = fun(x, *args)
  File "/home/aditya_user/time-forecast-app/venv/lib/python3.7/site-packages/scipy/optimize/optimize.py", line 327, in function_wrapper
    return function(*(wrapper_args + args))
  File "/home/aditya_user/time-forecast-app/venv/lib/python3.7/site-packages/statsmodels/base/model.py", line 500, in f
    return -self.loglike(params, *args) / nobs
  File "/home/aditya_user/time-forecast-app/venv/lib/python3.7/site-packages/statsmodels/tsa/arima_model.py", line 810, in loglike
    return self.loglike_kalman(params, set_sigma2)
  File "/home/aditya_user/time-forecast-app/venv/lib/python3.7/site-packages/statsmodels/tsa/arima_model.py", line 820, in loglike_kalman
    return KalmanFilter.loglike(params, self, set_sigma2)
  File "/home/aditya_user/time-forecast-app/venv/lib/python3.7/site-packages/statsmodels/tsa/kalmanf/kalmanfilter.py", line 220, in loglike
    Z_mat, R_mat, T_mat)
  File "statsmodels/tsa/kalmanf/kalman_loglike.pyx", line 331, in statsmodels.tsa.kalmanf.kalman_loglike.kalman_loglike_double
  File "statsmodels/tsa/kalmanf/kalman_loglike.pyx", line 62, in statsmodels.tsa.kalmanf.kalman_loglike.kalman_filter_double
  File "<__array_function__ internals>", line 6, in pinv
  File "/home/aditya_user/time-forecast-app/venv/lib/python3.7/site-packages/numpy/linalg/linalg.py", line 1961, in pinv
    u, s, vt = svd(a, full_matrices=False, hermitian=hermitian)
  File "<__array_function__ internals>", line 6, in svd
  File "/home/aditya_user/time-forecast-app/venv/lib/python3.7/site-packages/numpy/linalg/linalg.py", line 1626, in svd
    u, s, vh = gufunc(a, signature=signature, extobj=extobj)
  File "/home/aditya_user/time-forecast-app/venv/lib/python3.7/site-packages/numpy/linalg/linalg.py", line 106, in _raise_linalgerror_svd_nonconvergence
    raise LinAlgError("SVD did not converge")
numpy.linalg.LinAlgError: SVD did not converge

root - ERROR - Error while using ARMA on ship_pt: ZTRD, prod_hierarchy: 1 A I E, part_number: 10030450
root - ERROR - Traceback (most recent call last):
  File "/home/aditya_user/time-forecast-app/processing/process.py", line 62, in run
    rmse, mape, pred = algo_obj.get_predictions_rmse_mape(algo_name)
  File "/home/aditya_user/time-forecast-app/processing/algorithms.py", line 136, in get_predictions_rmse_mape
    model_fit = model.fit(disp=0)
  File "/home/aditya_user/time-forecast-app/venv/lib/python3.7/site-packages/statsmodels/tsa/arima_model.py", line 999, in fit
    callback=callback, **kwargs)
  File "/home/aditya_user/time-forecast-app/venv/lib/python3.7/site-packages/statsmodels/base/model.py", line 526, in fit
    full_output=full_output)
  File "/home/aditya_user/time-forecast-app/venv/lib/python3.7/site-packages/statsmodels/base/optimizer.py", line 218, in _fit
    hess=hessian)
  File "/home/aditya_user/time-forecast-app/venv/lib/python3.7/site-packages/statsmodels/base/optimizer.py", line 440, in _fit_lbfgs
    **extra_kwargs)
  File "/home/aditya_user/time-forecast-app/venv/lib/python3.7/site-packages/scipy/optimize/lbfgsb.py", line 199, in fmin_l_bfgs_b
    **opts)
  File "/home/aditya_user/time-forecast-app/venv/lib/python3.7/site-packages/scipy/optimize/lbfgsb.py", line 345, in _minimize_lbfgsb
    f, g = func_and_grad(x)
  File "/home/aditya_user/time-forecast-app/venv/lib/python3.7/site-packages/scipy/optimize/lbfgsb.py", line 290, in func_and_grad
    f = fun(x, *args)
  File "/home/aditya_user/time-forecast-app/venv/lib/python3.7/site-packages/scipy/optimize/optimize.py", line 327, in function_wrapper
    return function(*(wrapper_args + args))
  File "/home/aditya_user/time-forecast-app/venv/lib/python3.7/site-packages/statsmodels/base/model.py", line 500, in f
    return -self.loglike(params, *args) / nobs
  File "/home/aditya_user/time-forecast-app/venv/lib/python3.7/site-packages/statsmodels/tsa/arima_model.py", line 810, in loglike
    return self.loglike_kalman(params, set_sigma2)
  File "/home/aditya_user/time-forecast-app/venv/lib/python3.7/site-packages/statsmodels/tsa/arima_model.py", line 820, in loglike_kalman
    return KalmanFilter.loglike(params, self, set_sigma2)
  File "/home/aditya_user/time-forecast-app/venv/lib/python3.7/site-packages/statsmodels/tsa/kalmanf/kalmanfilter.py", line 220, in loglike
    Z_mat, R_mat, T_mat)
  File "statsmodels/tsa/kalmanf/kalman_loglike.pyx", line 331, in statsmodels.tsa.kalmanf.kalman_loglike.kalman_loglike_double
  File "statsmodels/tsa/kalmanf/kalman_loglike.pyx", line 62, in statsmodels.tsa.kalmanf.kalman_loglike.kalman_filter_double
  File "<__array_function__ internals>", line 6, in pinv
  File "/home/aditya_user/time-forecast-app/venv/lib/python3.7/site-packages/numpy/linalg/linalg.py", line 1961, in pinv
    u, s, vt = svd(a, full_matrices=False, hermitian=hermitian)
  File "<__array_function__ internals>", line 6, in svd
  File "/home/aditya_user/time-forecast-app/venv/lib/python3.7/site-packages/numpy/linalg/linalg.py", line 1626, in svd
    u, s, vh = gufunc(a, signature=signature, extobj=extobj)
  File "/home/aditya_user/time-forecast-app/venv/lib/python3.7/site-packages/numpy/linalg/linalg.py", line 106, in _raise_linalgerror_svd_nonconvergence
    raise LinAlgError("SVD did not converge")
numpy.linalg.LinAlgError: SVD did not converge

root - ERROR - Error while using ARMA on ship_pt: ZTRD, prod_hierarchy: 9 Z Z Z, part_number: 30026783
root - ERROR - Traceback (most recent call last):
  File "/home/aditya_user/time-forecast-app/processing/process.py", line 62, in run
    rmse, mape, pred = algo_obj.get_predictions_rmse_mape(algo_name)
  File "/home/aditya_user/time-forecast-app/processing/algorithms.py", line 136, in get_predictions_rmse_mape
    model_fit = model.fit(disp=0)
  File "/home/aditya_user/time-forecast-app/venv/lib/python3.7/site-packages/statsmodels/tsa/arima_model.py", line 986, in fit
    start_ar_lags)
  File "/home/aditya_user/time-forecast-app/venv/lib/python3.7/site-packages/statsmodels/tsa/arima_model.py", line 577, in _fit_start_params
    start_params = self._fit_start_params_hr(order, start_ar_lags)
  File "/home/aditya_user/time-forecast-app/venv/lib/python3.7/site-packages/statsmodels/tsa/arima_model.py", line 512, in _fit_start_params_hr
    mod = ar_select_order(endog, maxlag, trend='n').model
  File "/home/aditya_user/time-forecast-app/venv/lib/python3.7/site-packages/statsmodels/tsa/ar_model.py", line 2297, in ar_select_order
    missing=missing)
  File "/home/aditya_user/time-forecast-app/venv/lib/python3.7/site-packages/statsmodels/tsa/ar_model.py", line 184, in __init__
    self._setup_regressors()
  File "/home/aditya_user/time-forecast-app/venv/lib/python3.7/site-packages/statsmodels/tsa/ar_model.py", line 281, in _setup_regressors
    nobs))
ValueError: The model specification cannot be estimated. The model contains 7 regressors (0 trend, 0 seasonal, 7 lags) but after adjustment for hold_back and creation of the lags, there are only 5 data points available to estimate parameters.

root - ERROR - Error while using MOVING AVERAGE on ship_pt: ZTRD, prod_hierarchy: 9 Z Z Z, part_number: 30026789
root - ERROR - Traceback (most recent call last):
  File "/home/aditya_user/time-forecast-app/processing/process.py", line 62, in run
    rmse, mape, pred = algo_obj.get_predictions_rmse_mape(algo_name)
  File "/home/aditya_user/time-forecast-app/processing/algorithms.py", line 148, in get_predictions_rmse_mape
    rmse, mape = self.rmse_mape(forecast)
  File "/home/aditya_user/time-forecast-app/processing/algorithms.py", line 98, in rmse_mape
    return round(math.sqrt(mean_squared_error(self.test, predicted)),2), round(self.mean_absolute_percentage_error(
  File "/home/aditya_user/time-forecast-app/venv/lib/python3.7/site-packages/sklearn/metrics/_regression.py", line 252, in mean_squared_error
    y_true, y_pred, multioutput)
  File "/home/aditya_user/time-forecast-app/venv/lib/python3.7/site-packages/sklearn/metrics/_regression.py", line 86, in _check_reg_targets
    y_pred = check_array(y_pred, ensure_2d=False, dtype=dtype)
  File "/home/aditya_user/time-forecast-app/venv/lib/python3.7/site-packages/sklearn/utils/validation.py", line 578, in check_array
    allow_nan=force_all_finite == 'allow-nan')
  File "/home/aditya_user/time-forecast-app/venv/lib/python3.7/site-packages/sklearn/utils/validation.py", line 60, in _assert_all_finite
    msg_dtype if msg_dtype is not None else X.dtype)
ValueError: Input contains NaN, infinity or a value too large for dtype('float64').

root - ERROR - Error while using ARMA on ship_pt: ZTRD, prod_hierarchy: 9 Z Z Z, part_number: 30026789
root - ERROR - Traceback (most recent call last):
  File "/home/aditya_user/time-forecast-app/processing/process.py", line 62, in run
    rmse, mape, pred = algo_obj.get_predictions_rmse_mape(algo_name)
  File "/home/aditya_user/time-forecast-app/processing/algorithms.py", line 136, in get_predictions_rmse_mape
    model_fit = model.fit(disp=0)
  File "/home/aditya_user/time-forecast-app/venv/lib/python3.7/site-packages/statsmodels/tsa/arima_model.py", line 986, in fit
    start_ar_lags)
  File "/home/aditya_user/time-forecast-app/venv/lib/python3.7/site-packages/statsmodels/tsa/arima_model.py", line 577, in _fit_start_params
    start_params = self._fit_start_params_hr(order, start_ar_lags)
  File "/home/aditya_user/time-forecast-app/venv/lib/python3.7/site-packages/statsmodels/tsa/arima_model.py", line 512, in _fit_start_params_hr
    mod = ar_select_order(endog, maxlag, trend='n').model
  File "/home/aditya_user/time-forecast-app/venv/lib/python3.7/site-packages/statsmodels/tsa/ar_model.py", line 2297, in ar_select_order
    missing=missing)
  File "/home/aditya_user/time-forecast-app/venv/lib/python3.7/site-packages/statsmodels/tsa/ar_model.py", line 184, in __init__
    self._setup_regressors()
  File "/home/aditya_user/time-forecast-app/venv/lib/python3.7/site-packages/statsmodels/tsa/ar_model.py", line 281, in _setup_regressors
    nobs))
ValueError: The model specification cannot be estimated. The model contains 7 regressors (0 trend, 0 seasonal, 7 lags) but after adjustment for hold_back and creation of the lags, there are only 5 data points available to estimate parameters.

root - ERROR - Error while using ARMA on ship_pt: ZTRD, prod_hierarchy: 9 Z Z Z, part_number: 30030676
root - ERROR - Traceback (most recent call last):
  File "/home/aditya_user/time-forecast-app/processing/process.py", line 62, in run
    rmse, mape, pred = algo_obj.get_predictions_rmse_mape(algo_name)
  File "/home/aditya_user/time-forecast-app/processing/algorithms.py", line 136, in get_predictions_rmse_mape
    model_fit = model.fit(disp=0)
  File "/home/aditya_user/time-forecast-app/venv/lib/python3.7/site-packages/statsmodels/tsa/arima_model.py", line 986, in fit
    start_ar_lags)
  File "/home/aditya_user/time-forecast-app/venv/lib/python3.7/site-packages/statsmodels/tsa/arima_model.py", line 577, in _fit_start_params
    start_params = self._fit_start_params_hr(order, start_ar_lags)
  File "/home/aditya_user/time-forecast-app/venv/lib/python3.7/site-packages/statsmodels/tsa/arima_model.py", line 512, in _fit_start_params_hr
    mod = ar_select_order(endog, maxlag, trend='n').model
  File "/home/aditya_user/time-forecast-app/venv/lib/python3.7/site-packages/statsmodels/tsa/ar_model.py", line 2297, in ar_select_order
    missing=missing)
  File "/home/aditya_user/time-forecast-app/venv/lib/python3.7/site-packages/statsmodels/tsa/ar_model.py", line 184, in __init__
    self._setup_regressors()
  File "/home/aditya_user/time-forecast-app/venv/lib/python3.7/site-packages/statsmodels/tsa/ar_model.py", line 281, in _setup_regressors
    nobs))
ValueError: The model specification cannot be estimated. The model contains 7 regressors (0 trend, 0 seasonal, 7 lags) but after adjustment for hold_back and creation of the lags, there are only 5 data points available to estimate parameters.

root - ERROR - Error while using ARMA on ship_pt: ZTRD, prod_hierarchy: 9 Z Z Z, part_number: 30030867
root - ERROR - Traceback (most recent call last):
  File "/home/aditya_user/time-forecast-app/processing/process.py", line 62, in run
    rmse, mape, pred = algo_obj.get_predictions_rmse_mape(algo_name)
  File "/home/aditya_user/time-forecast-app/processing/algorithms.py", line 136, in get_predictions_rmse_mape
    model_fit = model.fit(disp=0)
  File "/home/aditya_user/time-forecast-app/venv/lib/python3.7/site-packages/statsmodels/tsa/arima_model.py", line 986, in fit
    start_ar_lags)
  File "/home/aditya_user/time-forecast-app/venv/lib/python3.7/site-packages/statsmodels/tsa/arima_model.py", line 577, in _fit_start_params
    start_params = self._fit_start_params_hr(order, start_ar_lags)
  File "/home/aditya_user/time-forecast-app/venv/lib/python3.7/site-packages/statsmodels/tsa/arima_model.py", line 512, in _fit_start_params_hr
    mod = ar_select_order(endog, maxlag, trend='n').model
  File "/home/aditya_user/time-forecast-app/venv/lib/python3.7/site-packages/statsmodels/tsa/ar_model.py", line 2297, in ar_select_order
    missing=missing)
  File "/home/aditya_user/time-forecast-app/venv/lib/python3.7/site-packages/statsmodels/tsa/ar_model.py", line 184, in __init__
    self._setup_regressors()
  File "/home/aditya_user/time-forecast-app/venv/lib/python3.7/site-packages/statsmodels/tsa/ar_model.py", line 281, in _setup_regressors
    nobs))
ValueError: The model specification cannot be estimated. The model contains 7 regressors (0 trend, 0 seasonal, 7 lags) but after adjustment for hold_back and creation of the lags, there are only 5 data points available to estimate parameters.

root - ERROR - Error while using ARMA on ship_pt: ZTRD, prod_hierarchy: 9 Z Z Z, part_number: 30032431
root - ERROR - Traceback (most recent call last):
  File "/home/aditya_user/time-forecast-app/processing/process.py", line 62, in run
    rmse, mape, pred = algo_obj.get_predictions_rmse_mape(algo_name)
  File "/home/aditya_user/time-forecast-app/processing/algorithms.py", line 136, in get_predictions_rmse_mape
    model_fit = model.fit(disp=0)
  File "/home/aditya_user/time-forecast-app/venv/lib/python3.7/site-packages/statsmodels/tsa/arima_model.py", line 986, in fit
    start_ar_lags)
  File "/home/aditya_user/time-forecast-app/venv/lib/python3.7/site-packages/statsmodels/tsa/arima_model.py", line 577, in _fit_start_params
    start_params = self._fit_start_params_hr(order, start_ar_lags)
  File "/home/aditya_user/time-forecast-app/venv/lib/python3.7/site-packages/statsmodels/tsa/arima_model.py", line 512, in _fit_start_params_hr
    mod = ar_select_order(endog, maxlag, trend='n').model
  File "/home/aditya_user/time-forecast-app/venv/lib/python3.7/site-packages/statsmodels/tsa/ar_model.py", line 2297, in ar_select_order
    missing=missing)
  File "/home/aditya_user/time-forecast-app/venv/lib/python3.7/site-packages/statsmodels/tsa/ar_model.py", line 184, in __init__
    self._setup_regressors()
  File "/home/aditya_user/time-forecast-app/venv/lib/python3.7/site-packages/statsmodels/tsa/ar_model.py", line 281, in _setup_regressors
    nobs))
ValueError: The model specification cannot be estimated. The model contains 7 regressors (0 trend, 0 seasonal, 7 lags) but after adjustment for hold_back and creation of the lags, there are only 5 data points available to estimate parameters.

root - ERROR - Error while using ARMA on ship_pt: ZTRD, prod_hierarchy: 9 Z Z Z, part_number: 30037746
root - ERROR - Traceback (most recent call last):
  File "/home/aditya_user/time-forecast-app/processing/process.py", line 62, in run
    rmse, mape, pred = algo_obj.get_predictions_rmse_mape(algo_name)
  File "/home/aditya_user/time-forecast-app/processing/algorithms.py", line 136, in get_predictions_rmse_mape
    model_fit = model.fit(disp=0)
  File "/home/aditya_user/time-forecast-app/venv/lib/python3.7/site-packages/statsmodels/tsa/arima_model.py", line 986, in fit
    start_ar_lags)
  File "/home/aditya_user/time-forecast-app/venv/lib/python3.7/site-packages/statsmodels/tsa/arima_model.py", line 577, in _fit_start_params
    start_params = self._fit_start_params_hr(order, start_ar_lags)
  File "/home/aditya_user/time-forecast-app/venv/lib/python3.7/site-packages/statsmodels/tsa/arima_model.py", line 512, in _fit_start_params_hr
    mod = ar_select_order(endog, maxlag, trend='n').model
  File "/home/aditya_user/time-forecast-app/venv/lib/python3.7/site-packages/statsmodels/tsa/ar_model.py", line 2297, in ar_select_order
    missing=missing)
  File "/home/aditya_user/time-forecast-app/venv/lib/python3.7/site-packages/statsmodels/tsa/ar_model.py", line 184, in __init__
    self._setup_regressors()
  File "/home/aditya_user/time-forecast-app/venv/lib/python3.7/site-packages/statsmodels/tsa/ar_model.py", line 281, in _setup_regressors
    nobs))
ValueError: The model specification cannot be estimated. The model contains 7 regressors (0 trend, 0 seasonal, 7 lags) but after adjustment for hold_back and creation of the lags, there are only 5 data points available to estimate parameters.

root - ERROR - Error while using ARMA on ship_pt: ZTRD, prod_hierarchy: 9 Z Z Z, part_number: 30037889
root - ERROR - Traceback (most recent call last):
  File "/home/aditya_user/time-forecast-app/processing/process.py", line 62, in run
    rmse, mape, pred = algo_obj.get_predictions_rmse_mape(algo_name)
  File "/home/aditya_user/time-forecast-app/processing/algorithms.py", line 136, in get_predictions_rmse_mape
    model_fit = model.fit(disp=0)
  File "/home/aditya_user/time-forecast-app/venv/lib/python3.7/site-packages/statsmodels/tsa/arima_model.py", line 986, in fit
    start_ar_lags)
  File "/home/aditya_user/time-forecast-app/venv/lib/python3.7/site-packages/statsmodels/tsa/arima_model.py", line 577, in _fit_start_params
    start_params = self._fit_start_params_hr(order, start_ar_lags)
  File "/home/aditya_user/time-forecast-app/venv/lib/python3.7/site-packages/statsmodels/tsa/arima_model.py", line 512, in _fit_start_params_hr
    mod = ar_select_order(endog, maxlag, trend='n').model
  File "/home/aditya_user/time-forecast-app/venv/lib/python3.7/site-packages/statsmodels/tsa/ar_model.py", line 2297, in ar_select_order
    missing=missing)
  File "/home/aditya_user/time-forecast-app/venv/lib/python3.7/site-packages/statsmodels/tsa/ar_model.py", line 184, in __init__
    self._setup_regressors()
  File "/home/aditya_user/time-forecast-app/venv/lib/python3.7/site-packages/statsmodels/tsa/ar_model.py", line 281, in _setup_regressors
    nobs))
ValueError: The model specification cannot be estimated. The model contains 7 regressors (0 trend, 0 seasonal, 7 lags) but after adjustment for hold_back and creation of the lags, there are only 5 data points available to estimate parameters.

root - ERROR - Error while using ARMA on ship_pt: ZTRD, prod_hierarchy: 9 Z Z Z, part_number: 30037920
root - ERROR - Traceback (most recent call last):
  File "/home/aditya_user/time-forecast-app/processing/process.py", line 62, in run
    rmse, mape, pred = algo_obj.get_predictions_rmse_mape(algo_name)
  File "/home/aditya_user/time-forecast-app/processing/algorithms.py", line 136, in get_predictions_rmse_mape
    model_fit = model.fit(disp=0)
  File "/home/aditya_user/time-forecast-app/venv/lib/python3.7/site-packages/statsmodels/tsa/arima_model.py", line 986, in fit
    start_ar_lags)
  File "/home/aditya_user/time-forecast-app/venv/lib/python3.7/site-packages/statsmodels/tsa/arima_model.py", line 577, in _fit_start_params
    start_params = self._fit_start_params_hr(order, start_ar_lags)
  File "/home/aditya_user/time-forecast-app/venv/lib/python3.7/site-packages/statsmodels/tsa/arima_model.py", line 512, in _fit_start_params_hr
    mod = ar_select_order(endog, maxlag, trend='n').model
  File "/home/aditya_user/time-forecast-app/venv/lib/python3.7/site-packages/statsmodels/tsa/ar_model.py", line 2297, in ar_select_order
    missing=missing)
  File "/home/aditya_user/time-forecast-app/venv/lib/python3.7/site-packages/statsmodels/tsa/ar_model.py", line 184, in __init__
    self._setup_regressors()
  File "/home/aditya_user/time-forecast-app/venv/lib/python3.7/site-packages/statsmodels/tsa/ar_model.py", line 281, in _setup_regressors
    nobs))
ValueError: The model specification cannot be estimated. The model contains 7 regressors (0 trend, 0 seasonal, 7 lags) but after adjustment for hold_back and creation of the lags, there are only 5 data points available to estimate parameters.

root - ERROR - Error while using ARMA on ship_pt: ZTRD, prod_hierarchy: 1 A I E, part_number: 10030450
root - ERROR - Traceback (most recent call last):
  File "/home/aditya_user/time-forecast-app/processing/process.py", line 62, in run
    rmse, mape, pred = algo_obj.get_predictions_rmse_mape(algo_name)
  File "/home/aditya_user/time-forecast-app/processing/algorithms.py", line 136, in get_predictions_rmse_mape
    model_fit = model.fit(disp=0)
  File "/home/aditya_user/time-forecast-app/venv/lib/python3.7/site-packages/statsmodels/tsa/arima_model.py", line 999, in fit
    callback=callback, **kwargs)
  File "/home/aditya_user/time-forecast-app/venv/lib/python3.7/site-packages/statsmodels/base/model.py", line 526, in fit
    full_output=full_output)
  File "/home/aditya_user/time-forecast-app/venv/lib/python3.7/site-packages/statsmodels/base/optimizer.py", line 218, in _fit
    hess=hessian)
  File "/home/aditya_user/time-forecast-app/venv/lib/python3.7/site-packages/statsmodels/base/optimizer.py", line 440, in _fit_lbfgs
    **extra_kwargs)
  File "/home/aditya_user/time-forecast-app/venv/lib/python3.7/site-packages/scipy/optimize/lbfgsb.py", line 199, in fmin_l_bfgs_b
    **opts)
  File "/home/aditya_user/time-forecast-app/venv/lib/python3.7/site-packages/scipy/optimize/lbfgsb.py", line 345, in _minimize_lbfgsb
    f, g = func_and_grad(x)
  File "/home/aditya_user/time-forecast-app/venv/lib/python3.7/site-packages/scipy/optimize/lbfgsb.py", line 290, in func_and_grad
    f = fun(x, *args)
  File "/home/aditya_user/time-forecast-app/venv/lib/python3.7/site-packages/scipy/optimize/optimize.py", line 327, in function_wrapper
    return function(*(wrapper_args + args))
  File "/home/aditya_user/time-forecast-app/venv/lib/python3.7/site-packages/statsmodels/base/model.py", line 500, in f
    return -self.loglike(params, *args) / nobs
  File "/home/aditya_user/time-forecast-app/venv/lib/python3.7/site-packages/statsmodels/tsa/arima_model.py", line 810, in loglike
    return self.loglike_kalman(params, set_sigma2)
  File "/home/aditya_user/time-forecast-app/venv/lib/python3.7/site-packages/statsmodels/tsa/arima_model.py", line 820, in loglike_kalman
    return KalmanFilter.loglike(params, self, set_sigma2)
  File "/home/aditya_user/time-forecast-app/venv/lib/python3.7/site-packages/statsmodels/tsa/kalmanf/kalmanfilter.py", line 220, in loglike
    Z_mat, R_mat, T_mat)
  File "statsmodels/tsa/kalmanf/kalman_loglike.pyx", line 331, in statsmodels.tsa.kalmanf.kalman_loglike.kalman_loglike_double
  File "statsmodels/tsa/kalmanf/kalman_loglike.pyx", line 62, in statsmodels.tsa.kalmanf.kalman_loglike.kalman_filter_double
  File "<__array_function__ internals>", line 6, in pinv
  File "/home/aditya_user/time-forecast-app/venv/lib/python3.7/site-packages/numpy/linalg/linalg.py", line 1961, in pinv
    u, s, vt = svd(a, full_matrices=False, hermitian=hermitian)
  File "<__array_function__ internals>", line 6, in svd
  File "/home/aditya_user/time-forecast-app/venv/lib/python3.7/site-packages/numpy/linalg/linalg.py", line 1626, in svd
    u, s, vh = gufunc(a, signature=signature, extobj=extobj)
  File "/home/aditya_user/time-forecast-app/venv/lib/python3.7/site-packages/numpy/linalg/linalg.py", line 106, in _raise_linalgerror_svd_nonconvergence
    raise LinAlgError("SVD did not converge")
numpy.linalg.LinAlgError: SVD did not converge

root - ERROR - Error while using ARMA on ship_pt: ZTRD, prod_hierarchy: 9 Z Z Z, part_number: 30038359
root - ERROR - Traceback (most recent call last):
  File "/home/aditya_user/time-forecast-app/processing/process.py", line 62, in run
    rmse, mape, pred = algo_obj.get_predictions_rmse_mape(algo_name)
  File "/home/aditya_user/time-forecast-app/processing/algorithms.py", line 136, in get_predictions_rmse_mape
    model_fit = model.fit(disp=0)
  File "/home/aditya_user/time-forecast-app/venv/lib/python3.7/site-packages/statsmodels/tsa/arima_model.py", line 986, in fit
    start_ar_lags)
  File "/home/aditya_user/time-forecast-app/venv/lib/python3.7/site-packages/statsmodels/tsa/arima_model.py", line 577, in _fit_start_params
    start_params = self._fit_start_params_hr(order, start_ar_lags)
  File "/home/aditya_user/time-forecast-app/venv/lib/python3.7/site-packages/statsmodels/tsa/arima_model.py", line 512, in _fit_start_params_hr
    mod = ar_select_order(endog, maxlag, trend='n').model
  File "/home/aditya_user/time-forecast-app/venv/lib/python3.7/site-packages/statsmodels/tsa/ar_model.py", line 2297, in ar_select_order
    missing=missing)
  File "/home/aditya_user/time-forecast-app/venv/lib/python3.7/site-packages/statsmodels/tsa/ar_model.py", line 184, in __init__
    self._setup_regressors()
  File "/home/aditya_user/time-forecast-app/venv/lib/python3.7/site-packages/statsmodels/tsa/ar_model.py", line 281, in _setup_regressors
    nobs))
ValueError: The model specification cannot be estimated. The model contains 7 regressors (0 trend, 0 seasonal, 7 lags) but after adjustment for hold_back and creation of the lags, there are only 5 data points available to estimate parameters.

root - ERROR - Error while using ARMA on ship_pt: ZTRD, prod_hierarchy: 9 Z Z Z, part_number: 30038557
root - ERROR - Traceback (most recent call last):
  File "/home/aditya_user/time-forecast-app/processing/process.py", line 62, in run
    rmse, mape, pred = algo_obj.get_predictions_rmse_mape(algo_name)
  File "/home/aditya_user/time-forecast-app/processing/algorithms.py", line 136, in get_predictions_rmse_mape
    model_fit = model.fit(disp=0)
  File "/home/aditya_user/time-forecast-app/venv/lib/python3.7/site-packages/statsmodels/tsa/arima_model.py", line 986, in fit
    start_ar_lags)
  File "/home/aditya_user/time-forecast-app/venv/lib/python3.7/site-packages/statsmodels/tsa/arima_model.py", line 577, in _fit_start_params
    start_params = self._fit_start_params_hr(order, start_ar_lags)
  File "/home/aditya_user/time-forecast-app/venv/lib/python3.7/site-packages/statsmodels/tsa/arima_model.py", line 512, in _fit_start_params_hr
    mod = ar_select_order(endog, maxlag, trend='n').model
  File "/home/aditya_user/time-forecast-app/venv/lib/python3.7/site-packages/statsmodels/tsa/ar_model.py", line 2297, in ar_select_order
    missing=missing)
  File "/home/aditya_user/time-forecast-app/venv/lib/python3.7/site-packages/statsmodels/tsa/ar_model.py", line 184, in __init__
    self._setup_regressors()
  File "/home/aditya_user/time-forecast-app/venv/lib/python3.7/site-packages/statsmodels/tsa/ar_model.py", line 281, in _setup_regressors
    nobs))
ValueError: The model specification cannot be estimated. The model contains 7 regressors (0 trend, 0 seasonal, 7 lags) but after adjustment for hold_back and creation of the lags, there are only 5 data points available to estimate parameters.

root - ERROR - Error while using ARMA on ship_pt: ZTRD, prod_hierarchy: 9 Z Z Z, part_number: 30038564
root - ERROR - Traceback (most recent call last):
  File "/home/aditya_user/time-forecast-app/processing/process.py", line 62, in run
    rmse, mape, pred = algo_obj.get_predictions_rmse_mape(algo_name)
  File "/home/aditya_user/time-forecast-app/processing/algorithms.py", line 136, in get_predictions_rmse_mape
    model_fit = model.fit(disp=0)
  File "/home/aditya_user/time-forecast-app/venv/lib/python3.7/site-packages/statsmodels/tsa/arima_model.py", line 986, in fit
    start_ar_lags)
  File "/home/aditya_user/time-forecast-app/venv/lib/python3.7/site-packages/statsmodels/tsa/arima_model.py", line 577, in _fit_start_params
    start_params = self._fit_start_params_hr(order, start_ar_lags)
  File "/home/aditya_user/time-forecast-app/venv/lib/python3.7/site-packages/statsmodels/tsa/arima_model.py", line 512, in _fit_start_params_hr
    mod = ar_select_order(endog, maxlag, trend='n').model
  File "/home/aditya_user/time-forecast-app/venv/lib/python3.7/site-packages/statsmodels/tsa/ar_model.py", line 2297, in ar_select_order
    missing=missing)
  File "/home/aditya_user/time-forecast-app/venv/lib/python3.7/site-packages/statsmodels/tsa/ar_model.py", line 184, in __init__
    self._setup_regressors()
  File "/home/aditya_user/time-forecast-app/venv/lib/python3.7/site-packages/statsmodels/tsa/ar_model.py", line 281, in _setup_regressors
    nobs))
ValueError: The model specification cannot be estimated. The model contains 7 regressors (0 trend, 0 seasonal, 7 lags) but after adjustment for hold_back and creation of the lags, there are only 5 data points available to estimate parameters.

root - ERROR - Error while using ARMA on ship_pt: ZTRD, prod_hierarchy: 9 Z Z Z, part_number: 30038871
root - ERROR - Traceback (most recent call last):
  File "/home/aditya_user/time-forecast-app/processing/process.py", line 62, in run
    rmse, mape, pred = algo_obj.get_predictions_rmse_mape(algo_name)
  File "/home/aditya_user/time-forecast-app/processing/algorithms.py", line 136, in get_predictions_rmse_mape
    model_fit = model.fit(disp=0)
  File "/home/aditya_user/time-forecast-app/venv/lib/python3.7/site-packages/statsmodels/tsa/arima_model.py", line 986, in fit
    start_ar_lags)
  File "/home/aditya_user/time-forecast-app/venv/lib/python3.7/site-packages/statsmodels/tsa/arima_model.py", line 577, in _fit_start_params
    start_params = self._fit_start_params_hr(order, start_ar_lags)
  File "/home/aditya_user/time-forecast-app/venv/lib/python3.7/site-packages/statsmodels/tsa/arima_model.py", line 512, in _fit_start_params_hr
    mod = ar_select_order(endog, maxlag, trend='n').model
  File "/home/aditya_user/time-forecast-app/venv/lib/python3.7/site-packages/statsmodels/tsa/ar_model.py", line 2297, in ar_select_order
    missing=missing)
  File "/home/aditya_user/time-forecast-app/venv/lib/python3.7/site-packages/statsmodels/tsa/ar_model.py", line 184, in __init__
    self._setup_regressors()
  File "/home/aditya_user/time-forecast-app/venv/lib/python3.7/site-packages/statsmodels/tsa/ar_model.py", line 281, in _setup_regressors
    nobs))
ValueError: The model specification cannot be estimated. The model contains 7 regressors (0 trend, 0 seasonal, 7 lags) but after adjustment for hold_back and creation of the lags, there are only 5 data points available to estimate parameters.

root - ERROR - Error while using ARMA on ship_pt: ZTRD, prod_hierarchy: 9 Z Z Z, part_number: 30038966
root - ERROR - Traceback (most recent call last):
  File "/home/aditya_user/time-forecast-app/processing/process.py", line 62, in run
    rmse, mape, pred = algo_obj.get_predictions_rmse_mape(algo_name)
  File "/home/aditya_user/time-forecast-app/processing/algorithms.py", line 136, in get_predictions_rmse_mape
    model_fit = model.fit(disp=0)
  File "/home/aditya_user/time-forecast-app/venv/lib/python3.7/site-packages/statsmodels/tsa/arima_model.py", line 986, in fit
    start_ar_lags)
  File "/home/aditya_user/time-forecast-app/venv/lib/python3.7/site-packages/statsmodels/tsa/arima_model.py", line 577, in _fit_start_params
    start_params = self._fit_start_params_hr(order, start_ar_lags)
  File "/home/aditya_user/time-forecast-app/venv/lib/python3.7/site-packages/statsmodels/tsa/arima_model.py", line 512, in _fit_start_params_hr
    mod = ar_select_order(endog, maxlag, trend='n').model
  File "/home/aditya_user/time-forecast-app/venv/lib/python3.7/site-packages/statsmodels/tsa/ar_model.py", line 2297, in ar_select_order
    missing=missing)
  File "/home/aditya_user/time-forecast-app/venv/lib/python3.7/site-packages/statsmodels/tsa/ar_model.py", line 184, in __init__
    self._setup_regressors()
  File "/home/aditya_user/time-forecast-app/venv/lib/python3.7/site-packages/statsmodels/tsa/ar_model.py", line 281, in _setup_regressors
    nobs))
ValueError: The model specification cannot be estimated. The model contains 7 regressors (0 trend, 0 seasonal, 7 lags) but after adjustment for hold_back and creation of the lags, there are only 5 data points available to estimate parameters.

root - ERROR - Error while using ARMA on ship_pt: ZTRD, prod_hierarchy: 9 Z Z Z, part_number: 30038968
root - ERROR - Traceback (most recent call last):
  File "/home/aditya_user/time-forecast-app/processing/process.py", line 62, in run
    rmse, mape, pred = algo_obj.get_predictions_rmse_mape(algo_name)
  File "/home/aditya_user/time-forecast-app/processing/algorithms.py", line 136, in get_predictions_rmse_mape
    model_fit = model.fit(disp=0)
  File "/home/aditya_user/time-forecast-app/venv/lib/python3.7/site-packages/statsmodels/tsa/arima_model.py", line 986, in fit
    start_ar_lags)
  File "/home/aditya_user/time-forecast-app/venv/lib/python3.7/site-packages/statsmodels/tsa/arima_model.py", line 577, in _fit_start_params
    start_params = self._fit_start_params_hr(order, start_ar_lags)
  File "/home/aditya_user/time-forecast-app/venv/lib/python3.7/site-packages/statsmodels/tsa/arima_model.py", line 512, in _fit_start_params_hr
    mod = ar_select_order(endog, maxlag, trend='n').model
  File "/home/aditya_user/time-forecast-app/venv/lib/python3.7/site-packages/statsmodels/tsa/ar_model.py", line 2297, in ar_select_order
    missing=missing)
  File "/home/aditya_user/time-forecast-app/venv/lib/python3.7/site-packages/statsmodels/tsa/ar_model.py", line 184, in __init__
    self._setup_regressors()
  File "/home/aditya_user/time-forecast-app/venv/lib/python3.7/site-packages/statsmodels/tsa/ar_model.py", line 281, in _setup_regressors
    nobs))
ValueError: The model specification cannot be estimated. The model contains 7 regressors (0 trend, 0 seasonal, 7 lags) but after adjustment for hold_back and creation of the lags, there are only 5 data points available to estimate parameters.

root - ERROR - Error while using ARMA on ship_pt: ZTRD, prod_hierarchy: 9 Z Z Z, part_number: 30038977
root - ERROR - Traceback (most recent call last):
  File "/home/aditya_user/time-forecast-app/processing/process.py", line 62, in run
    rmse, mape, pred = algo_obj.get_predictions_rmse_mape(algo_name)
  File "/home/aditya_user/time-forecast-app/processing/algorithms.py", line 136, in get_predictions_rmse_mape
    model_fit = model.fit(disp=0)
  File "/home/aditya_user/time-forecast-app/venv/lib/python3.7/site-packages/statsmodels/tsa/arima_model.py", line 986, in fit
    start_ar_lags)
  File "/home/aditya_user/time-forecast-app/venv/lib/python3.7/site-packages/statsmodels/tsa/arima_model.py", line 577, in _fit_start_params
    start_params = self._fit_start_params_hr(order, start_ar_lags)
  File "/home/aditya_user/time-forecast-app/venv/lib/python3.7/site-packages/statsmodels/tsa/arima_model.py", line 512, in _fit_start_params_hr
    mod = ar_select_order(endog, maxlag, trend='n').model
  File "/home/aditya_user/time-forecast-app/venv/lib/python3.7/site-packages/statsmodels/tsa/ar_model.py", line 2297, in ar_select_order
    missing=missing)
  File "/home/aditya_user/time-forecast-app/venv/lib/python3.7/site-packages/statsmodels/tsa/ar_model.py", line 184, in __init__
    self._setup_regressors()
  File "/home/aditya_user/time-forecast-app/venv/lib/python3.7/site-packages/statsmodels/tsa/ar_model.py", line 281, in _setup_regressors
    nobs))
ValueError: The model specification cannot be estimated. The model contains 7 regressors (0 trend, 0 seasonal, 7 lags) but after adjustment for hold_back and creation of the lags, there are only 5 data points available to estimate parameters.

root - ERROR - Error while using ARMA on ship_pt: ZTRD, prod_hierarchy: 9 Z Z Z, part_number: 30039003
root - ERROR - Traceback (most recent call last):
  File "/home/aditya_user/time-forecast-app/processing/process.py", line 62, in run
    rmse, mape, pred = algo_obj.get_predictions_rmse_mape(algo_name)
  File "/home/aditya_user/time-forecast-app/processing/algorithms.py", line 136, in get_predictions_rmse_mape
    model_fit = model.fit(disp=0)
  File "/home/aditya_user/time-forecast-app/venv/lib/python3.7/site-packages/statsmodels/tsa/arima_model.py", line 986, in fit
    start_ar_lags)
  File "/home/aditya_user/time-forecast-app/venv/lib/python3.7/site-packages/statsmodels/tsa/arima_model.py", line 577, in _fit_start_params
    start_params = self._fit_start_params_hr(order, start_ar_lags)
  File "/home/aditya_user/time-forecast-app/venv/lib/python3.7/site-packages/statsmodels/tsa/arima_model.py", line 512, in _fit_start_params_hr
    mod = ar_select_order(endog, maxlag, trend='n').model
  File "/home/aditya_user/time-forecast-app/venv/lib/python3.7/site-packages/statsmodels/tsa/ar_model.py", line 2297, in ar_select_order
    missing=missing)
  File "/home/aditya_user/time-forecast-app/venv/lib/python3.7/site-packages/statsmodels/tsa/ar_model.py", line 184, in __init__
    self._setup_regressors()
  File "/home/aditya_user/time-forecast-app/venv/lib/python3.7/site-packages/statsmodels/tsa/ar_model.py", line 281, in _setup_regressors
    nobs))
ValueError: The model specification cannot be estimated. The model contains 7 regressors (0 trend, 0 seasonal, 7 lags) but after adjustment for hold_back and creation of the lags, there are only 5 data points available to estimate parameters.

root - ERROR - Error while using ARMA on ship_pt: ZTRD, prod_hierarchy: 9 Z Z Z, part_number: 30039085
root - ERROR - Traceback (most recent call last):
  File "/home/aditya_user/time-forecast-app/processing/process.py", line 62, in run
    rmse, mape, pred = algo_obj.get_predictions_rmse_mape(algo_name)
  File "/home/aditya_user/time-forecast-app/processing/algorithms.py", line 136, in get_predictions_rmse_mape
    model_fit = model.fit(disp=0)
  File "/home/aditya_user/time-forecast-app/venv/lib/python3.7/site-packages/statsmodels/tsa/arima_model.py", line 986, in fit
    start_ar_lags)
  File "/home/aditya_user/time-forecast-app/venv/lib/python3.7/site-packages/statsmodels/tsa/arima_model.py", line 577, in _fit_start_params
    start_params = self._fit_start_params_hr(order, start_ar_lags)
  File "/home/aditya_user/time-forecast-app/venv/lib/python3.7/site-packages/statsmodels/tsa/arima_model.py", line 512, in _fit_start_params_hr
    mod = ar_select_order(endog, maxlag, trend='n').model
  File "/home/aditya_user/time-forecast-app/venv/lib/python3.7/site-packages/statsmodels/tsa/ar_model.py", line 2297, in ar_select_order
    missing=missing)
  File "/home/aditya_user/time-forecast-app/venv/lib/python3.7/site-packages/statsmodels/tsa/ar_model.py", line 184, in __init__
    self._setup_regressors()
  File "/home/aditya_user/time-forecast-app/venv/lib/python3.7/site-packages/statsmodels/tsa/ar_model.py", line 281, in _setup_regressors
    nobs))
ValueError: The model specification cannot be estimated. The model contains 7 regressors (0 trend, 0 seasonal, 7 lags) but after adjustment for hold_back and creation of the lags, there are only 5 data points available to estimate parameters.

root - ERROR - Error while using ARMA on ship_pt: ZTRD, prod_hierarchy: 9 Z Z Z, part_number: 30039086
root - ERROR - Traceback (most recent call last):
  File "/home/aditya_user/time-forecast-app/processing/process.py", line 62, in run
    rmse, mape, pred = algo_obj.get_predictions_rmse_mape(algo_name)
  File "/home/aditya_user/time-forecast-app/processing/algorithms.py", line 136, in get_predictions_rmse_mape
    model_fit = model.fit(disp=0)
  File "/home/aditya_user/time-forecast-app/venv/lib/python3.7/site-packages/statsmodels/tsa/arima_model.py", line 986, in fit
    start_ar_lags)
  File "/home/aditya_user/time-forecast-app/venv/lib/python3.7/site-packages/statsmodels/tsa/arima_model.py", line 577, in _fit_start_params
    start_params = self._fit_start_params_hr(order, start_ar_lags)
  File "/home/aditya_user/time-forecast-app/venv/lib/python3.7/site-packages/statsmodels/tsa/arima_model.py", line 512, in _fit_start_params_hr
    mod = ar_select_order(endog, maxlag, trend='n').model
  File "/home/aditya_user/time-forecast-app/venv/lib/python3.7/site-packages/statsmodels/tsa/ar_model.py", line 2297, in ar_select_order
    missing=missing)
  File "/home/aditya_user/time-forecast-app/venv/lib/python3.7/site-packages/statsmodels/tsa/ar_model.py", line 184, in __init__
    self._setup_regressors()
  File "/home/aditya_user/time-forecast-app/venv/lib/python3.7/site-packages/statsmodels/tsa/ar_model.py", line 281, in _setup_regressors
    nobs))
ValueError: The model specification cannot be estimated. The model contains 7 regressors (0 trend, 0 seasonal, 7 lags) but after adjustment for hold_back and creation of the lags, there are only 5 data points available to estimate parameters.

root - ERROR - Error while using FNN method on ship_pt: ZTRD, prod_hierarchy: 2 B Y C, part_number: 10076001
root - ERROR - Traceback (most recent call last):
  File "/home/aditya_user/time-forecast-app/processing/process.py", line 172, in run
    rmse_fnn, mape_fnn, pred_fnn = algo_obj.fnn_calculate()
  File "/home/aditya_user/time-forecast-app/processing/algorithms.py", line 531, in fnn_calculate
    yhat = FeedForwardNeuralNetwork.fnn(self.total, len(self.test))
  File "/home/aditya_user/time-forecast-app/processing/fnn.py", line 128, in fnn
    data, n_test, config)
  File "/home/aditya_user/time-forecast-app/processing/fnn.py", line 80, in walk_forward_validation
    model = FeedForwardNeuralNetwork.model_fit(train, cfg)
  File "/home/aditya_user/time-forecast-app/processing/fnn.py", line 61, in model_fit
    verbose=0)
  File "/home/aditya_user/time-forecast-app/venv/lib/python3.7/site-packages/tensorflow/python/keras/engine/training.py", line 643, in fit
    use_multiprocessing=use_multiprocessing)
  File "/home/aditya_user/time-forecast-app/venv/lib/python3.7/site-packages/tensorflow/python/keras/engine/training_arrays.py", line 664, in fit
    steps_name='steps_per_epoch')
  File "/home/aditya_user/time-forecast-app/venv/lib/python3.7/site-packages/tensorflow/python/keras/engine/training_arrays.py", line 187, in model_iteration
    f = _make_execution_function(model, mode)
  File "/home/aditya_user/time-forecast-app/venv/lib/python3.7/site-packages/tensorflow/python/keras/engine/training_arrays.py", line 555, in _make_execution_function
    return model._make_execution_function(mode)
  File "/home/aditya_user/time-forecast-app/venv/lib/python3.7/site-packages/tensorflow/python/keras/engine/training.py", line 2031, in _make_execution_function
    self._make_train_function()
  File "/home/aditya_user/time-forecast-app/venv/lib/python3.7/site-packages/tensorflow/python/keras/engine/training.py", line 1986, in _make_train_function
    **self._function_kwargs)
  File "/home/aditya_user/time-forecast-app/venv/lib/python3.7/site-packages/tensorflow/python/keras/backend.py", line 3544, in function
    return EagerExecutionFunction(inputs, outputs, updates=updates, name=name)
  File "/home/aditya_user/time-forecast-app/venv/lib/python3.7/site-packages/tensorflow/python/keras/backend.py", line 3438, in __init__
    add_sources=True, handle_captures=True, base_graph=source_graph)
  File "/home/aditya_user/time-forecast-app/venv/lib/python3.7/site-packages/tensorflow/python/eager/lift_to_graph.py", line 368, in lift_to_graph
    for s in six.itervalues(captures):
RuntimeError: OrderedDict mutated during iteration

root - ERROR - Error while using ARMA on ship_pt: ZTRD, prod_hierarchy: 9 Z Z Z, part_number: 30039317
root - ERROR - Traceback (most recent call last):
  File "/home/aditya_user/time-forecast-app/processing/process.py", line 62, in run
    rmse, mape, pred = algo_obj.get_predictions_rmse_mape(algo_name)
  File "/home/aditya_user/time-forecast-app/processing/algorithms.py", line 136, in get_predictions_rmse_mape
    model_fit = model.fit(disp=0)
  File "/home/aditya_user/time-forecast-app/venv/lib/python3.7/site-packages/statsmodels/tsa/arima_model.py", line 986, in fit
    start_ar_lags)
  File "/home/aditya_user/time-forecast-app/venv/lib/python3.7/site-packages/statsmodels/tsa/arima_model.py", line 577, in _fit_start_params
    start_params = self._fit_start_params_hr(order, start_ar_lags)
  File "/home/aditya_user/time-forecast-app/venv/lib/python3.7/site-packages/statsmodels/tsa/arima_model.py", line 512, in _fit_start_params_hr
    mod = ar_select_order(endog, maxlag, trend='n').model
  File "/home/aditya_user/time-forecast-app/venv/lib/python3.7/site-packages/statsmodels/tsa/ar_model.py", line 2297, in ar_select_order
    missing=missing)
  File "/home/aditya_user/time-forecast-app/venv/lib/python3.7/site-packages/statsmodels/tsa/ar_model.py", line 184, in __init__
    self._setup_regressors()
  File "/home/aditya_user/time-forecast-app/venv/lib/python3.7/site-packages/statsmodels/tsa/ar_model.py", line 281, in _setup_regressors
    nobs))
ValueError: The model specification cannot be estimated. The model contains 7 regressors (0 trend, 0 seasonal, 7 lags) but after adjustment for hold_back and creation of the lags, there are only 5 data points available to estimate parameters.

root - ERROR - Error while using ARMA on ship_pt: ZTRD, prod_hierarchy: 9 Z Z Z, part_number: 30039319
root - ERROR - Traceback (most recent call last):
  File "/home/aditya_user/time-forecast-app/processing/process.py", line 62, in run
    rmse, mape, pred = algo_obj.get_predictions_rmse_mape(algo_name)
  File "/home/aditya_user/time-forecast-app/processing/algorithms.py", line 136, in get_predictions_rmse_mape
    model_fit = model.fit(disp=0)
  File "/home/aditya_user/time-forecast-app/venv/lib/python3.7/site-packages/statsmodels/tsa/arima_model.py", line 986, in fit
    start_ar_lags)
  File "/home/aditya_user/time-forecast-app/venv/lib/python3.7/site-packages/statsmodels/tsa/arima_model.py", line 577, in _fit_start_params
    start_params = self._fit_start_params_hr(order, start_ar_lags)
  File "/home/aditya_user/time-forecast-app/venv/lib/python3.7/site-packages/statsmodels/tsa/arima_model.py", line 512, in _fit_start_params_hr
    mod = ar_select_order(endog, maxlag, trend='n').model
  File "/home/aditya_user/time-forecast-app/venv/lib/python3.7/site-packages/statsmodels/tsa/ar_model.py", line 2297, in ar_select_order
    missing=missing)
  File "/home/aditya_user/time-forecast-app/venv/lib/python3.7/site-packages/statsmodels/tsa/ar_model.py", line 184, in __init__
    self._setup_regressors()
  File "/home/aditya_user/time-forecast-app/venv/lib/python3.7/site-packages/statsmodels/tsa/ar_model.py", line 281, in _setup_regressors
    nobs))
ValueError: The model specification cannot be estimated. The model contains 7 regressors (0 trend, 0 seasonal, 7 lags) but after adjustment for hold_back and creation of the lags, there are only 5 data points available to estimate parameters.

django.request - WARNING - Not Found: /favicon.ico
django.request - WARNING - Not Found: /HNAP1/
django.request - WARNING - Not Found: /sqlite/main.php
django.request - WARNING - Not Found: /sqlitemanager/main.php
django.request - WARNING - Not Found: /SQLiteManager/main.php
django.request - WARNING - Not Found: /SQLite/main.php
django.request - WARNING - Not Found: /SQlite/main.php
django.request - WARNING - Not Found: /main.php
django.request - WARNING - Not Found: /test/sqlite/SQLiteManager-1.2.0/SQLiteManager-1.2.0/main.php
django.request - WARNING - Not Found: /SQLiteManager-1.2.4/main.php
django.request - WARNING - Not Found: /agSearch/SQlite/main.php
django.request - WARNING - Not Found: /favicon.ico
django.request - WARNING - Not Found: /favicon.ico
root - ERROR - Error while using ARMA on ship_pt: ZTRD, prod_hierarchy: 1 A I E, part_number: 10030450
root - ERROR - Traceback (most recent call last):
  File "/home/aditya_user/time-forecast-app/processing/process.py", line 62, in run
    rmse, mape, pred = algo_obj.get_predictions_rmse_mape(algo_name)
  File "/home/aditya_user/time-forecast-app/processing/algorithms.py", line 136, in get_predictions_rmse_mape
    model_fit = model.fit(disp=0)
  File "/home/aditya_user/time-forecast-app/venv/lib/python3.7/site-packages/statsmodels/tsa/arima_model.py", line 999, in fit
    callback=callback, **kwargs)
  File "/home/aditya_user/time-forecast-app/venv/lib/python3.7/site-packages/statsmodels/base/model.py", line 526, in fit
    full_output=full_output)
  File "/home/aditya_user/time-forecast-app/venv/lib/python3.7/site-packages/statsmodels/base/optimizer.py", line 218, in _fit
    hess=hessian)
  File "/home/aditya_user/time-forecast-app/venv/lib/python3.7/site-packages/statsmodels/base/optimizer.py", line 440, in _fit_lbfgs
    **extra_kwargs)
  File "/home/aditya_user/time-forecast-app/venv/lib/python3.7/site-packages/scipy/optimize/lbfgsb.py", line 199, in fmin_l_bfgs_b
    **opts)
  File "/home/aditya_user/time-forecast-app/venv/lib/python3.7/site-packages/scipy/optimize/lbfgsb.py", line 345, in _minimize_lbfgsb
    f, g = func_and_grad(x)
  File "/home/aditya_user/time-forecast-app/venv/lib/python3.7/site-packages/scipy/optimize/lbfgsb.py", line 290, in func_and_grad
    f = fun(x, *args)
  File "/home/aditya_user/time-forecast-app/venv/lib/python3.7/site-packages/scipy/optimize/optimize.py", line 327, in function_wrapper
    return function(*(wrapper_args + args))
  File "/home/aditya_user/time-forecast-app/venv/lib/python3.7/site-packages/statsmodels/base/model.py", line 500, in f
    return -self.loglike(params, *args) / nobs
  File "/home/aditya_user/time-forecast-app/venv/lib/python3.7/site-packages/statsmodels/tsa/arima_model.py", line 810, in loglike
    return self.loglike_kalman(params, set_sigma2)
  File "/home/aditya_user/time-forecast-app/venv/lib/python3.7/site-packages/statsmodels/tsa/arima_model.py", line 820, in loglike_kalman
    return KalmanFilter.loglike(params, self, set_sigma2)
  File "/home/aditya_user/time-forecast-app/venv/lib/python3.7/site-packages/statsmodels/tsa/kalmanf/kalmanfilter.py", line 220, in loglike
    Z_mat, R_mat, T_mat)
  File "statsmodels/tsa/kalmanf/kalman_loglike.pyx", line 331, in statsmodels.tsa.kalmanf.kalman_loglike.kalman_loglike_double
  File "statsmodels/tsa/kalmanf/kalman_loglike.pyx", line 62, in statsmodels.tsa.kalmanf.kalman_loglike.kalman_filter_double
  File "<__array_function__ internals>", line 6, in pinv
  File "/home/aditya_user/time-forecast-app/venv/lib/python3.7/site-packages/numpy/linalg/linalg.py", line 1961, in pinv
    u, s, vt = svd(a, full_matrices=False, hermitian=hermitian)
  File "<__array_function__ internals>", line 6, in svd
  File "/home/aditya_user/time-forecast-app/venv/lib/python3.7/site-packages/numpy/linalg/linalg.py", line 1626, in svd
    u, s, vh = gufunc(a, signature=signature, extobj=extobj)
  File "/home/aditya_user/time-forecast-app/venv/lib/python3.7/site-packages/numpy/linalg/linalg.py", line 106, in _raise_linalgerror_svd_nonconvergence
    raise LinAlgError("SVD did not converge")
numpy.linalg.LinAlgError: SVD did not converge

django.security.DisallowedHost - ERROR - Invalid HTTP_HOST header: '127.0.0.1'. You may need to add '127.0.0.1' to ALLOWED_HOSTS.
django.request - WARNING - Bad Request: /adv,/cgi-bin/weblogin.cgi
root - ERROR - Error while using ARMA on ship_pt: ZTRD, prod_hierarchy: 9 Z Z Z, part_number: 30026783
root - ERROR - Traceback (most recent call last):
  File "/home/aditya_user/time-forecast-app/processing/process.py", line 62, in run
    rmse, mape, pred = algo_obj.get_predictions_rmse_mape(algo_name)
  File "/home/aditya_user/time-forecast-app/processing/algorithms.py", line 136, in get_predictions_rmse_mape
    model_fit = model.fit(disp=0)
  File "/home/aditya_user/time-forecast-app/venv/lib/python3.7/site-packages/statsmodels/tsa/arima_model.py", line 986, in fit
    start_ar_lags)
  File "/home/aditya_user/time-forecast-app/venv/lib/python3.7/site-packages/statsmodels/tsa/arima_model.py", line 577, in _fit_start_params
    start_params = self._fit_start_params_hr(order, start_ar_lags)
  File "/home/aditya_user/time-forecast-app/venv/lib/python3.7/site-packages/statsmodels/tsa/arima_model.py", line 512, in _fit_start_params_hr
    mod = ar_select_order(endog, maxlag, trend='n').model
  File "/home/aditya_user/time-forecast-app/venv/lib/python3.7/site-packages/statsmodels/tsa/ar_model.py", line 2297, in ar_select_order
    missing=missing)
  File "/home/aditya_user/time-forecast-app/venv/lib/python3.7/site-packages/statsmodels/tsa/ar_model.py", line 184, in __init__
    self._setup_regressors()
  File "/home/aditya_user/time-forecast-app/venv/lib/python3.7/site-packages/statsmodels/tsa/ar_model.py", line 281, in _setup_regressors
    nobs))
ValueError: The model specification cannot be estimated. The model contains 7 regressors (0 trend, 0 seasonal, 7 lags) but after adjustment for hold_back and creation of the lags, there are only 5 data points available to estimate parameters.

root - ERROR - Error while using MOVING AVERAGE on ship_pt: ZTRD, prod_hierarchy: 9 Z Z Z, part_number: 30026789
root - ERROR - Traceback (most recent call last):
  File "/home/aditya_user/time-forecast-app/processing/process.py", line 62, in run
    rmse, mape, pred = algo_obj.get_predictions_rmse_mape(algo_name)
  File "/home/aditya_user/time-forecast-app/processing/algorithms.py", line 148, in get_predictions_rmse_mape
    rmse, mape = self.rmse_mape(forecast)
  File "/home/aditya_user/time-forecast-app/processing/algorithms.py", line 98, in rmse_mape
    return round(math.sqrt(mean_squared_error(self.test, predicted)),2), round(self.mean_absolute_percentage_error(
  File "/home/aditya_user/time-forecast-app/venv/lib/python3.7/site-packages/sklearn/metrics/_regression.py", line 252, in mean_squared_error
    y_true, y_pred, multioutput)
  File "/home/aditya_user/time-forecast-app/venv/lib/python3.7/site-packages/sklearn/metrics/_regression.py", line 86, in _check_reg_targets
    y_pred = check_array(y_pred, ensure_2d=False, dtype=dtype)
  File "/home/aditya_user/time-forecast-app/venv/lib/python3.7/site-packages/sklearn/utils/validation.py", line 578, in check_array
    allow_nan=force_all_finite == 'allow-nan')
  File "/home/aditya_user/time-forecast-app/venv/lib/python3.7/site-packages/sklearn/utils/validation.py", line 60, in _assert_all_finite
    msg_dtype if msg_dtype is not None else X.dtype)
ValueError: Input contains NaN, infinity or a value too large for dtype('float64').

root - ERROR - Error while using ARMA on ship_pt: ZTRD, prod_hierarchy: 9 Z Z Z, part_number: 30026789
root - ERROR - Traceback (most recent call last):
  File "/home/aditya_user/time-forecast-app/processing/process.py", line 62, in run
    rmse, mape, pred = algo_obj.get_predictions_rmse_mape(algo_name)
  File "/home/aditya_user/time-forecast-app/processing/algorithms.py", line 136, in get_predictions_rmse_mape
    model_fit = model.fit(disp=0)
  File "/home/aditya_user/time-forecast-app/venv/lib/python3.7/site-packages/statsmodels/tsa/arima_model.py", line 986, in fit
    start_ar_lags)
  File "/home/aditya_user/time-forecast-app/venv/lib/python3.7/site-packages/statsmodels/tsa/arima_model.py", line 577, in _fit_start_params
    start_params = self._fit_start_params_hr(order, start_ar_lags)
  File "/home/aditya_user/time-forecast-app/venv/lib/python3.7/site-packages/statsmodels/tsa/arima_model.py", line 512, in _fit_start_params_hr
    mod = ar_select_order(endog, maxlag, trend='n').model
  File "/home/aditya_user/time-forecast-app/venv/lib/python3.7/site-packages/statsmodels/tsa/ar_model.py", line 2297, in ar_select_order
    missing=missing)
  File "/home/aditya_user/time-forecast-app/venv/lib/python3.7/site-packages/statsmodels/tsa/ar_model.py", line 184, in __init__
    self._setup_regressors()
  File "/home/aditya_user/time-forecast-app/venv/lib/python3.7/site-packages/statsmodels/tsa/ar_model.py", line 281, in _setup_regressors
    nobs))
ValueError: The model specification cannot be estimated. The model contains 7 regressors (0 trend, 0 seasonal, 7 lags) but after adjustment for hold_back and creation of the lags, there are only 5 data points available to estimate parameters.

root - ERROR - Error while using ARMA on ship_pt: ZTRD, prod_hierarchy: 9 Z Z Z, part_number: 30030676
root - ERROR - Traceback (most recent call last):
  File "/home/aditya_user/time-forecast-app/processing/process.py", line 62, in run
    rmse, mape, pred = algo_obj.get_predictions_rmse_mape(algo_name)
  File "/home/aditya_user/time-forecast-app/processing/algorithms.py", line 136, in get_predictions_rmse_mape
    model_fit = model.fit(disp=0)
  File "/home/aditya_user/time-forecast-app/venv/lib/python3.7/site-packages/statsmodels/tsa/arima_model.py", line 986, in fit
    start_ar_lags)
  File "/home/aditya_user/time-forecast-app/venv/lib/python3.7/site-packages/statsmodels/tsa/arima_model.py", line 577, in _fit_start_params
    start_params = self._fit_start_params_hr(order, start_ar_lags)
  File "/home/aditya_user/time-forecast-app/venv/lib/python3.7/site-packages/statsmodels/tsa/arima_model.py", line 512, in _fit_start_params_hr
    mod = ar_select_order(endog, maxlag, trend='n').model
  File "/home/aditya_user/time-forecast-app/venv/lib/python3.7/site-packages/statsmodels/tsa/ar_model.py", line 2297, in ar_select_order
    missing=missing)
  File "/home/aditya_user/time-forecast-app/venv/lib/python3.7/site-packages/statsmodels/tsa/ar_model.py", line 184, in __init__
    self._setup_regressors()
  File "/home/aditya_user/time-forecast-app/venv/lib/python3.7/site-packages/statsmodels/tsa/ar_model.py", line 281, in _setup_regressors
    nobs))
ValueError: The model specification cannot be estimated. The model contains 7 regressors (0 trend, 0 seasonal, 7 lags) but after adjustment for hold_back and creation of the lags, there are only 5 data points available to estimate parameters.

root - ERROR - Error while using ARMA on ship_pt: ZTRD, prod_hierarchy: 9 Z Z Z, part_number: 30030867
root - ERROR - Traceback (most recent call last):
  File "/home/aditya_user/time-forecast-app/processing/process.py", line 62, in run
    rmse, mape, pred = algo_obj.get_predictions_rmse_mape(algo_name)
  File "/home/aditya_user/time-forecast-app/processing/algorithms.py", line 136, in get_predictions_rmse_mape
    model_fit = model.fit(disp=0)
  File "/home/aditya_user/time-forecast-app/venv/lib/python3.7/site-packages/statsmodels/tsa/arima_model.py", line 986, in fit
    start_ar_lags)
  File "/home/aditya_user/time-forecast-app/venv/lib/python3.7/site-packages/statsmodels/tsa/arima_model.py", line 577, in _fit_start_params
    start_params = self._fit_start_params_hr(order, start_ar_lags)
  File "/home/aditya_user/time-forecast-app/venv/lib/python3.7/site-packages/statsmodels/tsa/arima_model.py", line 512, in _fit_start_params_hr
    mod = ar_select_order(endog, maxlag, trend='n').model
  File "/home/aditya_user/time-forecast-app/venv/lib/python3.7/site-packages/statsmodels/tsa/ar_model.py", line 2297, in ar_select_order
    missing=missing)
  File "/home/aditya_user/time-forecast-app/venv/lib/python3.7/site-packages/statsmodels/tsa/ar_model.py", line 184, in __init__
    self._setup_regressors()
  File "/home/aditya_user/time-forecast-app/venv/lib/python3.7/site-packages/statsmodels/tsa/ar_model.py", line 281, in _setup_regressors
    nobs))
ValueError: The model specification cannot be estimated. The model contains 7 regressors (0 trend, 0 seasonal, 7 lags) but after adjustment for hold_back and creation of the lags, there are only 5 data points available to estimate parameters.

root - ERROR - Error while using ARMA on ship_pt: ZTRD, prod_hierarchy: 9 Z Z Z, part_number: 30032431
root - ERROR - Traceback (most recent call last):
  File "/home/aditya_user/time-forecast-app/processing/process.py", line 62, in run
    rmse, mape, pred = algo_obj.get_predictions_rmse_mape(algo_name)
  File "/home/aditya_user/time-forecast-app/processing/algorithms.py", line 136, in get_predictions_rmse_mape
    model_fit = model.fit(disp=0)
  File "/home/aditya_user/time-forecast-app/venv/lib/python3.7/site-packages/statsmodels/tsa/arima_model.py", line 986, in fit
    start_ar_lags)
  File "/home/aditya_user/time-forecast-app/venv/lib/python3.7/site-packages/statsmodels/tsa/arima_model.py", line 577, in _fit_start_params
    start_params = self._fit_start_params_hr(order, start_ar_lags)
  File "/home/aditya_user/time-forecast-app/venv/lib/python3.7/site-packages/statsmodels/tsa/arima_model.py", line 512, in _fit_start_params_hr
    mod = ar_select_order(endog, maxlag, trend='n').model
  File "/home/aditya_user/time-forecast-app/venv/lib/python3.7/site-packages/statsmodels/tsa/ar_model.py", line 2297, in ar_select_order
    missing=missing)
  File "/home/aditya_user/time-forecast-app/venv/lib/python3.7/site-packages/statsmodels/tsa/ar_model.py", line 184, in __init__
    self._setup_regressors()
  File "/home/aditya_user/time-forecast-app/venv/lib/python3.7/site-packages/statsmodels/tsa/ar_model.py", line 281, in _setup_regressors
    nobs))
ValueError: The model specification cannot be estimated. The model contains 7 regressors (0 trend, 0 seasonal, 7 lags) but after adjustment for hold_back and creation of the lags, there are only 5 data points available to estimate parameters.

root - ERROR - Error while using ARMA on ship_pt: ZTRD, prod_hierarchy: 9 Z Z Z, part_number: 30037746
root - ERROR - Traceback (most recent call last):
  File "/home/aditya_user/time-forecast-app/processing/process.py", line 62, in run
    rmse, mape, pred = algo_obj.get_predictions_rmse_mape(algo_name)
  File "/home/aditya_user/time-forecast-app/processing/algorithms.py", line 136, in get_predictions_rmse_mape
    model_fit = model.fit(disp=0)
  File "/home/aditya_user/time-forecast-app/venv/lib/python3.7/site-packages/statsmodels/tsa/arima_model.py", line 986, in fit
    start_ar_lags)
  File "/home/aditya_user/time-forecast-app/venv/lib/python3.7/site-packages/statsmodels/tsa/arima_model.py", line 577, in _fit_start_params
    start_params = self._fit_start_params_hr(order, start_ar_lags)
  File "/home/aditya_user/time-forecast-app/venv/lib/python3.7/site-packages/statsmodels/tsa/arima_model.py", line 512, in _fit_start_params_hr
    mod = ar_select_order(endog, maxlag, trend='n').model
  File "/home/aditya_user/time-forecast-app/venv/lib/python3.7/site-packages/statsmodels/tsa/ar_model.py", line 2297, in ar_select_order
    missing=missing)
  File "/home/aditya_user/time-forecast-app/venv/lib/python3.7/site-packages/statsmodels/tsa/ar_model.py", line 184, in __init__
    self._setup_regressors()
  File "/home/aditya_user/time-forecast-app/venv/lib/python3.7/site-packages/statsmodels/tsa/ar_model.py", line 281, in _setup_regressors
    nobs))
ValueError: The model specification cannot be estimated. The model contains 7 regressors (0 trend, 0 seasonal, 7 lags) but after adjustment for hold_back and creation of the lags, there are only 5 data points available to estimate parameters.

root - ERROR - Error while using ARMA on ship_pt: ZTRD, prod_hierarchy: 9 Z Z Z, part_number: 30037889
root - ERROR - Traceback (most recent call last):
  File "/home/aditya_user/time-forecast-app/processing/process.py", line 62, in run
    rmse, mape, pred = algo_obj.get_predictions_rmse_mape(algo_name)
  File "/home/aditya_user/time-forecast-app/processing/algorithms.py", line 136, in get_predictions_rmse_mape
    model_fit = model.fit(disp=0)
  File "/home/aditya_user/time-forecast-app/venv/lib/python3.7/site-packages/statsmodels/tsa/arima_model.py", line 986, in fit
    start_ar_lags)
  File "/home/aditya_user/time-forecast-app/venv/lib/python3.7/site-packages/statsmodels/tsa/arima_model.py", line 577, in _fit_start_params
    start_params = self._fit_start_params_hr(order, start_ar_lags)
  File "/home/aditya_user/time-forecast-app/venv/lib/python3.7/site-packages/statsmodels/tsa/arima_model.py", line 512, in _fit_start_params_hr
    mod = ar_select_order(endog, maxlag, trend='n').model
  File "/home/aditya_user/time-forecast-app/venv/lib/python3.7/site-packages/statsmodels/tsa/ar_model.py", line 2297, in ar_select_order
    missing=missing)
  File "/home/aditya_user/time-forecast-app/venv/lib/python3.7/site-packages/statsmodels/tsa/ar_model.py", line 184, in __init__
    self._setup_regressors()
  File "/home/aditya_user/time-forecast-app/venv/lib/python3.7/site-packages/statsmodels/tsa/ar_model.py", line 281, in _setup_regressors
    nobs))
ValueError: The model specification cannot be estimated. The model contains 7 regressors (0 trend, 0 seasonal, 7 lags) but after adjustment for hold_back and creation of the lags, there are only 5 data points available to estimate parameters.

root - ERROR - Error while using ARMA on ship_pt: ZTRD, prod_hierarchy: 9 Z Z Z, part_number: 30037920
root - ERROR - Traceback (most recent call last):
  File "/home/aditya_user/time-forecast-app/processing/process.py", line 62, in run
    rmse, mape, pred = algo_obj.get_predictions_rmse_mape(algo_name)
  File "/home/aditya_user/time-forecast-app/processing/algorithms.py", line 136, in get_predictions_rmse_mape
    model_fit = model.fit(disp=0)
  File "/home/aditya_user/time-forecast-app/venv/lib/python3.7/site-packages/statsmodels/tsa/arima_model.py", line 986, in fit
    start_ar_lags)
  File "/home/aditya_user/time-forecast-app/venv/lib/python3.7/site-packages/statsmodels/tsa/arima_model.py", line 577, in _fit_start_params
    start_params = self._fit_start_params_hr(order, start_ar_lags)
  File "/home/aditya_user/time-forecast-app/venv/lib/python3.7/site-packages/statsmodels/tsa/arima_model.py", line 512, in _fit_start_params_hr
    mod = ar_select_order(endog, maxlag, trend='n').model
  File "/home/aditya_user/time-forecast-app/venv/lib/python3.7/site-packages/statsmodels/tsa/ar_model.py", line 2297, in ar_select_order
    missing=missing)
  File "/home/aditya_user/time-forecast-app/venv/lib/python3.7/site-packages/statsmodels/tsa/ar_model.py", line 184, in __init__
    self._setup_regressors()
  File "/home/aditya_user/time-forecast-app/venv/lib/python3.7/site-packages/statsmodels/tsa/ar_model.py", line 281, in _setup_regressors
    nobs))
ValueError: The model specification cannot be estimated. The model contains 7 regressors (0 trend, 0 seasonal, 7 lags) but after adjustment for hold_back and creation of the lags, there are only 5 data points available to estimate parameters.

root - ERROR - Error while using ARMA on ship_pt: ZTRD, prod_hierarchy: 9 Z Z Z, part_number: 30038359
root - ERROR - Traceback (most recent call last):
  File "/home/aditya_user/time-forecast-app/processing/process.py", line 62, in run
    rmse, mape, pred = algo_obj.get_predictions_rmse_mape(algo_name)
  File "/home/aditya_user/time-forecast-app/processing/algorithms.py", line 136, in get_predictions_rmse_mape
    model_fit = model.fit(disp=0)
  File "/home/aditya_user/time-forecast-app/venv/lib/python3.7/site-packages/statsmodels/tsa/arima_model.py", line 986, in fit
    start_ar_lags)
  File "/home/aditya_user/time-forecast-app/venv/lib/python3.7/site-packages/statsmodels/tsa/arima_model.py", line 577, in _fit_start_params
    start_params = self._fit_start_params_hr(order, start_ar_lags)
  File "/home/aditya_user/time-forecast-app/venv/lib/python3.7/site-packages/statsmodels/tsa/arima_model.py", line 512, in _fit_start_params_hr
    mod = ar_select_order(endog, maxlag, trend='n').model
  File "/home/aditya_user/time-forecast-app/venv/lib/python3.7/site-packages/statsmodels/tsa/ar_model.py", line 2297, in ar_select_order
    missing=missing)
  File "/home/aditya_user/time-forecast-app/venv/lib/python3.7/site-packages/statsmodels/tsa/ar_model.py", line 184, in __init__
    self._setup_regressors()
  File "/home/aditya_user/time-forecast-app/venv/lib/python3.7/site-packages/statsmodels/tsa/ar_model.py", line 281, in _setup_regressors
    nobs))
ValueError: The model specification cannot be estimated. The model contains 7 regressors (0 trend, 0 seasonal, 7 lags) but after adjustment for hold_back and creation of the lags, there are only 5 data points available to estimate parameters.

root - ERROR - Error while using ARMA on ship_pt: ZTRD, prod_hierarchy: 9 Z Z Z, part_number: 30038557
root - ERROR - Traceback (most recent call last):
  File "/home/aditya_user/time-forecast-app/processing/process.py", line 62, in run
    rmse, mape, pred = algo_obj.get_predictions_rmse_mape(algo_name)
  File "/home/aditya_user/time-forecast-app/processing/algorithms.py", line 136, in get_predictions_rmse_mape
    model_fit = model.fit(disp=0)
  File "/home/aditya_user/time-forecast-app/venv/lib/python3.7/site-packages/statsmodels/tsa/arima_model.py", line 986, in fit
    start_ar_lags)
  File "/home/aditya_user/time-forecast-app/venv/lib/python3.7/site-packages/statsmodels/tsa/arima_model.py", line 577, in _fit_start_params
    start_params = self._fit_start_params_hr(order, start_ar_lags)
  File "/home/aditya_user/time-forecast-app/venv/lib/python3.7/site-packages/statsmodels/tsa/arima_model.py", line 512, in _fit_start_params_hr
    mod = ar_select_order(endog, maxlag, trend='n').model
  File "/home/aditya_user/time-forecast-app/venv/lib/python3.7/site-packages/statsmodels/tsa/ar_model.py", line 2297, in ar_select_order
    missing=missing)
  File "/home/aditya_user/time-forecast-app/venv/lib/python3.7/site-packages/statsmodels/tsa/ar_model.py", line 184, in __init__
    self._setup_regressors()
  File "/home/aditya_user/time-forecast-app/venv/lib/python3.7/site-packages/statsmodels/tsa/ar_model.py", line 281, in _setup_regressors
    nobs))
ValueError: The model specification cannot be estimated. The model contains 7 regressors (0 trend, 0 seasonal, 7 lags) but after adjustment for hold_back and creation of the lags, there are only 5 data points available to estimate parameters.

root - ERROR - Error while using ARMA on ship_pt: ZTRD, prod_hierarchy: 9 Z Z Z, part_number: 30038564
root - ERROR - Traceback (most recent call last):
  File "/home/aditya_user/time-forecast-app/processing/process.py", line 62, in run
    rmse, mape, pred = algo_obj.get_predictions_rmse_mape(algo_name)
  File "/home/aditya_user/time-forecast-app/processing/algorithms.py", line 136, in get_predictions_rmse_mape
    model_fit = model.fit(disp=0)
  File "/home/aditya_user/time-forecast-app/venv/lib/python3.7/site-packages/statsmodels/tsa/arima_model.py", line 986, in fit
    start_ar_lags)
  File "/home/aditya_user/time-forecast-app/venv/lib/python3.7/site-packages/statsmodels/tsa/arima_model.py", line 577, in _fit_start_params
    start_params = self._fit_start_params_hr(order, start_ar_lags)
  File "/home/aditya_user/time-forecast-app/venv/lib/python3.7/site-packages/statsmodels/tsa/arima_model.py", line 512, in _fit_start_params_hr
    mod = ar_select_order(endog, maxlag, trend='n').model
  File "/home/aditya_user/time-forecast-app/venv/lib/python3.7/site-packages/statsmodels/tsa/ar_model.py", line 2297, in ar_select_order
    missing=missing)
  File "/home/aditya_user/time-forecast-app/venv/lib/python3.7/site-packages/statsmodels/tsa/ar_model.py", line 184, in __init__
    self._setup_regressors()
  File "/home/aditya_user/time-forecast-app/venv/lib/python3.7/site-packages/statsmodels/tsa/ar_model.py", line 281, in _setup_regressors
    nobs))
ValueError: The model specification cannot be estimated. The model contains 7 regressors (0 trend, 0 seasonal, 7 lags) but after adjustment for hold_back and creation of the lags, there are only 5 data points available to estimate parameters.

root - ERROR - Error while using ARMA on ship_pt: ZTRD, prod_hierarchy: 9 Z Z Z, part_number: 30038871
root - ERROR - Traceback (most recent call last):
  File "/home/aditya_user/time-forecast-app/processing/process.py", line 62, in run
    rmse, mape, pred = algo_obj.get_predictions_rmse_mape(algo_name)
  File "/home/aditya_user/time-forecast-app/processing/algorithms.py", line 136, in get_predictions_rmse_mape
    model_fit = model.fit(disp=0)
  File "/home/aditya_user/time-forecast-app/venv/lib/python3.7/site-packages/statsmodels/tsa/arima_model.py", line 986, in fit
    start_ar_lags)
  File "/home/aditya_user/time-forecast-app/venv/lib/python3.7/site-packages/statsmodels/tsa/arima_model.py", line 577, in _fit_start_params
    start_params = self._fit_start_params_hr(order, start_ar_lags)
  File "/home/aditya_user/time-forecast-app/venv/lib/python3.7/site-packages/statsmodels/tsa/arima_model.py", line 512, in _fit_start_params_hr
    mod = ar_select_order(endog, maxlag, trend='n').model
  File "/home/aditya_user/time-forecast-app/venv/lib/python3.7/site-packages/statsmodels/tsa/ar_model.py", line 2297, in ar_select_order
    missing=missing)
  File "/home/aditya_user/time-forecast-app/venv/lib/python3.7/site-packages/statsmodels/tsa/ar_model.py", line 184, in __init__
    self._setup_regressors()
  File "/home/aditya_user/time-forecast-app/venv/lib/python3.7/site-packages/statsmodels/tsa/ar_model.py", line 281, in _setup_regressors
    nobs))
ValueError: The model specification cannot be estimated. The model contains 7 regressors (0 trend, 0 seasonal, 7 lags) but after adjustment for hold_back and creation of the lags, there are only 5 data points available to estimate parameters.

root - ERROR - Error while using ARMA on ship_pt: ZTRD, prod_hierarchy: 9 Z Z Z, part_number: 30038966
root - ERROR - Traceback (most recent call last):
  File "/home/aditya_user/time-forecast-app/processing/process.py", line 62, in run
    rmse, mape, pred = algo_obj.get_predictions_rmse_mape(algo_name)
  File "/home/aditya_user/time-forecast-app/processing/algorithms.py", line 136, in get_predictions_rmse_mape
    model_fit = model.fit(disp=0)
  File "/home/aditya_user/time-forecast-app/venv/lib/python3.7/site-packages/statsmodels/tsa/arima_model.py", line 986, in fit
    start_ar_lags)
  File "/home/aditya_user/time-forecast-app/venv/lib/python3.7/site-packages/statsmodels/tsa/arima_model.py", line 577, in _fit_start_params
    start_params = self._fit_start_params_hr(order, start_ar_lags)
  File "/home/aditya_user/time-forecast-app/venv/lib/python3.7/site-packages/statsmodels/tsa/arima_model.py", line 512, in _fit_start_params_hr
    mod = ar_select_order(endog, maxlag, trend='n').model
  File "/home/aditya_user/time-forecast-app/venv/lib/python3.7/site-packages/statsmodels/tsa/ar_model.py", line 2297, in ar_select_order
    missing=missing)
  File "/home/aditya_user/time-forecast-app/venv/lib/python3.7/site-packages/statsmodels/tsa/ar_model.py", line 184, in __init__
    self._setup_regressors()
  File "/home/aditya_user/time-forecast-app/venv/lib/python3.7/site-packages/statsmodels/tsa/ar_model.py", line 281, in _setup_regressors
    nobs))
ValueError: The model specification cannot be estimated. The model contains 7 regressors (0 trend, 0 seasonal, 7 lags) but after adjustment for hold_back and creation of the lags, there are only 5 data points available to estimate parameters.

root - ERROR - Error while using ARMA on ship_pt: ZTRD, prod_hierarchy: 9 Z Z Z, part_number: 30038968
root - ERROR - Traceback (most recent call last):
  File "/home/aditya_user/time-forecast-app/processing/process.py", line 62, in run
    rmse, mape, pred = algo_obj.get_predictions_rmse_mape(algo_name)
  File "/home/aditya_user/time-forecast-app/processing/algorithms.py", line 136, in get_predictions_rmse_mape
    model_fit = model.fit(disp=0)
  File "/home/aditya_user/time-forecast-app/venv/lib/python3.7/site-packages/statsmodels/tsa/arima_model.py", line 986, in fit
    start_ar_lags)
  File "/home/aditya_user/time-forecast-app/venv/lib/python3.7/site-packages/statsmodels/tsa/arima_model.py", line 577, in _fit_start_params
    start_params = self._fit_start_params_hr(order, start_ar_lags)
  File "/home/aditya_user/time-forecast-app/venv/lib/python3.7/site-packages/statsmodels/tsa/arima_model.py", line 512, in _fit_start_params_hr
    mod = ar_select_order(endog, maxlag, trend='n').model
  File "/home/aditya_user/time-forecast-app/venv/lib/python3.7/site-packages/statsmodels/tsa/ar_model.py", line 2297, in ar_select_order
    missing=missing)
  File "/home/aditya_user/time-forecast-app/venv/lib/python3.7/site-packages/statsmodels/tsa/ar_model.py", line 184, in __init__
    self._setup_regressors()
  File "/home/aditya_user/time-forecast-app/venv/lib/python3.7/site-packages/statsmodels/tsa/ar_model.py", line 281, in _setup_regressors
    nobs))
ValueError: The model specification cannot be estimated. The model contains 7 regressors (0 trend, 0 seasonal, 7 lags) but after adjustment for hold_back and creation of the lags, there are only 5 data points available to estimate parameters.

root - ERROR - Error while using ARMA on ship_pt: ZTRD, prod_hierarchy: 9 Z Z Z, part_number: 30038977
root - ERROR - Traceback (most recent call last):
  File "/home/aditya_user/time-forecast-app/processing/process.py", line 62, in run
    rmse, mape, pred = algo_obj.get_predictions_rmse_mape(algo_name)
  File "/home/aditya_user/time-forecast-app/processing/algorithms.py", line 136, in get_predictions_rmse_mape
    model_fit = model.fit(disp=0)
  File "/home/aditya_user/time-forecast-app/venv/lib/python3.7/site-packages/statsmodels/tsa/arima_model.py", line 986, in fit
    start_ar_lags)
  File "/home/aditya_user/time-forecast-app/venv/lib/python3.7/site-packages/statsmodels/tsa/arima_model.py", line 577, in _fit_start_params
    start_params = self._fit_start_params_hr(order, start_ar_lags)
  File "/home/aditya_user/time-forecast-app/venv/lib/python3.7/site-packages/statsmodels/tsa/arima_model.py", line 512, in _fit_start_params_hr
    mod = ar_select_order(endog, maxlag, trend='n').model
  File "/home/aditya_user/time-forecast-app/venv/lib/python3.7/site-packages/statsmodels/tsa/ar_model.py", line 2297, in ar_select_order
    missing=missing)
  File "/home/aditya_user/time-forecast-app/venv/lib/python3.7/site-packages/statsmodels/tsa/ar_model.py", line 184, in __init__
    self._setup_regressors()
  File "/home/aditya_user/time-forecast-app/venv/lib/python3.7/site-packages/statsmodels/tsa/ar_model.py", line 281, in _setup_regressors
    nobs))
ValueError: The model specification cannot be estimated. The model contains 7 regressors (0 trend, 0 seasonal, 7 lags) but after adjustment for hold_back and creation of the lags, there are only 5 data points available to estimate parameters.

root - ERROR - Error while using ARMA on ship_pt: ZTRD, prod_hierarchy: 9 Z Z Z, part_number: 30039003
root - ERROR - Traceback (most recent call last):
  File "/home/aditya_user/time-forecast-app/processing/process.py", line 62, in run
    rmse, mape, pred = algo_obj.get_predictions_rmse_mape(algo_name)
  File "/home/aditya_user/time-forecast-app/processing/algorithms.py", line 136, in get_predictions_rmse_mape
    model_fit = model.fit(disp=0)
  File "/home/aditya_user/time-forecast-app/venv/lib/python3.7/site-packages/statsmodels/tsa/arima_model.py", line 986, in fit
    start_ar_lags)
  File "/home/aditya_user/time-forecast-app/venv/lib/python3.7/site-packages/statsmodels/tsa/arima_model.py", line 577, in _fit_start_params
    start_params = self._fit_start_params_hr(order, start_ar_lags)
  File "/home/aditya_user/time-forecast-app/venv/lib/python3.7/site-packages/statsmodels/tsa/arima_model.py", line 512, in _fit_start_params_hr
    mod = ar_select_order(endog, maxlag, trend='n').model
  File "/home/aditya_user/time-forecast-app/venv/lib/python3.7/site-packages/statsmodels/tsa/ar_model.py", line 2297, in ar_select_order
    missing=missing)
  File "/home/aditya_user/time-forecast-app/venv/lib/python3.7/site-packages/statsmodels/tsa/ar_model.py", line 184, in __init__
    self._setup_regressors()
  File "/home/aditya_user/time-forecast-app/venv/lib/python3.7/site-packages/statsmodels/tsa/ar_model.py", line 281, in _setup_regressors
    nobs))
ValueError: The model specification cannot be estimated. The model contains 7 regressors (0 trend, 0 seasonal, 7 lags) but after adjustment for hold_back and creation of the lags, there are only 5 data points available to estimate parameters.

root - ERROR - Error while using ARMA on ship_pt: ZTRD, prod_hierarchy: 9 Z Z Z, part_number: 30039085
root - ERROR - Traceback (most recent call last):
  File "/home/aditya_user/time-forecast-app/processing/process.py", line 62, in run
    rmse, mape, pred = algo_obj.get_predictions_rmse_mape(algo_name)
  File "/home/aditya_user/time-forecast-app/processing/algorithms.py", line 136, in get_predictions_rmse_mape
    model_fit = model.fit(disp=0)
  File "/home/aditya_user/time-forecast-app/venv/lib/python3.7/site-packages/statsmodels/tsa/arima_model.py", line 986, in fit
    start_ar_lags)
  File "/home/aditya_user/time-forecast-app/venv/lib/python3.7/site-packages/statsmodels/tsa/arima_model.py", line 577, in _fit_start_params
    start_params = self._fit_start_params_hr(order, start_ar_lags)
  File "/home/aditya_user/time-forecast-app/venv/lib/python3.7/site-packages/statsmodels/tsa/arima_model.py", line 512, in _fit_start_params_hr
    mod = ar_select_order(endog, maxlag, trend='n').model
  File "/home/aditya_user/time-forecast-app/venv/lib/python3.7/site-packages/statsmodels/tsa/ar_model.py", line 2297, in ar_select_order
    missing=missing)
  File "/home/aditya_user/time-forecast-app/venv/lib/python3.7/site-packages/statsmodels/tsa/ar_model.py", line 184, in __init__
    self._setup_regressors()
  File "/home/aditya_user/time-forecast-app/venv/lib/python3.7/site-packages/statsmodels/tsa/ar_model.py", line 281, in _setup_regressors
    nobs))
ValueError: The model specification cannot be estimated. The model contains 7 regressors (0 trend, 0 seasonal, 7 lags) but after adjustment for hold_back and creation of the lags, there are only 5 data points available to estimate parameters.

root - ERROR - Error while using ARMA on ship_pt: ZTRD, prod_hierarchy: 9 Z Z Z, part_number: 30039086
root - ERROR - Traceback (most recent call last):
  File "/home/aditya_user/time-forecast-app/processing/process.py", line 62, in run
    rmse, mape, pred = algo_obj.get_predictions_rmse_mape(algo_name)
  File "/home/aditya_user/time-forecast-app/processing/algorithms.py", line 136, in get_predictions_rmse_mape
    model_fit = model.fit(disp=0)
  File "/home/aditya_user/time-forecast-app/venv/lib/python3.7/site-packages/statsmodels/tsa/arima_model.py", line 986, in fit
    start_ar_lags)
  File "/home/aditya_user/time-forecast-app/venv/lib/python3.7/site-packages/statsmodels/tsa/arima_model.py", line 577, in _fit_start_params
    start_params = self._fit_start_params_hr(order, start_ar_lags)
  File "/home/aditya_user/time-forecast-app/venv/lib/python3.7/site-packages/statsmodels/tsa/arima_model.py", line 512, in _fit_start_params_hr
    mod = ar_select_order(endog, maxlag, trend='n').model
  File "/home/aditya_user/time-forecast-app/venv/lib/python3.7/site-packages/statsmodels/tsa/ar_model.py", line 2297, in ar_select_order
    missing=missing)
  File "/home/aditya_user/time-forecast-app/venv/lib/python3.7/site-packages/statsmodels/tsa/ar_model.py", line 184, in __init__
    self._setup_regressors()
  File "/home/aditya_user/time-forecast-app/venv/lib/python3.7/site-packages/statsmodels/tsa/ar_model.py", line 281, in _setup_regressors
    nobs))
ValueError: The model specification cannot be estimated. The model contains 7 regressors (0 trend, 0 seasonal, 7 lags) but after adjustment for hold_back and creation of the lags, there are only 5 data points available to estimate parameters.

root - ERROR - Error while using ARMA on ship_pt: ZTRD, prod_hierarchy: 9 Z Z Z, part_number: 30039317
root - ERROR - Traceback (most recent call last):
  File "/home/aditya_user/time-forecast-app/processing/process.py", line 62, in run
    rmse, mape, pred = algo_obj.get_predictions_rmse_mape(algo_name)
  File "/home/aditya_user/time-forecast-app/processing/algorithms.py", line 136, in get_predictions_rmse_mape
    model_fit = model.fit(disp=0)
  File "/home/aditya_user/time-forecast-app/venv/lib/python3.7/site-packages/statsmodels/tsa/arima_model.py", line 986, in fit
    start_ar_lags)
  File "/home/aditya_user/time-forecast-app/venv/lib/python3.7/site-packages/statsmodels/tsa/arima_model.py", line 577, in _fit_start_params
    start_params = self._fit_start_params_hr(order, start_ar_lags)
  File "/home/aditya_user/time-forecast-app/venv/lib/python3.7/site-packages/statsmodels/tsa/arima_model.py", line 512, in _fit_start_params_hr
    mod = ar_select_order(endog, maxlag, trend='n').model
  File "/home/aditya_user/time-forecast-app/venv/lib/python3.7/site-packages/statsmodels/tsa/ar_model.py", line 2297, in ar_select_order
    missing=missing)
  File "/home/aditya_user/time-forecast-app/venv/lib/python3.7/site-packages/statsmodels/tsa/ar_model.py", line 184, in __init__
    self._setup_regressors()
  File "/home/aditya_user/time-forecast-app/venv/lib/python3.7/site-packages/statsmodels/tsa/ar_model.py", line 281, in _setup_regressors
    nobs))
ValueError: The model specification cannot be estimated. The model contains 7 regressors (0 trend, 0 seasonal, 7 lags) but after adjustment for hold_back and creation of the lags, there are only 5 data points available to estimate parameters.

root - ERROR - Error while using ARMA on ship_pt: ZTRD, prod_hierarchy: 9 Z Z Z, part_number: 30039319
root - ERROR - Traceback (most recent call last):
  File "/home/aditya_user/time-forecast-app/processing/process.py", line 62, in run
    rmse, mape, pred = algo_obj.get_predictions_rmse_mape(algo_name)
  File "/home/aditya_user/time-forecast-app/processing/algorithms.py", line 136, in get_predictions_rmse_mape
    model_fit = model.fit(disp=0)
  File "/home/aditya_user/time-forecast-app/venv/lib/python3.7/site-packages/statsmodels/tsa/arima_model.py", line 986, in fit
    start_ar_lags)
  File "/home/aditya_user/time-forecast-app/venv/lib/python3.7/site-packages/statsmodels/tsa/arima_model.py", line 577, in _fit_start_params
    start_params = self._fit_start_params_hr(order, start_ar_lags)
  File "/home/aditya_user/time-forecast-app/venv/lib/python3.7/site-packages/statsmodels/tsa/arima_model.py", line 512, in _fit_start_params_hr
    mod = ar_select_order(endog, maxlag, trend='n').model
  File "/home/aditya_user/time-forecast-app/venv/lib/python3.7/site-packages/statsmodels/tsa/ar_model.py", line 2297, in ar_select_order
    missing=missing)
  File "/home/aditya_user/time-forecast-app/venv/lib/python3.7/site-packages/statsmodels/tsa/ar_model.py", line 184, in __init__
    self._setup_regressors()
  File "/home/aditya_user/time-forecast-app/venv/lib/python3.7/site-packages/statsmodels/tsa/ar_model.py", line 281, in _setup_regressors
    nobs))
ValueError: The model specification cannot be estimated. The model contains 7 regressors (0 trend, 0 seasonal, 7 lags) but after adjustment for hold_back and creation of the lags, there are only 5 data points available to estimate parameters.

