django.request - WARNING - Not Found: /favicon.ico
django.request - WARNING - Not Found: /favicon.ico
django.request - WARNING - Not Found: /favicon.ico
django.request - WARNING - Not Found: /favicon.ico
django.request - WARNING - Not Found: /dashboard/adityagator.github.io
django.request - WARNING - Not Found: /favicon.ico
django.request - WARNING - Not Found: /favicon.ico
django.request - WARNING - Not Found: /favicon.ico
django.security.DisallowedHost - ERROR - Invalid HTTP_HOST header: '123.125.114.144'. You may need to add '123.125.114.144' to ALLOWED_HOSTS.
django.request - WARNING - Bad Request: /
django.request - WARNING - Not Found: /favicon.ico
root - ERROR - Exception raised during clustering:
root - ERROR - Traceback (most recent call last):
  File "/home/aditya_user/time-forecast-app/processing/cluster.py", line 18, in run
    raise Exception("Input file must contain at least 3 rows for clustering.")
Exception: Input file must contain at least 3 rows for clustering.

root - ERROR - Error while using ARIMA on ship_pt: ZTRD, prod_hierarchy: 2 A I B, part_number: 
root - ERROR - Traceback (most recent call last):
  File "/home/aditya_user/time-forecast-app/processing/process.py", line 60, in run
    rmse, mape, pred = algo_obj.get_predictions_rmse_mape(algo_name)
  File "/home/aditya_user/time-forecast-app/processing/algorithms.py", line 122, in get_predictions_rmse_mape
    model_fit = model.fit()
  File "/home/aditya_user/time-forecast-app/venv/lib/python3.7/site-packages/statsmodels/tsa/arima/model.py", line 327, in fit
    **method_kwargs)
  File "/home/aditya_user/time-forecast-app/venv/lib/python3.7/site-packages/statsmodels/tsa/statespace/mlemodel.py", line 659, in fit
    skip_hessian=True, **kwargs)
  File "/home/aditya_user/time-forecast-app/venv/lib/python3.7/site-packages/statsmodels/base/model.py", line 526, in fit
    full_output=full_output)
  File "/home/aditya_user/time-forecast-app/venv/lib/python3.7/site-packages/statsmodels/base/optimizer.py", line 218, in _fit
    hess=hessian)
  File "/home/aditya_user/time-forecast-app/venv/lib/python3.7/site-packages/statsmodels/base/optimizer.py", line 440, in _fit_lbfgs
    **extra_kwargs)
  File "/home/aditya_user/time-forecast-app/venv/lib/python3.7/site-packages/scipy/optimize/lbfgsb.py", line 199, in fmin_l_bfgs_b
    **opts)
  File "/home/aditya_user/time-forecast-app/venv/lib/python3.7/site-packages/scipy/optimize/lbfgsb.py", line 345, in _minimize_lbfgsb
    f, g = func_and_grad(x)
  File "/home/aditya_user/time-forecast-app/venv/lib/python3.7/site-packages/scipy/optimize/lbfgsb.py", line 290, in func_and_grad
    f = fun(x, *args)
  File "/home/aditya_user/time-forecast-app/venv/lib/python3.7/site-packages/scipy/optimize/optimize.py", line 327, in function_wrapper
    return function(*(wrapper_args + args))
  File "/home/aditya_user/time-forecast-app/venv/lib/python3.7/site-packages/statsmodels/base/model.py", line 500, in f
    return -self.loglike(params, *args) / nobs
  File "/home/aditya_user/time-forecast-app/venv/lib/python3.7/site-packages/statsmodels/tsa/statespace/mlemodel.py", line 889, in loglike
    loglike = self.ssm.loglike(complex_step=complex_step, **kwargs)
  File "/home/aditya_user/time-forecast-app/venv/lib/python3.7/site-packages/statsmodels/tsa/statespace/kalman_filter.py", line 977, in loglike
    kfilter = self._filter(**kwargs)
  File "/home/aditya_user/time-forecast-app/venv/lib/python3.7/site-packages/statsmodels/tsa/statespace/kalman_filter.py", line 897, in _filter
    self._initialize_state(prefix=prefix, complex_step=complex_step)
  File "/home/aditya_user/time-forecast-app/venv/lib/python3.7/site-packages/statsmodels/tsa/statespace/representation.py", line 950, in _initialize_state
    complex_step=complex_step)
  File "statsmodels/tsa/statespace/_representation.pyx", line 1334, in statsmodels.tsa.statespace._representation.dStatespace.initialize
  File "statsmodels/tsa/statespace/_initialization.pyx", line 288, in statsmodels.tsa.statespace._initialization.dInitialization.initialize
  File "statsmodels/tsa/statespace/_initialization.pyx", line 406, in statsmodels.tsa.statespace._initialization.dInitialization.initialize_stationary_stationary_cov
  File "statsmodels/tsa/statespace/_tools.pyx", line 1206, in statsmodels.tsa.statespace._tools._dsolve_discrete_lyapunov
numpy.linalg.LinAlgError: LU decomposition error.

root - ERROR - Error while using ARMA on ship_pt: ZTRD, prod_hierarchy: 2 A I B, part_number: 
root - ERROR - Traceback (most recent call last):
  File "/home/aditya_user/time-forecast-app/processing/process.py", line 60, in run
    rmse, mape, pred = algo_obj.get_predictions_rmse_mape(algo_name)
  File "/home/aditya_user/time-forecast-app/processing/algorithms.py", line 132, in get_predictions_rmse_mape
    model_fit = model.fit(disp=0)
  File "/home/aditya_user/time-forecast-app/venv/lib/python3.7/site-packages/statsmodels/tsa/arima_model.py", line 986, in fit
    start_ar_lags)
  File "/home/aditya_user/time-forecast-app/venv/lib/python3.7/site-packages/statsmodels/tsa/arima_model.py", line 577, in _fit_start_params
    start_params = self._fit_start_params_hr(order, start_ar_lags)
  File "/home/aditya_user/time-forecast-app/venv/lib/python3.7/site-packages/statsmodels/tsa/arima_model.py", line 513, in _fit_start_params_hr
    armod = mod.fit()
  File "/home/aditya_user/time-forecast-app/venv/lib/python3.7/site-packages/statsmodels/tsa/ar_model.py", line 355, in fit
    scale = nobs / (nobs - k)
ZeroDivisionError: division by zero

root - ERROR - Error while using SARIMA on ship_pt: ZTRD, prod_hierarchy: 2 A I B, part_number: 
root - ERROR - Traceback (most recent call last):
  File "/home/aditya_user/time-forecast-app/processing/process.py", line 60, in run
    rmse, mape, pred = algo_obj.get_predictions_rmse_mape(algo_name)
  File "/home/aditya_user/time-forecast-app/processing/algorithms.py", line 135, in get_predictions_rmse_mape
    model_fit = model.fit(disp=0)
  File "/home/aditya_user/time-forecast-app/venv/lib/python3.7/site-packages/statsmodels/tsa/statespace/mlemodel.py", line 607, in fit
    start_params = self.start_params
  File "/home/aditya_user/time-forecast-app/venv/lib/python3.7/site-packages/statsmodels/tsa/statespace/sarimax.py", line 953, in start_params
    warning_description='ARMA and trend')
  File "/home/aditya_user/time-forecast-app/venv/lib/python3.7/site-packages/statsmodels/tsa/statespace/sarimax.py", line 836, in _conditional_sum_squares
    Y = endog[k:]
IndexError: too many indices for array

django.request - ERROR - Internal Server Error: /process/258
Traceback (most recent call last):
  File "/home/aditya_user/time-forecast-app/venv/lib/python3.7/site-packages/django/core/handlers/exception.py", line 34, in inner
    response = get_response(request)
  File "/home/aditya_user/time-forecast-app/venv/lib/python3.7/site-packages/django/core/handlers/base.py", line 115, in _get_response
    response = self.process_exception_by_middleware(e, request)
  File "/home/aditya_user/time-forecast-app/venv/lib/python3.7/site-packages/django/core/handlers/base.py", line 113, in _get_response
    response = wrapped_callback(request, *callback_args, **callback_kwargs)
  File "/home/aditya_user/time-forecast-app/venv/lib/python3.7/site-packages/django/contrib/auth/decorators.py", line 21, in _wrapped_view
    return view_func(request, *args, **kwargs)
  File "/home/aditya_user/time-forecast-app/processing/views.py", line 15, in processing_view
    if Process.run(input):
  File "/home/aditya_user/time-forecast-app/processing/process.py", line 248, in run
    top5 = algo_obj.rankTopAlgorithms(algo_obj.rmse_pred)
  File "/home/aditya_user/time-forecast-app/processing/algorithms.py", line 46, in rankTopAlgorithms
    min_rmse = min(rmse_list)
ValueError: min() arg is an empty sequence
root - ERROR - Exception raised during clustering:
root - ERROR - Traceback (most recent call last):
  File "/home/aditya_user/time-forecast-app/processing/cluster.py", line 18, in run
    raise Exception("Input file must contain at least 3 rows for clustering.")
Exception: Input file must contain at least 3 rows for clustering.

root - ERROR - Error while using ARIMA on ship_pt: ZTRD, prod_hierarchy: 2 A I B, part_number: 
root - ERROR - Traceback (most recent call last):
  File "/home/aditya_user/time-forecast-app/processing/process.py", line 60, in run
    rmse, mape, pred = algo_obj.get_predictions_rmse_mape(algo_name)
  File "/home/aditya_user/time-forecast-app/processing/algorithms.py", line 122, in get_predictions_rmse_mape
    model_fit = model.fit()
  File "/home/aditya_user/time-forecast-app/venv/lib/python3.7/site-packages/statsmodels/tsa/arima/model.py", line 327, in fit
    **method_kwargs)
  File "/home/aditya_user/time-forecast-app/venv/lib/python3.7/site-packages/statsmodels/tsa/statespace/mlemodel.py", line 659, in fit
    skip_hessian=True, **kwargs)
  File "/home/aditya_user/time-forecast-app/venv/lib/python3.7/site-packages/statsmodels/base/model.py", line 526, in fit
    full_output=full_output)
  File "/home/aditya_user/time-forecast-app/venv/lib/python3.7/site-packages/statsmodels/base/optimizer.py", line 218, in _fit
    hess=hessian)
  File "/home/aditya_user/time-forecast-app/venv/lib/python3.7/site-packages/statsmodels/base/optimizer.py", line 440, in _fit_lbfgs
    **extra_kwargs)
  File "/home/aditya_user/time-forecast-app/venv/lib/python3.7/site-packages/scipy/optimize/lbfgsb.py", line 199, in fmin_l_bfgs_b
    **opts)
  File "/home/aditya_user/time-forecast-app/venv/lib/python3.7/site-packages/scipy/optimize/lbfgsb.py", line 345, in _minimize_lbfgsb
    f, g = func_and_grad(x)
  File "/home/aditya_user/time-forecast-app/venv/lib/python3.7/site-packages/scipy/optimize/lbfgsb.py", line 290, in func_and_grad
    f = fun(x, *args)
  File "/home/aditya_user/time-forecast-app/venv/lib/python3.7/site-packages/scipy/optimize/optimize.py", line 327, in function_wrapper
    return function(*(wrapper_args + args))
  File "/home/aditya_user/time-forecast-app/venv/lib/python3.7/site-packages/statsmodels/base/model.py", line 500, in f
    return -self.loglike(params, *args) / nobs
  File "/home/aditya_user/time-forecast-app/venv/lib/python3.7/site-packages/statsmodels/tsa/statespace/mlemodel.py", line 889, in loglike
    loglike = self.ssm.loglike(complex_step=complex_step, **kwargs)
  File "/home/aditya_user/time-forecast-app/venv/lib/python3.7/site-packages/statsmodels/tsa/statespace/kalman_filter.py", line 977, in loglike
    kfilter = self._filter(**kwargs)
  File "/home/aditya_user/time-forecast-app/venv/lib/python3.7/site-packages/statsmodels/tsa/statespace/kalman_filter.py", line 897, in _filter
    self._initialize_state(prefix=prefix, complex_step=complex_step)
  File "/home/aditya_user/time-forecast-app/venv/lib/python3.7/site-packages/statsmodels/tsa/statespace/representation.py", line 950, in _initialize_state
    complex_step=complex_step)
  File "statsmodels/tsa/statespace/_representation.pyx", line 1334, in statsmodels.tsa.statespace._representation.dStatespace.initialize
  File "statsmodels/tsa/statespace/_initialization.pyx", line 288, in statsmodels.tsa.statespace._initialization.dInitialization.initialize
  File "statsmodels/tsa/statespace/_initialization.pyx", line 406, in statsmodels.tsa.statespace._initialization.dInitialization.initialize_stationary_stationary_cov
  File "statsmodels/tsa/statespace/_tools.pyx", line 1206, in statsmodels.tsa.statespace._tools._dsolve_discrete_lyapunov
numpy.linalg.LinAlgError: LU decomposition error.

root - ERROR - Error while using ARMA on ship_pt: ZTRD, prod_hierarchy: 2 A I B, part_number: 
root - ERROR - Traceback (most recent call last):
  File "/home/aditya_user/time-forecast-app/processing/process.py", line 60, in run
    rmse, mape, pred = algo_obj.get_predictions_rmse_mape(algo_name)
  File "/home/aditya_user/time-forecast-app/processing/algorithms.py", line 132, in get_predictions_rmse_mape
    model_fit = model.fit(disp=0)
  File "/home/aditya_user/time-forecast-app/venv/lib/python3.7/site-packages/statsmodels/tsa/arima_model.py", line 986, in fit
    start_ar_lags)
  File "/home/aditya_user/time-forecast-app/venv/lib/python3.7/site-packages/statsmodels/tsa/arima_model.py", line 577, in _fit_start_params
    start_params = self._fit_start_params_hr(order, start_ar_lags)
  File "/home/aditya_user/time-forecast-app/venv/lib/python3.7/site-packages/statsmodels/tsa/arima_model.py", line 513, in _fit_start_params_hr
    armod = mod.fit()
  File "/home/aditya_user/time-forecast-app/venv/lib/python3.7/site-packages/statsmodels/tsa/ar_model.py", line 355, in fit
    scale = nobs / (nobs - k)
ZeroDivisionError: division by zero

root - ERROR - Error while using SARIMA on ship_pt: ZTRD, prod_hierarchy: 2 A I B, part_number: 
root - ERROR - Traceback (most recent call last):
  File "/home/aditya_user/time-forecast-app/processing/process.py", line 60, in run
    rmse, mape, pred = algo_obj.get_predictions_rmse_mape(algo_name)
  File "/home/aditya_user/time-forecast-app/processing/algorithms.py", line 135, in get_predictions_rmse_mape
    model_fit = model.fit(disp=0)
  File "/home/aditya_user/time-forecast-app/venv/lib/python3.7/site-packages/statsmodels/tsa/statespace/mlemodel.py", line 607, in fit
    start_params = self.start_params
  File "/home/aditya_user/time-forecast-app/venv/lib/python3.7/site-packages/statsmodels/tsa/statespace/sarimax.py", line 953, in start_params
    warning_description='ARMA and trend')
  File "/home/aditya_user/time-forecast-app/venv/lib/python3.7/site-packages/statsmodels/tsa/statespace/sarimax.py", line 836, in _conditional_sum_squares
    Y = endog[k:]
IndexError: too many indices for array

django.request - ERROR - Internal Server Error: /process/259
Traceback (most recent call last):
  File "/home/aditya_user/time-forecast-app/venv/lib/python3.7/site-packages/django/core/handlers/exception.py", line 34, in inner
    response = get_response(request)
  File "/home/aditya_user/time-forecast-app/venv/lib/python3.7/site-packages/django/core/handlers/base.py", line 115, in _get_response
    response = self.process_exception_by_middleware(e, request)
  File "/home/aditya_user/time-forecast-app/venv/lib/python3.7/site-packages/django/core/handlers/base.py", line 113, in _get_response
    response = wrapped_callback(request, *callback_args, **callback_kwargs)
  File "/home/aditya_user/time-forecast-app/venv/lib/python3.7/site-packages/django/contrib/auth/decorators.py", line 21, in _wrapped_view
    return view_func(request, *args, **kwargs)
  File "/home/aditya_user/time-forecast-app/processing/views.py", line 15, in processing_view
    if Process.run(input):
  File "/home/aditya_user/time-forecast-app/processing/process.py", line 248, in run
    top5 = algo_obj.rankTopAlgorithms(algo_obj.rmse_pred)
  File "/home/aditya_user/time-forecast-app/processing/algorithms.py", line 46, in rankTopAlgorithms
    min_rmse = min(rmse_list)
ValueError: min() arg is an empty sequence
root - ERROR - Exception raised during clustering:
root - ERROR - Traceback (most recent call last):
  File "/home/aditya_user/time-forecast-app/processing/cluster.py", line 18, in run
    raise Exception("Input file must contain at least 3 rows for clustering.")
Exception: Input file must contain at least 3 rows for clustering.

root - ERROR - Error while using ARIMA on ship_pt: ZTRD, prod_hierarchy: 2 A I B, part_number: 
root - ERROR - Traceback (most recent call last):
  File "/home/aditya_user/time-forecast-app/processing/process.py", line 60, in run
    rmse, mape, pred = algo_obj.get_predictions_rmse_mape(algo_name)
  File "/home/aditya_user/time-forecast-app/processing/algorithms.py", line 122, in get_predictions_rmse_mape
    model_fit = model.fit()
  File "/home/aditya_user/time-forecast-app/venv/lib/python3.7/site-packages/statsmodels/tsa/arima/model.py", line 327, in fit
    **method_kwargs)
  File "/home/aditya_user/time-forecast-app/venv/lib/python3.7/site-packages/statsmodels/tsa/statespace/mlemodel.py", line 659, in fit
    skip_hessian=True, **kwargs)
  File "/home/aditya_user/time-forecast-app/venv/lib/python3.7/site-packages/statsmodels/base/model.py", line 526, in fit
    full_output=full_output)
  File "/home/aditya_user/time-forecast-app/venv/lib/python3.7/site-packages/statsmodels/base/optimizer.py", line 218, in _fit
    hess=hessian)
  File "/home/aditya_user/time-forecast-app/venv/lib/python3.7/site-packages/statsmodels/base/optimizer.py", line 440, in _fit_lbfgs
    **extra_kwargs)
  File "/home/aditya_user/time-forecast-app/venv/lib/python3.7/site-packages/scipy/optimize/lbfgsb.py", line 199, in fmin_l_bfgs_b
    **opts)
  File "/home/aditya_user/time-forecast-app/venv/lib/python3.7/site-packages/scipy/optimize/lbfgsb.py", line 345, in _minimize_lbfgsb
    f, g = func_and_grad(x)
  File "/home/aditya_user/time-forecast-app/venv/lib/python3.7/site-packages/scipy/optimize/lbfgsb.py", line 290, in func_and_grad
    f = fun(x, *args)
  File "/home/aditya_user/time-forecast-app/venv/lib/python3.7/site-packages/scipy/optimize/optimize.py", line 327, in function_wrapper
    return function(*(wrapper_args + args))
  File "/home/aditya_user/time-forecast-app/venv/lib/python3.7/site-packages/statsmodels/base/model.py", line 500, in f
    return -self.loglike(params, *args) / nobs
  File "/home/aditya_user/time-forecast-app/venv/lib/python3.7/site-packages/statsmodels/tsa/statespace/mlemodel.py", line 889, in loglike
    loglike = self.ssm.loglike(complex_step=complex_step, **kwargs)
  File "/home/aditya_user/time-forecast-app/venv/lib/python3.7/site-packages/statsmodels/tsa/statespace/kalman_filter.py", line 977, in loglike
    kfilter = self._filter(**kwargs)
  File "/home/aditya_user/time-forecast-app/venv/lib/python3.7/site-packages/statsmodels/tsa/statespace/kalman_filter.py", line 897, in _filter
    self._initialize_state(prefix=prefix, complex_step=complex_step)
  File "/home/aditya_user/time-forecast-app/venv/lib/python3.7/site-packages/statsmodels/tsa/statespace/representation.py", line 950, in _initialize_state
    complex_step=complex_step)
  File "statsmodels/tsa/statespace/_representation.pyx", line 1334, in statsmodels.tsa.statespace._representation.dStatespace.initialize
  File "statsmodels/tsa/statespace/_initialization.pyx", line 288, in statsmodels.tsa.statespace._initialization.dInitialization.initialize
  File "statsmodels/tsa/statespace/_initialization.pyx", line 406, in statsmodels.tsa.statespace._initialization.dInitialization.initialize_stationary_stationary_cov
  File "statsmodels/tsa/statespace/_tools.pyx", line 1206, in statsmodels.tsa.statespace._tools._dsolve_discrete_lyapunov
numpy.linalg.LinAlgError: LU decomposition error.

root - ERROR - Error while using ARMA on ship_pt: ZTRD, prod_hierarchy: 2 A I B, part_number: 
root - ERROR - Traceback (most recent call last):
  File "/home/aditya_user/time-forecast-app/processing/process.py", line 60, in run
    rmse, mape, pred = algo_obj.get_predictions_rmse_mape(algo_name)
  File "/home/aditya_user/time-forecast-app/processing/algorithms.py", line 132, in get_predictions_rmse_mape
    model_fit = model.fit(disp=0)
  File "/home/aditya_user/time-forecast-app/venv/lib/python3.7/site-packages/statsmodels/tsa/arima_model.py", line 986, in fit
    start_ar_lags)
  File "/home/aditya_user/time-forecast-app/venv/lib/python3.7/site-packages/statsmodels/tsa/arima_model.py", line 577, in _fit_start_params
    start_params = self._fit_start_params_hr(order, start_ar_lags)
  File "/home/aditya_user/time-forecast-app/venv/lib/python3.7/site-packages/statsmodels/tsa/arima_model.py", line 513, in _fit_start_params_hr
    armod = mod.fit()
  File "/home/aditya_user/time-forecast-app/venv/lib/python3.7/site-packages/statsmodels/tsa/ar_model.py", line 355, in fit
    scale = nobs / (nobs - k)
ZeroDivisionError: division by zero

root - ERROR - Error while using SARIMA on ship_pt: ZTRD, prod_hierarchy: 2 A I B, part_number: 
root - ERROR - Traceback (most recent call last):
  File "/home/aditya_user/time-forecast-app/processing/process.py", line 60, in run
    rmse, mape, pred = algo_obj.get_predictions_rmse_mape(algo_name)
  File "/home/aditya_user/time-forecast-app/processing/algorithms.py", line 135, in get_predictions_rmse_mape
    model_fit = model.fit(disp=0)
  File "/home/aditya_user/time-forecast-app/venv/lib/python3.7/site-packages/statsmodels/tsa/statespace/mlemodel.py", line 607, in fit
    start_params = self.start_params
  File "/home/aditya_user/time-forecast-app/venv/lib/python3.7/site-packages/statsmodels/tsa/statespace/sarimax.py", line 953, in start_params
    warning_description='ARMA and trend')
  File "/home/aditya_user/time-forecast-app/venv/lib/python3.7/site-packages/statsmodels/tsa/statespace/sarimax.py", line 836, in _conditional_sum_squares
    Y = endog[k:]
IndexError: too many indices for array

django.request - ERROR - Internal Server Error: /process/260
Traceback (most recent call last):
  File "/home/aditya_user/time-forecast-app/venv/lib/python3.7/site-packages/django/core/handlers/exception.py", line 34, in inner
    response = get_response(request)
  File "/home/aditya_user/time-forecast-app/venv/lib/python3.7/site-packages/django/core/handlers/base.py", line 115, in _get_response
    response = self.process_exception_by_middleware(e, request)
  File "/home/aditya_user/time-forecast-app/venv/lib/python3.7/site-packages/django/core/handlers/base.py", line 113, in _get_response
    response = wrapped_callback(request, *callback_args, **callback_kwargs)
  File "/home/aditya_user/time-forecast-app/venv/lib/python3.7/site-packages/django/contrib/auth/decorators.py", line 21, in _wrapped_view
    return view_func(request, *args, **kwargs)
  File "/home/aditya_user/time-forecast-app/processing/views.py", line 15, in processing_view
    if Process.run(input):
  File "/home/aditya_user/time-forecast-app/processing/process.py", line 248, in run
    top5 = algo_obj.rankTopAlgorithms(algo_obj.rmse_pred)
  File "/home/aditya_user/time-forecast-app/processing/algorithms.py", line 46, in rankTopAlgorithms
    min_rmse = min(rmse_list)
ValueError: min() arg is an empty sequence
root - ERROR - Error while using ARIMA on ship_pt: ﻿ZTRD, prod_hierarchy: 2 A J E, part_number: EVO
root - ERROR - Traceback (most recent call last):
  File "/home/aditya_user/time-forecast-app/processing/process.py", line 60, in run
    rmse, mape, pred = algo_obj.get_predictions_rmse_mape(algo_name)
  File "/home/aditya_user/time-forecast-app/processing/algorithms.py", line 122, in get_predictions_rmse_mape
    model_fit = model.fit()
  File "/home/aditya_user/time-forecast-app/venv/lib/python3.7/site-packages/statsmodels/tsa/arima/model.py", line 327, in fit
    **method_kwargs)
  File "/home/aditya_user/time-forecast-app/venv/lib/python3.7/site-packages/statsmodels/tsa/statespace/mlemodel.py", line 659, in fit
    skip_hessian=True, **kwargs)
  File "/home/aditya_user/time-forecast-app/venv/lib/python3.7/site-packages/statsmodels/base/model.py", line 526, in fit
    full_output=full_output)
  File "/home/aditya_user/time-forecast-app/venv/lib/python3.7/site-packages/statsmodels/base/optimizer.py", line 218, in _fit
    hess=hessian)
  File "/home/aditya_user/time-forecast-app/venv/lib/python3.7/site-packages/statsmodels/base/optimizer.py", line 440, in _fit_lbfgs
    **extra_kwargs)
  File "/home/aditya_user/time-forecast-app/venv/lib/python3.7/site-packages/scipy/optimize/lbfgsb.py", line 199, in fmin_l_bfgs_b
    **opts)
  File "/home/aditya_user/time-forecast-app/venv/lib/python3.7/site-packages/scipy/optimize/lbfgsb.py", line 345, in _minimize_lbfgsb
    f, g = func_and_grad(x)
  File "/home/aditya_user/time-forecast-app/venv/lib/python3.7/site-packages/scipy/optimize/lbfgsb.py", line 290, in func_and_grad
    f = fun(x, *args)
  File "/home/aditya_user/time-forecast-app/venv/lib/python3.7/site-packages/scipy/optimize/optimize.py", line 327, in function_wrapper
    return function(*(wrapper_args + args))
  File "/home/aditya_user/time-forecast-app/venv/lib/python3.7/site-packages/statsmodels/base/model.py", line 500, in f
    return -self.loglike(params, *args) / nobs
  File "/home/aditya_user/time-forecast-app/venv/lib/python3.7/site-packages/statsmodels/tsa/statespace/mlemodel.py", line 889, in loglike
    loglike = self.ssm.loglike(complex_step=complex_step, **kwargs)
  File "/home/aditya_user/time-forecast-app/venv/lib/python3.7/site-packages/statsmodels/tsa/statespace/kalman_filter.py", line 977, in loglike
    kfilter = self._filter(**kwargs)
  File "/home/aditya_user/time-forecast-app/venv/lib/python3.7/site-packages/statsmodels/tsa/statespace/kalman_filter.py", line 897, in _filter
    self._initialize_state(prefix=prefix, complex_step=complex_step)
  File "/home/aditya_user/time-forecast-app/venv/lib/python3.7/site-packages/statsmodels/tsa/statespace/representation.py", line 950, in _initialize_state
    complex_step=complex_step)
  File "statsmodels/tsa/statespace/_representation.pyx", line 1334, in statsmodels.tsa.statespace._representation.dStatespace.initialize
  File "statsmodels/tsa/statespace/_initialization.pyx", line 288, in statsmodels.tsa.statespace._initialization.dInitialization.initialize
  File "statsmodels/tsa/statespace/_initialization.pyx", line 406, in statsmodels.tsa.statespace._initialization.dInitialization.initialize_stationary_stationary_cov
  File "statsmodels/tsa/statespace/_tools.pyx", line 1206, in statsmodels.tsa.statespace._tools._dsolve_discrete_lyapunov
numpy.linalg.LinAlgError: LU decomposition error.

root - ERROR - Error while using ARMA on ship_pt: ZTRD, prod_hierarchy: 2 A J F, part_number: FLUENT
root - ERROR - Traceback (most recent call last):
  File "/home/aditya_user/time-forecast-app/processing/process.py", line 60, in run
    rmse, mape, pred = algo_obj.get_predictions_rmse_mape(algo_name)
  File "/home/aditya_user/time-forecast-app/processing/algorithms.py", line 132, in get_predictions_rmse_mape
    model_fit = model.fit(disp=0)
  File "/home/aditya_user/time-forecast-app/venv/lib/python3.7/site-packages/statsmodels/tsa/arima_model.py", line 999, in fit
    callback=callback, **kwargs)
  File "/home/aditya_user/time-forecast-app/venv/lib/python3.7/site-packages/statsmodels/base/model.py", line 526, in fit
    full_output=full_output)
  File "/home/aditya_user/time-forecast-app/venv/lib/python3.7/site-packages/statsmodels/base/optimizer.py", line 218, in _fit
    hess=hessian)
  File "/home/aditya_user/time-forecast-app/venv/lib/python3.7/site-packages/statsmodels/base/optimizer.py", line 440, in _fit_lbfgs
    **extra_kwargs)
  File "/home/aditya_user/time-forecast-app/venv/lib/python3.7/site-packages/scipy/optimize/lbfgsb.py", line 199, in fmin_l_bfgs_b
    **opts)
  File "/home/aditya_user/time-forecast-app/venv/lib/python3.7/site-packages/scipy/optimize/lbfgsb.py", line 345, in _minimize_lbfgsb
    f, g = func_and_grad(x)
  File "/home/aditya_user/time-forecast-app/venv/lib/python3.7/site-packages/scipy/optimize/lbfgsb.py", line 290, in func_and_grad
    f = fun(x, *args)
  File "/home/aditya_user/time-forecast-app/venv/lib/python3.7/site-packages/scipy/optimize/optimize.py", line 327, in function_wrapper
    return function(*(wrapper_args + args))
  File "/home/aditya_user/time-forecast-app/venv/lib/python3.7/site-packages/statsmodels/base/model.py", line 500, in f
    return -self.loglike(params, *args) / nobs
  File "/home/aditya_user/time-forecast-app/venv/lib/python3.7/site-packages/statsmodels/tsa/arima_model.py", line 810, in loglike
    return self.loglike_kalman(params, set_sigma2)
  File "/home/aditya_user/time-forecast-app/venv/lib/python3.7/site-packages/statsmodels/tsa/arima_model.py", line 820, in loglike_kalman
    return KalmanFilter.loglike(params, self, set_sigma2)
  File "/home/aditya_user/time-forecast-app/venv/lib/python3.7/site-packages/statsmodels/tsa/kalmanf/kalmanfilter.py", line 220, in loglike
    Z_mat, R_mat, T_mat)
  File "statsmodels/tsa/kalmanf/kalman_loglike.pyx", line 331, in statsmodels.tsa.kalmanf.kalman_loglike.kalman_loglike_double
  File "statsmodels/tsa/kalmanf/kalman_loglike.pyx", line 62, in statsmodels.tsa.kalmanf.kalman_loglike.kalman_filter_double
  File "<__array_function__ internals>", line 6, in pinv
  File "/home/aditya_user/time-forecast-app/venv/lib/python3.7/site-packages/numpy/linalg/linalg.py", line 1961, in pinv
    u, s, vt = svd(a, full_matrices=False, hermitian=hermitian)
  File "<__array_function__ internals>", line 6, in svd
  File "/home/aditya_user/time-forecast-app/venv/lib/python3.7/site-packages/numpy/linalg/linalg.py", line 1626, in svd
    u, s, vh = gufunc(a, signature=signature, extobj=extobj)
  File "/home/aditya_user/time-forecast-app/venv/lib/python3.7/site-packages/numpy/linalg/linalg.py", line 106, in _raise_linalgerror_svd_nonconvergence
    raise LinAlgError("SVD did not converge")
numpy.linalg.LinAlgError: SVD did not converge

root - ERROR - Error while using ARIMA on ship_pt: ZTRD, prod_hierarchy: 2 A K C, part_number: SP
root - ERROR - Traceback (most recent call last):
  File "/home/aditya_user/time-forecast-app/processing/process.py", line 60, in run
    rmse, mape, pred = algo_obj.get_predictions_rmse_mape(algo_name)
  File "/home/aditya_user/time-forecast-app/processing/algorithms.py", line 122, in get_predictions_rmse_mape
    model_fit = model.fit()
  File "/home/aditya_user/time-forecast-app/venv/lib/python3.7/site-packages/statsmodels/tsa/arima/model.py", line 327, in fit
    **method_kwargs)
  File "/home/aditya_user/time-forecast-app/venv/lib/python3.7/site-packages/statsmodels/tsa/statespace/mlemodel.py", line 659, in fit
    skip_hessian=True, **kwargs)
  File "/home/aditya_user/time-forecast-app/venv/lib/python3.7/site-packages/statsmodels/base/model.py", line 526, in fit
    full_output=full_output)
  File "/home/aditya_user/time-forecast-app/venv/lib/python3.7/site-packages/statsmodels/base/optimizer.py", line 218, in _fit
    hess=hessian)
  File "/home/aditya_user/time-forecast-app/venv/lib/python3.7/site-packages/statsmodels/base/optimizer.py", line 440, in _fit_lbfgs
    **extra_kwargs)
  File "/home/aditya_user/time-forecast-app/venv/lib/python3.7/site-packages/scipy/optimize/lbfgsb.py", line 199, in fmin_l_bfgs_b
    **opts)
  File "/home/aditya_user/time-forecast-app/venv/lib/python3.7/site-packages/scipy/optimize/lbfgsb.py", line 345, in _minimize_lbfgsb
    f, g = func_and_grad(x)
  File "/home/aditya_user/time-forecast-app/venv/lib/python3.7/site-packages/scipy/optimize/lbfgsb.py", line 290, in func_and_grad
    f = fun(x, *args)
  File "/home/aditya_user/time-forecast-app/venv/lib/python3.7/site-packages/scipy/optimize/optimize.py", line 327, in function_wrapper
    return function(*(wrapper_args + args))
  File "/home/aditya_user/time-forecast-app/venv/lib/python3.7/site-packages/statsmodels/base/model.py", line 500, in f
    return -self.loglike(params, *args) / nobs
  File "/home/aditya_user/time-forecast-app/venv/lib/python3.7/site-packages/statsmodels/tsa/statespace/mlemodel.py", line 889, in loglike
    loglike = self.ssm.loglike(complex_step=complex_step, **kwargs)
  File "/home/aditya_user/time-forecast-app/venv/lib/python3.7/site-packages/statsmodels/tsa/statespace/kalman_filter.py", line 977, in loglike
    kfilter = self._filter(**kwargs)
  File "/home/aditya_user/time-forecast-app/venv/lib/python3.7/site-packages/statsmodels/tsa/statespace/kalman_filter.py", line 897, in _filter
    self._initialize_state(prefix=prefix, complex_step=complex_step)
  File "/home/aditya_user/time-forecast-app/venv/lib/python3.7/site-packages/statsmodels/tsa/statespace/representation.py", line 950, in _initialize_state
    complex_step=complex_step)
  File "statsmodels/tsa/statespace/_representation.pyx", line 1334, in statsmodels.tsa.statespace._representation.dStatespace.initialize
  File "statsmodels/tsa/statespace/_initialization.pyx", line 288, in statsmodels.tsa.statespace._initialization.dInitialization.initialize
  File "statsmodels/tsa/statespace/_initialization.pyx", line 406, in statsmodels.tsa.statespace._initialization.dInitialization.initialize_stationary_stationary_cov
  File "statsmodels/tsa/statespace/_tools.pyx", line 1206, in statsmodels.tsa.statespace._tools._dsolve_discrete_lyapunov
numpy.linalg.LinAlgError: LU decomposition error.

root - ERROR - Error while using ARMA on ship_pt: ZTRD, prod_hierarchy: 2 A K C, part_number: SP
root - ERROR - Traceback (most recent call last):
  File "/home/aditya_user/time-forecast-app/processing/process.py", line 60, in run
    rmse, mape, pred = algo_obj.get_predictions_rmse_mape(algo_name)
  File "/home/aditya_user/time-forecast-app/processing/algorithms.py", line 132, in get_predictions_rmse_mape
    model_fit = model.fit(disp=0)
  File "/home/aditya_user/time-forecast-app/venv/lib/python3.7/site-packages/statsmodels/tsa/arima_model.py", line 986, in fit
    start_ar_lags)
  File "/home/aditya_user/time-forecast-app/venv/lib/python3.7/site-packages/statsmodels/tsa/arima_model.py", line 577, in _fit_start_params
    start_params = self._fit_start_params_hr(order, start_ar_lags)
  File "/home/aditya_user/time-forecast-app/venv/lib/python3.7/site-packages/statsmodels/tsa/arima_model.py", line 562, in _fit_start_params_hr
    raise ValueError("The computed initial MA coefficients are not "
ValueError: The computed initial MA coefficients are not invertible
You should induce invertibility, choose a different model order, or you can
pass your own start_params.

root - ERROR - Error while using ARIMA on ship_pt: ZTRD, prod_hierarchy: 2 A L E, part_number: SP
root - ERROR - Traceback (most recent call last):
  File "/home/aditya_user/time-forecast-app/processing/process.py", line 60, in run
    rmse, mape, pred = algo_obj.get_predictions_rmse_mape(algo_name)
  File "/home/aditya_user/time-forecast-app/processing/algorithms.py", line 122, in get_predictions_rmse_mape
    model_fit = model.fit()
  File "/home/aditya_user/time-forecast-app/venv/lib/python3.7/site-packages/statsmodels/tsa/arima/model.py", line 327, in fit
    **method_kwargs)
  File "/home/aditya_user/time-forecast-app/venv/lib/python3.7/site-packages/statsmodels/tsa/statespace/mlemodel.py", line 659, in fit
    skip_hessian=True, **kwargs)
  File "/home/aditya_user/time-forecast-app/venv/lib/python3.7/site-packages/statsmodels/base/model.py", line 526, in fit
    full_output=full_output)
  File "/home/aditya_user/time-forecast-app/venv/lib/python3.7/site-packages/statsmodels/base/optimizer.py", line 218, in _fit
    hess=hessian)
  File "/home/aditya_user/time-forecast-app/venv/lib/python3.7/site-packages/statsmodels/base/optimizer.py", line 440, in _fit_lbfgs
    **extra_kwargs)
  File "/home/aditya_user/time-forecast-app/venv/lib/python3.7/site-packages/scipy/optimize/lbfgsb.py", line 199, in fmin_l_bfgs_b
    **opts)
  File "/home/aditya_user/time-forecast-app/venv/lib/python3.7/site-packages/scipy/optimize/lbfgsb.py", line 345, in _minimize_lbfgsb
    f, g = func_and_grad(x)
  File "/home/aditya_user/time-forecast-app/venv/lib/python3.7/site-packages/scipy/optimize/lbfgsb.py", line 290, in func_and_grad
    f = fun(x, *args)
  File "/home/aditya_user/time-forecast-app/venv/lib/python3.7/site-packages/scipy/optimize/optimize.py", line 327, in function_wrapper
    return function(*(wrapper_args + args))
  File "/home/aditya_user/time-forecast-app/venv/lib/python3.7/site-packages/statsmodels/base/model.py", line 500, in f
    return -self.loglike(params, *args) / nobs
  File "/home/aditya_user/time-forecast-app/venv/lib/python3.7/site-packages/statsmodels/tsa/statespace/mlemodel.py", line 889, in loglike
    loglike = self.ssm.loglike(complex_step=complex_step, **kwargs)
  File "/home/aditya_user/time-forecast-app/venv/lib/python3.7/site-packages/statsmodels/tsa/statespace/kalman_filter.py", line 977, in loglike
    kfilter = self._filter(**kwargs)
  File "/home/aditya_user/time-forecast-app/venv/lib/python3.7/site-packages/statsmodels/tsa/statespace/kalman_filter.py", line 897, in _filter
    self._initialize_state(prefix=prefix, complex_step=complex_step)
  File "/home/aditya_user/time-forecast-app/venv/lib/python3.7/site-packages/statsmodels/tsa/statespace/representation.py", line 950, in _initialize_state
    complex_step=complex_step)
  File "statsmodels/tsa/statespace/_representation.pyx", line 1334, in statsmodels.tsa.statespace._representation.dStatespace.initialize
  File "statsmodels/tsa/statespace/_initialization.pyx", line 288, in statsmodels.tsa.statespace._initialization.dInitialization.initialize
  File "statsmodels/tsa/statespace/_initialization.pyx", line 406, in statsmodels.tsa.statespace._initialization.dInitialization.initialize_stationary_stationary_cov
  File "statsmodels/tsa/statespace/_tools.pyx", line 1206, in statsmodels.tsa.statespace._tools._dsolve_discrete_lyapunov
numpy.linalg.LinAlgError: LU decomposition error.

root - ERROR - Error while using ARMA on ship_pt: ZTRD, prod_hierarchy: 2 A L E, part_number: SP
root - ERROR - Traceback (most recent call last):
  File "/home/aditya_user/time-forecast-app/processing/process.py", line 60, in run
    rmse, mape, pred = algo_obj.get_predictions_rmse_mape(algo_name)
  File "/home/aditya_user/time-forecast-app/processing/algorithms.py", line 132, in get_predictions_rmse_mape
    model_fit = model.fit(disp=0)
  File "/home/aditya_user/time-forecast-app/venv/lib/python3.7/site-packages/statsmodels/tsa/arima_model.py", line 986, in fit
    start_ar_lags)
  File "/home/aditya_user/time-forecast-app/venv/lib/python3.7/site-packages/statsmodels/tsa/arima_model.py", line 577, in _fit_start_params
    start_params = self._fit_start_params_hr(order, start_ar_lags)
  File "/home/aditya_user/time-forecast-app/venv/lib/python3.7/site-packages/statsmodels/tsa/arima_model.py", line 555, in _fit_start_params_hr
    raise ValueError("The computed initial AR coefficients are not "
ValueError: The computed initial AR coefficients are not stationary
You should induce stationarity, choose a different model order, or you can
pass your own start_params.

root - ERROR - Error while using ARIMA on ship_pt: ZTRD, prod_hierarchy: 2 B A F, part_number: SP
root - ERROR - Traceback (most recent call last):
  File "/home/aditya_user/time-forecast-app/processing/process.py", line 60, in run
    rmse, mape, pred = algo_obj.get_predictions_rmse_mape(algo_name)
  File "/home/aditya_user/time-forecast-app/processing/algorithms.py", line 122, in get_predictions_rmse_mape
    model_fit = model.fit()
  File "/home/aditya_user/time-forecast-app/venv/lib/python3.7/site-packages/statsmodels/tsa/arima/model.py", line 327, in fit
    **method_kwargs)
  File "/home/aditya_user/time-forecast-app/venv/lib/python3.7/site-packages/statsmodels/tsa/statespace/mlemodel.py", line 659, in fit
    skip_hessian=True, **kwargs)
  File "/home/aditya_user/time-forecast-app/venv/lib/python3.7/site-packages/statsmodels/base/model.py", line 526, in fit
    full_output=full_output)
  File "/home/aditya_user/time-forecast-app/venv/lib/python3.7/site-packages/statsmodels/base/optimizer.py", line 218, in _fit
    hess=hessian)
  File "/home/aditya_user/time-forecast-app/venv/lib/python3.7/site-packages/statsmodels/base/optimizer.py", line 440, in _fit_lbfgs
    **extra_kwargs)
  File "/home/aditya_user/time-forecast-app/venv/lib/python3.7/site-packages/scipy/optimize/lbfgsb.py", line 199, in fmin_l_bfgs_b
    **opts)
  File "/home/aditya_user/time-forecast-app/venv/lib/python3.7/site-packages/scipy/optimize/lbfgsb.py", line 345, in _minimize_lbfgsb
    f, g = func_and_grad(x)
  File "/home/aditya_user/time-forecast-app/venv/lib/python3.7/site-packages/scipy/optimize/lbfgsb.py", line 290, in func_and_grad
    f = fun(x, *args)
  File "/home/aditya_user/time-forecast-app/venv/lib/python3.7/site-packages/scipy/optimize/optimize.py", line 327, in function_wrapper
    return function(*(wrapper_args + args))
  File "/home/aditya_user/time-forecast-app/venv/lib/python3.7/site-packages/statsmodels/base/model.py", line 500, in f
    return -self.loglike(params, *args) / nobs
  File "/home/aditya_user/time-forecast-app/venv/lib/python3.7/site-packages/statsmodels/tsa/statespace/mlemodel.py", line 889, in loglike
    loglike = self.ssm.loglike(complex_step=complex_step, **kwargs)
  File "/home/aditya_user/time-forecast-app/venv/lib/python3.7/site-packages/statsmodels/tsa/statespace/kalman_filter.py", line 977, in loglike
    kfilter = self._filter(**kwargs)
  File "/home/aditya_user/time-forecast-app/venv/lib/python3.7/site-packages/statsmodels/tsa/statespace/kalman_filter.py", line 897, in _filter
    self._initialize_state(prefix=prefix, complex_step=complex_step)
  File "/home/aditya_user/time-forecast-app/venv/lib/python3.7/site-packages/statsmodels/tsa/statespace/representation.py", line 950, in _initialize_state
    complex_step=complex_step)
  File "statsmodels/tsa/statespace/_representation.pyx", line 1334, in statsmodels.tsa.statespace._representation.dStatespace.initialize
  File "statsmodels/tsa/statespace/_initialization.pyx", line 288, in statsmodels.tsa.statespace._initialization.dInitialization.initialize
  File "statsmodels/tsa/statespace/_initialization.pyx", line 406, in statsmodels.tsa.statespace._initialization.dInitialization.initialize_stationary_stationary_cov
  File "statsmodels/tsa/statespace/_tools.pyx", line 1284, in statsmodels.tsa.statespace._tools._dsolve_discrete_lyapunov
numpy.linalg.LinAlgError: Schur decomposition solver error.

root - ERROR - Error while using ARMA on ship_pt: ZTRD, prod_hierarchy: 2 B A F, part_number: SP
root - ERROR - Traceback (most recent call last):
  File "/home/aditya_user/time-forecast-app/processing/process.py", line 60, in run
    rmse, mape, pred = algo_obj.get_predictions_rmse_mape(algo_name)
  File "/home/aditya_user/time-forecast-app/processing/algorithms.py", line 132, in get_predictions_rmse_mape
    model_fit = model.fit(disp=0)
  File "/home/aditya_user/time-forecast-app/venv/lib/python3.7/site-packages/statsmodels/tsa/arima_model.py", line 986, in fit
    start_ar_lags)
  File "/home/aditya_user/time-forecast-app/venv/lib/python3.7/site-packages/statsmodels/tsa/arima_model.py", line 577, in _fit_start_params
    start_params = self._fit_start_params_hr(order, start_ar_lags)
  File "/home/aditya_user/time-forecast-app/venv/lib/python3.7/site-packages/statsmodels/tsa/arima_model.py", line 555, in _fit_start_params_hr
    raise ValueError("The computed initial AR coefficients are not "
ValueError: The computed initial AR coefficients are not stationary
You should induce stationarity, choose a different model order, or you can
pass your own start_params.

