root - ERROR - Error while using ARMA on ship_pt: ZTRD10037401, prod_hierarchy: ZTRD, part_number: 10037401
root - ERROR - Traceback (most recent call last):
  File "/home/aditya_user/time-forecast-app/processing/process.py", line 62, in run
    rmse, mape, pred = algo_obj.get_predictions_rmse_mape(algo_name)
  File "/home/aditya_user/time-forecast-app/processing/algorithms.py", line 136, in get_predictions_rmse_mape
    model_fit = model.fit(disp=0)
  File "/home/aditya_user/time-forecast-app/venv/lib/python3.7/site-packages/statsmodels/tsa/arima_model.py", line 986, in fit
    start_ar_lags)
  File "/home/aditya_user/time-forecast-app/venv/lib/python3.7/site-packages/statsmodels/tsa/arima_model.py", line 577, in _fit_start_params
    start_params = self._fit_start_params_hr(order, start_ar_lags)
  File "/home/aditya_user/time-forecast-app/venv/lib/python3.7/site-packages/statsmodels/tsa/arima_model.py", line 562, in _fit_start_params_hr
    raise ValueError("The computed initial MA coefficients are not "
ValueError: The computed initial MA coefficients are not invertible
You should induce invertibility, choose a different model order, or you can
pass your own start_params.

django.request - ERROR - Internal Server Error: /process/322
Traceback (most recent call last):
  File "/home/aditya_user/time-forecast-app/venv/lib/python3.7/site-packages/django/core/handlers/exception.py", line 34, in inner
    response = get_response(request)
  File "/home/aditya_user/time-forecast-app/venv/lib/python3.7/site-packages/django/core/handlers/base.py", line 115, in _get_response
    response = self.process_exception_by_middleware(e, request)
  File "/home/aditya_user/time-forecast-app/venv/lib/python3.7/site-packages/django/core/handlers/base.py", line 113, in _get_response
    response = wrapped_callback(request, *callback_args, **callback_kwargs)
  File "/home/aditya_user/time-forecast-app/venv/lib/python3.7/site-packages/django/contrib/auth/decorators.py", line 21, in _wrapped_view
    return view_func(request, *args, **kwargs)
  File "/home/aditya_user/time-forecast-app/processing/views.py", line 15, in processing_view
    if Process.run(input):
  File "/home/aditya_user/time-forecast-app/processing/process.py", line 250, in run
    top5 = algo_obj.rankTopAlgorithms(algo_obj.rmse_pred)
  File "/home/aditya_user/time-forecast-app/processing/algorithms.py", line 46, in rankTopAlgorithms
    min_rmse = min(rmse_list)
ValueError: min() arg is an empty sequence
django.request - WARNING - Not Found: /favicon.ico
django.security.DisallowedHost - ERROR - Invalid HTTP_HOST header: 'ip.ws.126.net:443'. You may need to add 'ip.ws.126.net' to ALLOWED_HOSTS.
django.request - WARNING - Bad Request: /
django.security.DisallowedHost - ERROR - Invalid HTTP_HOST header: '127.0.0.1'. You may need to add '127.0.0.1' to ALLOWED_HOSTS.
django.request - WARNING - Bad Request: /cgi-bin/mainfunction.cgi
django.request - WARNING - Not Found: /hudson
django.security.DisallowedHost - ERROR - Invalid HTTP_HOST header: 'li1038-174.members.linode.com'. You may need to add 'li1038-174.members.linode.com' to ALLOWED_HOSTS.
django.request - WARNING - Bad Request: /
django.request - WARNING - Not Found: /favicon.ico
django.request - WARNING - Not Found: /favicon.ico
django.request - WARNING - Not Found: /favicon.ico
django.request - WARNING - Not Found: /favicon.ico
django.request - WARNING - Not Found: /favicon.ico
django.request - WARNING - Not Found: /login/adityagator.github.io
django.request - WARNING - Not Found: /favicon.ico
django.request - WARNING - Not Found: /favicon.ico
django.request - WARNING - Not Found: /favicon.ico
django.request - WARNING - Not Found: /favicon.ico
django.request - WARNING - Not Found: /favicon.ico
django.request - WARNING - Not Found: /favicon.ico
django.request - WARNING - Not Found: /favicon.ico
root - ERROR - Exception raised during clustering:
root - ERROR - Traceback (most recent call last):
  File "/home/aditya_user/time-forecast-app/processing/cluster.py", line 18, in run
    raise Exception("Input file must contain at least 3 rows for clustering.")
Exception: Input file must contain at least 3 rows for clustering.

django.request - ERROR - Internal Server Error: /process/325
Traceback (most recent call last):
  File "/home/aditya_user/time-forecast-app/venv/lib/python3.7/site-packages/django/core/handlers/exception.py", line 34, in inner
    response = get_response(request)
  File "/home/aditya_user/time-forecast-app/venv/lib/python3.7/site-packages/django/core/handlers/base.py", line 115, in _get_response
    response = self.process_exception_by_middleware(e, request)
  File "/home/aditya_user/time-forecast-app/venv/lib/python3.7/site-packages/django/core/handlers/base.py", line 113, in _get_response
    response = wrapped_callback(request, *callback_args, **callback_kwargs)
  File "/home/aditya_user/time-forecast-app/venv/lib/python3.7/site-packages/django/contrib/auth/decorators.py", line 21, in _wrapped_view
    return view_func(request, *args, **kwargs)
  File "/home/aditya_user/time-forecast-app/processing/views.py", line 15, in processing_view
    if Process.run(input):
  File "/home/aditya_user/time-forecast-app/processing/process.py", line 44, in run
    vol_cluster, int_cluster, vol_count, int_count = Cluster.run(dict_data)
  File "/home/aditya_user/time-forecast-app/processing/cluster.py", line 81, in run
    return final_vol_dict, final_int_dict, vol_dict, int_dict
UnboundLocalError: local variable 'int_dict' referenced before assignment
django.request - WARNING - Not Found: /favicon.ico
root - ERROR - Error while using ARMA on ship_pt: ZTRD, prod_hierarchy: 1 A I E, part_number: 10030450
root - ERROR - Traceback (most recent call last):
  File "/home/aditya_user/time-forecast-app/processing/process.py", line 62, in run
    rmse, mape, pred = algo_obj.get_predictions_rmse_mape(algo_name)
  File "/home/aditya_user/time-forecast-app/processing/algorithms.py", line 136, in get_predictions_rmse_mape
    model_fit = model.fit(disp=0)
  File "/home/aditya_user/time-forecast-app/venv/lib/python3.7/site-packages/statsmodels/tsa/arima_model.py", line 999, in fit
    callback=callback, **kwargs)
  File "/home/aditya_user/time-forecast-app/venv/lib/python3.7/site-packages/statsmodels/base/model.py", line 526, in fit
    full_output=full_output)
  File "/home/aditya_user/time-forecast-app/venv/lib/python3.7/site-packages/statsmodels/base/optimizer.py", line 218, in _fit
    hess=hessian)
  File "/home/aditya_user/time-forecast-app/venv/lib/python3.7/site-packages/statsmodels/base/optimizer.py", line 440, in _fit_lbfgs
    **extra_kwargs)
  File "/home/aditya_user/time-forecast-app/venv/lib/python3.7/site-packages/scipy/optimize/lbfgsb.py", line 199, in fmin_l_bfgs_b
    **opts)
  File "/home/aditya_user/time-forecast-app/venv/lib/python3.7/site-packages/scipy/optimize/lbfgsb.py", line 345, in _minimize_lbfgsb
    f, g = func_and_grad(x)
  File "/home/aditya_user/time-forecast-app/venv/lib/python3.7/site-packages/scipy/optimize/lbfgsb.py", line 290, in func_and_grad
    f = fun(x, *args)
  File "/home/aditya_user/time-forecast-app/venv/lib/python3.7/site-packages/scipy/optimize/optimize.py", line 327, in function_wrapper
    return function(*(wrapper_args + args))
  File "/home/aditya_user/time-forecast-app/venv/lib/python3.7/site-packages/statsmodels/base/model.py", line 500, in f
    return -self.loglike(params, *args) / nobs
  File "/home/aditya_user/time-forecast-app/venv/lib/python3.7/site-packages/statsmodels/tsa/arima_model.py", line 810, in loglike
    return self.loglike_kalman(params, set_sigma2)
  File "/home/aditya_user/time-forecast-app/venv/lib/python3.7/site-packages/statsmodels/tsa/arima_model.py", line 820, in loglike_kalman
    return KalmanFilter.loglike(params, self, set_sigma2)
  File "/home/aditya_user/time-forecast-app/venv/lib/python3.7/site-packages/statsmodels/tsa/kalmanf/kalmanfilter.py", line 220, in loglike
    Z_mat, R_mat, T_mat)
  File "statsmodels/tsa/kalmanf/kalman_loglike.pyx", line 331, in statsmodels.tsa.kalmanf.kalman_loglike.kalman_loglike_double
  File "statsmodels/tsa/kalmanf/kalman_loglike.pyx", line 62, in statsmodels.tsa.kalmanf.kalman_loglike.kalman_filter_double
  File "<__array_function__ internals>", line 6, in pinv
  File "/home/aditya_user/time-forecast-app/venv/lib/python3.7/site-packages/numpy/linalg/linalg.py", line 1961, in pinv
    u, s, vt = svd(a, full_matrices=False, hermitian=hermitian)
  File "<__array_function__ internals>", line 6, in svd
  File "/home/aditya_user/time-forecast-app/venv/lib/python3.7/site-packages/numpy/linalg/linalg.py", line 1626, in svd
    u, s, vh = gufunc(a, signature=signature, extobj=extobj)
  File "/home/aditya_user/time-forecast-app/venv/lib/python3.7/site-packages/numpy/linalg/linalg.py", line 106, in _raise_linalgerror_svd_nonconvergence
    raise LinAlgError("SVD did not converge")
numpy.linalg.LinAlgError: SVD did not converge

django.request - WARNING - Not Found: /favicon.ico
django.request - WARNING - Not Found: /favicon.ico
root - ERROR - Error while using ARMA on ship_pt: ZTRD, prod_hierarchy: 1 A I E, part_number: 10030450
root - ERROR - Traceback (most recent call last):
  File "/home/aditya_user/time-forecast-app/processing/process.py", line 62, in run
    rmse, mape, pred = algo_obj.get_predictions_rmse_mape(algo_name)
  File "/home/aditya_user/time-forecast-app/processing/algorithms.py", line 136, in get_predictions_rmse_mape
    model_fit = model.fit(disp=0)
  File "/home/aditya_user/time-forecast-app/venv/lib/python3.7/site-packages/statsmodels/tsa/arima_model.py", line 999, in fit
    callback=callback, **kwargs)
  File "/home/aditya_user/time-forecast-app/venv/lib/python3.7/site-packages/statsmodels/base/model.py", line 526, in fit
    full_output=full_output)
  File "/home/aditya_user/time-forecast-app/venv/lib/python3.7/site-packages/statsmodels/base/optimizer.py", line 218, in _fit
    hess=hessian)
  File "/home/aditya_user/time-forecast-app/venv/lib/python3.7/site-packages/statsmodels/base/optimizer.py", line 440, in _fit_lbfgs
    **extra_kwargs)
  File "/home/aditya_user/time-forecast-app/venv/lib/python3.7/site-packages/scipy/optimize/lbfgsb.py", line 199, in fmin_l_bfgs_b
    **opts)
  File "/home/aditya_user/time-forecast-app/venv/lib/python3.7/site-packages/scipy/optimize/lbfgsb.py", line 345, in _minimize_lbfgsb
    f, g = func_and_grad(x)
  File "/home/aditya_user/time-forecast-app/venv/lib/python3.7/site-packages/scipy/optimize/lbfgsb.py", line 290, in func_and_grad
    f = fun(x, *args)
  File "/home/aditya_user/time-forecast-app/venv/lib/python3.7/site-packages/scipy/optimize/optimize.py", line 327, in function_wrapper
    return function(*(wrapper_args + args))
  File "/home/aditya_user/time-forecast-app/venv/lib/python3.7/site-packages/statsmodels/base/model.py", line 500, in f
    return -self.loglike(params, *args) / nobs
  File "/home/aditya_user/time-forecast-app/venv/lib/python3.7/site-packages/statsmodels/tsa/arima_model.py", line 810, in loglike
    return self.loglike_kalman(params, set_sigma2)
  File "/home/aditya_user/time-forecast-app/venv/lib/python3.7/site-packages/statsmodels/tsa/arima_model.py", line 820, in loglike_kalman
    return KalmanFilter.loglike(params, self, set_sigma2)
  File "/home/aditya_user/time-forecast-app/venv/lib/python3.7/site-packages/statsmodels/tsa/kalmanf/kalmanfilter.py", line 220, in loglike
    Z_mat, R_mat, T_mat)
  File "statsmodels/tsa/kalmanf/kalman_loglike.pyx", line 331, in statsmodels.tsa.kalmanf.kalman_loglike.kalman_loglike_double
  File "statsmodels/tsa/kalmanf/kalman_loglike.pyx", line 62, in statsmodels.tsa.kalmanf.kalman_loglike.kalman_filter_double
  File "<__array_function__ internals>", line 6, in pinv
  File "/home/aditya_user/time-forecast-app/venv/lib/python3.7/site-packages/numpy/linalg/linalg.py", line 1961, in pinv
    u, s, vt = svd(a, full_matrices=False, hermitian=hermitian)
  File "<__array_function__ internals>", line 6, in svd
  File "/home/aditya_user/time-forecast-app/venv/lib/python3.7/site-packages/numpy/linalg/linalg.py", line 1626, in svd
    u, s, vh = gufunc(a, signature=signature, extobj=extobj)
  File "/home/aditya_user/time-forecast-app/venv/lib/python3.7/site-packages/numpy/linalg/linalg.py", line 106, in _raise_linalgerror_svd_nonconvergence
    raise LinAlgError("SVD did not converge")
numpy.linalg.LinAlgError: SVD did not converge

