root - ERROR - Error while using ARIMA on ship_pt: ZTRD10037401, prod_hierarchy: ZTRD, part_number: 10037401
root - ERROR - Traceback (most recent call last):
  File "/home/aditya_user/time-forecast-app/processing/process.py", line 62, in run
    rmse, mape, pred = algo_obj.get_predictions_rmse_mape(algo_name)
  File "/home/aditya_user/time-forecast-app/processing/algorithms.py", line 146, in get_predictions_rmse_mape
    self.rmse2[min_algo] = rmse
AttributeError: 'Algorithms' object has no attribute 'rmse2'

root - ERROR - Error while using MOVING AVERAGE on ship_pt: ZTRD10037401, prod_hierarchy: ZTRD, part_number: 10037401
root - ERROR - Traceback (most recent call last):
  File "/home/aditya_user/time-forecast-app/processing/process.py", line 62, in run
    rmse, mape, pred = algo_obj.get_predictions_rmse_mape(algo_name)
  File "/home/aditya_user/time-forecast-app/processing/algorithms.py", line 146, in get_predictions_rmse_mape
    self.rmse2[min_algo] = rmse
AttributeError: 'Algorithms' object has no attribute 'rmse2'

root - ERROR - Error while using AR on ship_pt: ZTRD10037401, prod_hierarchy: ZTRD, part_number: 10037401
root - ERROR - Traceback (most recent call last):
  File "/home/aditya_user/time-forecast-app/processing/process.py", line 62, in run
    rmse, mape, pred = algo_obj.get_predictions_rmse_mape(algo_name)
  File "/home/aditya_user/time-forecast-app/processing/algorithms.py", line 146, in get_predictions_rmse_mape
    self.rmse2[min_algo] = rmse
AttributeError: 'Algorithms' object has no attribute 'rmse2'

root - ERROR - Error while using ARMA on ship_pt: ZTRD10037401, prod_hierarchy: ZTRD, part_number: 10037401
root - ERROR - Traceback (most recent call last):
  File "/home/aditya_user/time-forecast-app/processing/process.py", line 62, in run
    rmse, mape, pred = algo_obj.get_predictions_rmse_mape(algo_name)
  File "/home/aditya_user/time-forecast-app/processing/algorithms.py", line 129, in get_predictions_rmse_mape
    model_fit = model.fit(disp=0)
  File "/home/aditya_user/time-forecast-app/venv/lib/python3.7/site-packages/statsmodels/tsa/arima_model.py", line 986, in fit
    start_ar_lags)
  File "/home/aditya_user/time-forecast-app/venv/lib/python3.7/site-packages/statsmodels/tsa/arima_model.py", line 577, in _fit_start_params
    start_params = self._fit_start_params_hr(order, start_ar_lags)
  File "/home/aditya_user/time-forecast-app/venv/lib/python3.7/site-packages/statsmodels/tsa/arima_model.py", line 562, in _fit_start_params_hr
    raise ValueError("The computed initial MA coefficients are not "
ValueError: The computed initial MA coefficients are not invertible
You should induce invertibility, choose a different model order, or you can
pass your own start_params.

root - ERROR - Error while using SARIMA on ship_pt: ZTRD10037401, prod_hierarchy: ZTRD, part_number: 10037401
root - ERROR - Traceback (most recent call last):
  File "/home/aditya_user/time-forecast-app/processing/process.py", line 62, in run
    rmse, mape, pred = algo_obj.get_predictions_rmse_mape(algo_name)
  File "/home/aditya_user/time-forecast-app/processing/algorithms.py", line 146, in get_predictions_rmse_mape
    self.rmse2[min_algo] = rmse
AttributeError: 'Algorithms' object has no attribute 'rmse2'

root - ERROR - Error while using SES on ship_pt: ZTRD10037401, prod_hierarchy: ZTRD, part_number: 10037401
root - ERROR - Traceback (most recent call last):
  File "/home/aditya_user/time-forecast-app/processing/process.py", line 62, in run
    rmse, mape, pred = algo_obj.get_predictions_rmse_mape(algo_name)
  File "/home/aditya_user/time-forecast-app/processing/algorithms.py", line 146, in get_predictions_rmse_mape
    self.rmse2[min_algo] = rmse
AttributeError: 'Algorithms' object has no attribute 'rmse2'

root - ERROR - Error while using HWES method on ship_pt: ZTRD10037401, prod_hierarchy: ZTRD, part_number: 10037401
root - ERROR - Traceback (most recent call last):
  File "/home/aditya_user/time-forecast-app/processing/process.py", line 147, in run
    algo_obj.rmse_pred[Constants.HWES] = [rmse, predictions]
UnboundLocalError: local variable 'rmse' referenced before assignment

root - ERROR - Error while using ARIMA on ship_pt: ZTRD10037402, prod_hierarchy: ZTRD, part_number: 10037402
root - ERROR - Traceback (most recent call last):
  File "/home/aditya_user/time-forecast-app/processing/process.py", line 62, in run
    rmse, mape, pred = algo_obj.get_predictions_rmse_mape(algo_name)
  File "/home/aditya_user/time-forecast-app/processing/algorithms.py", line 146, in get_predictions_rmse_mape
    self.rmse2[min_algo] = rmse
AttributeError: 'Algorithms' object has no attribute 'rmse2'

root - ERROR - Error while using MOVING AVERAGE on ship_pt: ZTRD10037402, prod_hierarchy: ZTRD, part_number: 10037402
root - ERROR - Traceback (most recent call last):
  File "/home/aditya_user/time-forecast-app/processing/process.py", line 62, in run
    rmse, mape, pred = algo_obj.get_predictions_rmse_mape(algo_name)
  File "/home/aditya_user/time-forecast-app/processing/algorithms.py", line 146, in get_predictions_rmse_mape
    self.rmse2[min_algo] = rmse
AttributeError: 'Algorithms' object has no attribute 'rmse2'

root - ERROR - Error while using AR on ship_pt: ZTRD10037402, prod_hierarchy: ZTRD, part_number: 10037402
root - ERROR - Traceback (most recent call last):
  File "/home/aditya_user/time-forecast-app/processing/process.py", line 62, in run
    rmse, mape, pred = algo_obj.get_predictions_rmse_mape(algo_name)
  File "/home/aditya_user/time-forecast-app/processing/algorithms.py", line 146, in get_predictions_rmse_mape
    self.rmse2[min_algo] = rmse
AttributeError: 'Algorithms' object has no attribute 'rmse2'

root - ERROR - Error while using ARMA on ship_pt: ZTRD10037402, prod_hierarchy: ZTRD, part_number: 10037402
root - ERROR - Traceback (most recent call last):
  File "/home/aditya_user/time-forecast-app/processing/process.py", line 62, in run
    rmse, mape, pred = algo_obj.get_predictions_rmse_mape(algo_name)
  File "/home/aditya_user/time-forecast-app/processing/algorithms.py", line 146, in get_predictions_rmse_mape
    self.rmse2[min_algo] = rmse
AttributeError: 'Algorithms' object has no attribute 'rmse2'

root - ERROR - Error while using SARIMA on ship_pt: ZTRD10037402, prod_hierarchy: ZTRD, part_number: 10037402
root - ERROR - Traceback (most recent call last):
  File "/home/aditya_user/time-forecast-app/processing/process.py", line 62, in run
    rmse, mape, pred = algo_obj.get_predictions_rmse_mape(algo_name)
  File "/home/aditya_usdjango.security.DisallowedHost - ERROR - Invalid HTTP_HOST header: '192.154.229.223:80'. You may need to add '192.154.229.223' to ALLOWED_HOSTS.
django.request - WARNING - Bad Request: /shell
R - Error while using SES on ship_pt: ZTRD10037402, prod_hierarchy: ZTRD, part_number: 10037402
root - ERROR - Traceback (most recent call last):
  File "/home/aditya_user/time-forecast-app/processing/process.py", line 62, in run
    rmse, mape, pred = algo_obj.get_predictions_rmse_mape(algo_name)
  File "/home/aditya_user/time-forecast-app/processing/algorithms.py", line 146, in get_predictions_rmse_mape
    self.rmse2[min_algo] = rmse
AttributeError: 'Algorithms' object has no attribute 'rmse2'

root - ERROR - Error while using HWES method on ship_pt: ZTRD10037402, prod_hierarchy: ZTRD, part_number: 10037402
root - ERROR - Traceback (most recent call last):
  File "/home/aditya_user/time-forecast-app/processing/process.py", line 147, in run
    algo_obj.rmse_pred[Constants.HWES] = [rmse, predictions]
UnboundLocalError: local variable 'rmse' referenced before assignment

root - ERROR - Error while using ARIMA on ship_pt: ZTRD10037404, prod_hierarchy: ZTRD, part_number: 10037404
root - ERROR - Traceback (most recent call last):
  File "/home/aditya_user/time-forecast-app/processing/process.py", line 62, in run
    rmse, mape, pred = algo_obj.get_predictions_rmse_mape(algo_name)
  File "/home/aditya_user/time-forecast-app/processing/algorithms.py", line 146, in get_predictions_rmse_mape
    self.rmse2[min_algo] = rmse
AttributeError: 'Algorithms' object has no attribute 'rmse2'

root - ERROR - Error while using MOVING AVERAGE on ship_pt: ZTRD10037404, prod_hierarchy: ZTRD, part_number: 10037404
root - ERROR - Traceback (most recent call last):
  File "/home/aditya_user/time-forecast-app/processing/process.py", line 62, in run
    rmse, mape, pred = algo_obj.get_predictions_rmse_mape(algo_name)
  File "/home/aditya_user/time-forecast-app/processing/algorithms.py", line 146, in get_predictions_rmse_mape
    self.rmse2[min_algo] = rmse
AttributeError: 'Algorithms' object has no attribute 'rmse2'

root - ERROR - Error while using AR on ship_pt: ZTRD10037404, prod_hierarchy: ZTRD, part_number: 10037404
root - ERROR - Traceback (most recent call last):
  File "/home/aditya_user/time-forecast-app/processing/process.py", line 62, in run
    rmse, mape, pred = algo_obj.get_predictions_rmse_mape(algo_name)
  File "/home/aditya_user/time-forecast-app/processing/algorithms.py", line 146, in get_predictions_rmse_mape
    self.rmse2[min_algo] = rmse
AttributeError: 'Algorithms' object has no attribute 'rmse2'

root - ERROR - Error while using ARMA on ship_pt: ZTRD10037404, prod_hierarchy: ZTRD, part_number: 10037404
root - ERROR - Traceback (most recent call last):
  File "/home/aditya_user/time-forecast-app/processing/process.py", line 62, in run
    rmse, mape, pred = algo_obj.get_predictions_rmse_mape(algo_name)
  File "/home/aditya_user/time-forecast-app/processing/algorithms.py", line 146, in get_predictions_rmse_mape
    self.rmse2[min_algo] = rmse
AttributeError: 'Algorithms' object has no attribute 'rmse2'

root - ERROR - Error while using SARIMA on ship_pt: ZTRD10037404, prod_hierarchy: ZTRD, part_number: 10037404
root - ERROR - Traceback (most recent call last):
  File "/home/aditya_user/time-forecast-app/processing/process.py", line 62, in run
    rmse, mape, pred = algo_obj.get_predictions_rmse_mape(algo_name)
  File "/home/aditya_user/time-forecast-app/processing/algorithms.py", line 146, in get_predictions_rmse_mape
    self.rmse2[min_algo] = rmse
AttributeError: 'Algorithms' object has no attribute 'rmse2'

root - ERROR - Error while using SES on ship_pt: ZTRD10037404, prod_hierarchy: ZTRD, part_number: 10037404
root - ERROR - Traceback (most recent call last):
  File "/home/aditya_user/time-forecast-app/processing/process.py", line 62, in run
    rmse, mape, pred = algo_obj.get_predictions_rmse_mape(algo_name)
  File "/home/aditya_user/time-forecast-app/processing/algorithms.py", line 146, in get_predictions_rmse_mape
    self.rmse2[min_algo] = rmse
AttributeError: 'Algorithms' object has no attribute 'rmse2'

root - ERROR - Error while using HWES method on ship_pt: ZTRD10037404, prod_hierarchy: ZTRD, part_number: 10037404
root - ERROR - Traceback (most recent call last):
  File "/home/aditya_user/time-forecast-app/processing/process.py", line 147, in run
    algo_obj.rmse_pred[Constants.HWES] = [rmse, predictions]
UnboundLocalError: local variable 'rmse' referenced before assignment

root - ERROR - Error while using ARIMA on ship_pt: ZTRD10037407, prod_hierarchy: ZTRD, part_number: 10037407
root - ERROR - Traceback (most recent call last):
  File "/home/aditya_user/time-forecast-app/processing/process.py", line 62, in run
    rmse, mape, pred = algo_obj.get_predictions_rmse_mape(algo_name)
  File "/home/aditya_user/time-forecast-app/processing/algorithms.py", line 146, in get_predictions_rmse_mape
    self.rmse2[min_algo] = rmse
AttributeError: 'Algorithms' object has no attribute 'rmse2'

root - ERROR - Error while using MOVING AVERAGE on ship_pt: ZTRD10037407, prod_hierarchy: ZTRD, part_number: 10037407
root - ERROR - Traceback (most recent call last):
  File "/home/aditya_user/time-forecast-app/processing/process.py", line 62, in run
    rmse, mape, pred = algo_obj.get_predictions_rmse_mape(algo_name)
  File "/home/aditya_user/time-forecast-app/processing/algorithms.py", line 146, in get_predictions_rmse_mape
    self.rmse2[min_algo] = rmse
AttributeError: 'Algorithms' object has no attribute 'rmse2'

root - ERROR - Error while using AR on ship_pt: ZTRD10037407, prod_hierarchy: ZTRD, part_number: 10037407
root - ERROR - Traceback (most recent call last):
  File "/home/aditya_user/time-forecast-app/processing/process.py", line 62, in run
    rmse, mape, pred = algo_obj.get_predictions_rmse_mape(algo_name)
  File "/home/aditya_user/time-forecast-app/processing/algorithms.py", line 146, in get_predictions_rmse_mape
    self.rmse2[min_algo] = rmse
AttributeError: 'Algorithms' object has no attribute 'rmse2'

root - ERROR - Error while using ARMA on ship_pt: ZTRD10037407, prod_hierarchy: ZTRD, part_number: 10037407
root - ERROR - Traceback (most recent call last):
  File "/home/aditya_user/time-forecast-app/processing/process.py", line 62, in run
    rmse, mape, pred = algo_obj.get_predictions_rmse_mape(algo_name)
  File "/home/aditya_user/time-forecast-app/processing/algorithms.py", line 146, in get_predictions_rmse_mape
    self.rmse2[min_algo] = rmse
AttributeError: 'Algorithms' object has no attribute 'rmse2'

root - ERROR - Error while using SARIMA on ship_pt: ZTRD10037407, prod_hierarchy: ZTRD, part_number: 10037407
root - ERROR - Traceback (most recent call last):
  File "/home/aditya_user/time-forecast-app/processing/process.py", line 62, in run
    rmse, mape, pred = algo_obj.get_predictions_rmse_mape(algo_name)
  File "/home/aditya_user/time-forecast-app/processing/algorithms.py", line 146, in get_predictions_rmse_mape
    self.rmse2[min_algo] = rmse
AttributeError: 'Algorithms' object has no attribute 'rmse2'

root - ERROR - Error while using SES on ship_pt: ZTRD10037407, prod_hierarchy: ZTRD, part_number: 10037407
root - ERROR - Traceback (most recent call last):
  File "/home/aditya_user/time-forecast-app/processing/process.py", line 62, in run
    rmse, mape, pred = algo_obj.get_predictions_rmse_mape(algo_name)
  File "/home/aditya_user/time-forecast-app/processing/algorithms.py", line 146, in get_predictions_rmse_mape
    self.rmse2[min_algo] = rmse
AttributeError: 'Algorithms' object has no attribute 'rmse2'

root - ERROR - Error while using HWES method on ship_pt: ZTRD10037407, prod_hierarchy: ZTRD, part_number: 10037407
root - ERROR - Traceback (most recent call last):
  File "/home/aditya_user/time-forecast-app/processing/process.py", line 147, in run
    algo_obj.rmse_pred[Constants.HWES] = [rmse, predictions]
UnboundLocalError: local variable 'rmse' referenced before assignment

root - ERROR - Error while using ARIMA on ship_pt: ZTRD10037410, prod_hierarchy: ZTRD, part_number: 10037410
root - ERROR - Traceback (most recent call last):
  File "/home/aditya_user/time-forecast-app/processing/process.py", line 62, in run
    rmse, mape, pred = algo_obj.get_predictions_rmse_mape(algo_name)
  File "/home/aditya_user/time-forecast-app/processing/algorithms.py", line 146, in get_predictions_rmse_mape
    self.rmse2[min_algo] = rmse
AttributeError: 'Algorithms' object has no attribute 'rmse2'

root - ERROR - Error while using MOVING AVERAGE on ship_pt: ZTRD10037410, prod_hierarchy: ZTRD, part_number: 10037410
root - ERROR - Traceback (most recent call last):
  File "/home/aditya_user/time-forecast-app/processing/process.py", line 62, in run
    rmse, mape, pred = algo_obj.get_predictions_rmse_mape(algo_name)
  File "/home/aditya_user/time-forecast-app/processing/algorithms.py", line 146, in get_predictions_rmse_mape
    self.rmse2[min_algo] = rmse
AttributeError: 'Algorithms' object has no attribute 'rmse2'

root - ERROR - Error while using AR on ship_pt: ZTRD10037410, prod_hierarchy: ZTRD, part_number: 10037410
root - ERROR - Traceback (most recent call last):
  File "/home/aditya_user/time-forecast-app/processing/process.py", line 62, in run
    rmse, mape, pred = algo_obj.get_predictions_rmse_mape(algo_name)
  File "/home/aditya_user/time-forecast-app/processing/algorithms.py", line 146, in get_predictions_rmse_mape
    self.rmse2[min_algo] = rmse
AttributeError: 'Algorithms' object has no attribute 'rmse2'

root - ERROR - Error while using ARMA on ship_pt: ZTRD10037410, prod_hierarchy: ZTRD, part_number: 10037410
root - ERROR - Traceback (most recent call last):
  File "/home/aditya_user/time-forecast-app/processing/process.py", line 62, in run
    rmse, mape, pred = algo_obj.get_predictions_rmse_mape(algo_name)
  File "/home/aditya_user/time-forecast-app/processing/algorithms.py", line 146, in get_predictions_rmse_mape
    self.rmse2[min_algo] = rmse
AttributeError: 'Algorithms' object has no attribute 'rmse2'

root - ERROR - Error while using SARIMA on ship_pt: ZTRD10037410, prod_hierarchy: ZTRD, part_number: 10037410
root - ERROR - Traceback (most recent call last):
  File "/home/aditya_user/time-forecast-app/processing/process.py", line 62, in run
    rmse, mape, pred = algo_obj.get_predictions_rmse_mape(algo_name)
  File "/home/aditya_user/time-forecast-app/processing/algorithms.py", line 146, in get_predictions_rmse_mape
    self.rmse2[min_algo] = rmse
AttributeError: 'Algorithms' object has no attribute 'rmse2'

root - ERROR - Error while using SES on ship_pt: ZTRD10037410, prod_hierarchy: ZTRD, part_number: 10037410
root - ERROR - Traceback (most recent call last):
  File "/home/aditya_user/time-forecast-app/processing/process.py", line 62, in run
    rmse, mape, pred = algo_obj.get_predictions_rmse_mape(algo_name)
  File "/home/aditya_user/time-forecast-app/processing/algorithms.py", line 146, in get_predictions_rmse_mape
    self.rmse2[min_algo] = rmse
AttributeError: 'Algorithms' object has no attribute 'rmse2'

root - ERROR - Error while using HWES method on ship_pt: ZTRD10037410, prod_hierarchy: ZTRD, part_number: 10037410
root - ERROR - Traceback (most recent call last):
  File "/home/aditya_user/time-forecast-app/processing/process.py", line 147, in run
    algo_obj.rmse_pred[Constants.HWES] = [rmse, predictions]
UnboundLocalError: local variable 'rmse' referenced before assignment

root - ERROR - Error while using ARIMA on ship_pt: ZTRD10100064, prod_hierarchy: ZTRD, part_number: 10100064
root - ERROR - Traceback (most recent call last):
  File "/home/aditya_user/time-forecast-app/processing/process.py", line 62, in run
    rmse, mape, pred = algo_obj.get_predictions_rmse_mape(algo_name)
  File "/home/aditya_user/time-forecast-app/processing/algorithms.py", line 146, in get_predictions_rmse_mape
    self.rmse2[min_algo] = rmse
AttributeError: 'Algorithms' object has no attribute 'rmse2'

root - ERROR - Error while using MOVING AVERAGE on ship_pt: ZTRD10100064, prod_hierarchy: ZTRD, part_number: 10100064
root - ERROR - Traceback (most recent call last):
  File "/home/aditya_user/time-forecast-app/processing/process.py", line 62, in run
    rmse, mape, pred = algo_obj.get_predictions_rmse_mape(algo_name)
  File "/home/aditya_user/time-forecast-app/processing/algorithms.py", line 146, in get_predictions_rmse_mape
    self.rmse2[min_algo] = rmse
AttributeError: 'Algorithms' object has no attribute 'rmse2'

root - ERROR - Error while using AR on ship_pt: ZTRD10100064, prod_hierarchy: ZTRD, part_number: 10100064
root - ERROR - Traceback (most recent call last):
  File "/home/aditya_user/time-forecast-app/processing/process.py", line 62, in run
    rmse, mape, pred = algo_obj.get_predictions_rmse_mape(algo_name)
  File "/home/aditya_user/time-forecast-app/processing/algorithms.py", line 146, in get_predictions_rmse_mape
    self.rmse2[min_algo] = rmse
AttributeError: 'Algorithms' object has no attribute 'rmse2'

root - ERROR - Error while using ARMA on ship_pt: ZTRD10100064, prod_hierarchy: ZTRD, part_number: 10100064
root - ERROR - Traceback (most recent call last):
  File "/home/aditya_user/time-forecast-app/processing/process.py", line 62, in run
    rmse, mape, pred = algo_obj.get_predictions_rmse_mape(algo_name)
  File "/home/aditya_user/time-forecast-app/processing/algorithms.py", line 129, in get_predictions_rmse_mape
    model_fit = model.fit(disp=0)
  File "/home/aditya_user/time-forecast-app/venv/lib/python3.7/site-packages/statsmodels/tsa/arima_model.py", line 986, in fit
    start_ar_lags)
  File "/home/aditya_user/time-forecast-app/venv/lib/python3.7/site-packages/statsmodels/tsa/arima_model.py", line 577, in _fit_start_params
    start_params = self._fit_start_params_hr(order, start_ar_lags)
  File "/home/aditya_user/time-forecast-app/venv/lib/python3.7/site-packages/statsmodels/tsa/arima_model.py", line 555, in _fit_start_params_hr
    raise ValueError("The computed initial AR coefficients are not "
ValueError: The computed initial AR coefficients are not stationary
You should induce stationarity, choose a different model order, or you can
pass your own start_params.

root - ERROR - Error while using SARIMA on ship_pt: ZTRD10100064, prod_hierarchy: ZTRD, part_number: 10100064
root - ERROR - Traceback (most recent call last):
  File "/home/aditya_user/time-forecast-app/processing/process.py", line 62, in run
    rmse, mape, pred = algo_obj.get_predictions_rmse_mape(algo_name)
  File "/home/aditya_user/time-forecast-app/processing/algorithms.py", line 146, in get_predictions_rmse_mape
    self.rmse2[min_algo] = rmse
AttributeError: 'Algorithms' object has no attribute 'rmse2'

root - ERROR - Error while using SES on ship_pt: ZTRD10100064, prod_hierarchy: ZTRD, part_number: 10100064
root - ERROR - Traceback (most recent call last):
  File "/home/aditya_user/time-forecast-app/processing/process.py", line 62, in run
    rmse, mape, pred = algo_obj.get_predictions_rmse_mape(algo_name)
  File "/home/aditya_user/time-forecast-app/processing/algorithms.py", line 146, in get_predictions_rmse_mape
    self.rmse2[min_algo] = rmse
AttributeError: 'Algorithms' object has no attribute 'rmse2'

root - ERROR - Error while using HWES method on ship_pt: ZTRD10100064, prod_hierarchy: ZTRD, part_number: 10100064
root - ERROR - Traceback (most recent call last):
  File "/home/aditya_user/time-forecast-app/processing/process.py", line 147, in run
    algo_obj.rmse_pred[Constants.HWES] = [rmse, predictions]
UnboundLocalError: local variable 'rmse' referenced before assignment

root - ERROR - Error while using ARIMA on ship_pt: ZTRD10100200, prod_hierarchy: ZTRD, part_number: 10100200
root - ERROR - Traceback (most recent call last):
  File "/home/aditya_user/time-forecast-app/processing/process.py", line 62, in run
    rmse, mape, pred = algo_obj.get_predictions_rmse_mape(algo_name)
  File "/home/aditya_user/time-forecast-app/processing/algorithms.py", line 146, in get_predictions_rmse_mape
    self.rmse2[min_algo] = rmse
AttributeError: 'Algorithms' object has no attribute 'rmse2'

root - ERROR - Error while using MOVING AVERAGE on ship_pt: ZTRD10100200, prod_hierarchy: ZTRD, part_number: 10100200
root - ERROR - Traceback (most recent call last):
  File "/home/aditya_user/time-forecast-app/processing/process.py", line 62, in run
    rmse, mape, pred = algo_obj.get_predictions_rmse_mape(algo_name)
  File "/home/aditya_user/time-forecast-app/processing/algorithms.py", line 146, in get_predictions_rmse_mape
    self.rmse2[min_algo] = rmse
AttributeError: 'Algorithms' object has no attribute 'rmse2'

root - ERROR - Error while using AR on ship_pt: ZTRD10100200, prod_hierarchy: ZTRD, part_number: 10100200
root - ERROR - Traceback (most recent call last):
  File "/home/aditya_user/time-forecast-app/processing/process.py", line 62, in run
    rmse, mape, pred = algo_obj.get_predictions_rmse_mape(algo_name)
  File "/home/aditya_user/time-forecast-app/processing/algorithms.py", line 146, in get_predictions_rmse_mape
    self.rmse2[min_algo] = rmse
AttributeError: 'Algorithms' object has no attribute 'rmse2'

root - ERROR - Error while using ARMA on ship_pt: ZTRD10100200, prod_hierarchy: ZTRD, part_number: 10100200
root - ERROR - Traceback (most recent call last):
  File "/home/aditya_user/time-forecast-app/processing/process.py", line 62, in run
    rmse, mape, pred = algo_obj.get_predictions_rmse_mape(algo_name)
  File "/home/aditya_user/time-forecast-app/processing/algorithms.py", line 146, in get_predictions_rmse_mape
    self.rmse2[min_algo] = rmse
AttributeError: 'Algorithms' object has no attribute 'rmse2'

root - ERROR - Error while using SARIMA on ship_pt: ZTRD10100200, prod_hierarchy: ZTRD, part_number: 10100200
root - ERROR - Traceback (most recent call last):
  File "/home/aditya_user/time-forecast-app/processing/process.py", line 62, in run
    rmse, mape, pred = algo_obj.get_predictions_rmse_mape(algo_name)
  File "/home/aditya_user/time-forecast-app/processing/algorithms.py", line 146, in get_predictions_rmse_mape
    self.rmse2[min_algo] = rmse
AttributeError: 'Algorithms' object has no attribute 'rmse2'

root - ERROR - Error while using SES on ship_pt: ZTRD10100200, prod_hierarchy: ZTRD, part_number: 10100200
root - ERROR - Traceback (most recent call last):
  File "/home/aditya_user/time-forecast-app/processing/process.py", line 62, in run
    rmse, mape, pred = algo_obj.get_predictions_rmse_mape(algo_name)
  File "/home/aditya_user/time-forecast-app/processing/algorithms.py", line 146, in get_predictions_rmse_mape
    self.rmse2[min_algo] = rmse
AttributeError: 'Algorithms' object has no attribute 'rmse2'

root - ERROR - Error while using HWES method on ship_pt: ZTRD10100200, prod_hierarchy: ZTRD, part_number: 10100200
root - ERROR - Traceback (most recent call last):
  File "/home/aditya_user/time-forecast-app/processing/process.py", line 147, in run
    algo_obj.rmse_pred[Constants.HWES] = [rmse, predictions]
UnboundLocalError: local variable 'rmse' referenced before assignment

root - ERROR - Error while using ARIMA on ship_pt: ZTRD10037401, prod_hierarchy: ZTRD, part_number: 10037401
root - ERROR - Traceback (most recent call last):
  File "/home/aditya_user/time-forecast-app/processing/process.py", line 62, in run
    rmse, mape, pred = algo_obj.get_predictions_rmse_mape(algo_name)
  File "/home/aditya_user/time-forecast-app/processing/algorithms.py", line 146, in get_predictions_rmse_mape
    self.rmse2[min_algo] = rmse
AttributeError: 'Algorithms' object has no attribute 'rmse2'

root - ERROR - Error while using MOVING AVERAGE on ship_pt: ZTRD10037401, prod_hierarchy: ZTRD, part_number: 10037401
root - ERROR - Traceback (most recent call last):
  File "/home/aditya_user/time-forecast-app/processing/process.py", line 62, in run
    rmse, mape, pred = algo_obj.get_predictions_rmse_mape(algo_name)
  File "/home/aditya_user/time-forecast-app/processing/algorithms.py", line 146, in get_predictions_rmse_mape
    self.rmse2[min_algo] = rmse
AttributeError: 'Algorithms' object has no attribute 'rmse2'

root - ERROR - Error while using AR on ship_pt: ZTRD10037401, prod_hierarchy: ZTRD, part_number: 10037401
root - ERROR - Traceback (most recent call last):
  File "/home/aditya_user/time-forecast-app/processing/process.py", line 62, in run
    rmse, mape, pred = algo_obj.get_predictions_rmse_mape(algo_name)
  File "/home/aditya_user/time-forecast-app/processing/algorithms.py", line 146, in get_predictions_rmse_mape
    self.rmse2[min_algo] = rmse
AttributeError: 'Algorithms' object has no attribute 'rmse2'

root - ERROR - Error while using ARMA on ship_pt: ZTRD10037401, prod_hierarchy: ZTRD, part_number: 10037401
root - ERROR - Traceback (most recent call last):
  File "/home/aditya_user/time-forecast-app/processing/process.py", line 62, in run
    rmse, mape, pred = algo_obj.get_predictions_rmse_mape(algo_name)
  File "/home/aditya_user/time-forecast-app/processing/algorithms.py", line 129, in get_predictions_rmse_mape
    model_fit = model.fit(disp=0)
  File "/home/aditya_user/time-forecast-app/venv/lib/python3.7/site-packages/statsmodels/tsa/arima_model.py", line 986, in fit
    start_ar_lags)
  File "/home/aditya_user/time-forecast-app/venv/lib/python3.7/site-packages/statsmodels/tsa/arima_model.py", line 577, in _fit_start_params
    start_params = self._fit_start_params_hr(order, start_ar_lags)
  File "/home/aditya_user/time-forecast-app/venv/lib/python3.7/site-packages/statsmodels/tsa/arima_model.py", line 562, in _fit_start_params_hr
    raise ValueError("The computed initial MA coefficients are not "
ValueError: The computed initial MA coefficients are not invertible
You should induce invertibility, choose a different model order, or you can
pass your own start_params.

root - ERROR - Error while using SARIMA on ship_pt: ZTRD10037401, prod_hierarchy: ZTRD, part_number: 10037401
root - ERROR - Traceback (most recent call last):
  File "/home/aditya_user/time-forecast-app/processing/process.py", line 62, in run
    rmse, mape, pred = algo_obj.get_predictions_rmse_mape(algo_name)
  File "/home/aditya_user/time-forecast-app/processing/algorithms.py", line 146, in get_predictions_rmse_mape
    self.rmse2[min_algo] = rmse
AttributeError: 'Algorithms' object has no attribute 'rmse2'

root - ERROR - Error while using SES on ship_pt: ZTRD10037401, prod_hierarchy: ZTRD, part_number: 10037401
root - ERROR - Traceback (most recent call last):
  File "/home/aditya_user/time-forecast-app/processing/process.py", line 62, in run
    rmse, mape, pred = algo_obj.get_predictions_rmse_mape(algo_name)
  File "/home/aditya_user/time-forecast-app/processing/algorithms.py", line 146, in get_predictions_rmse_mape
    self.rmse2[min_algo] = rmse
AttributeError: 'Algorithms' object has no attribute 'rmse2'

root - ERROR - Error while using HWES method on ship_pt: ZTRD10037401, prod_hierarchy: ZTRD, part_number: 10037401
root - ERROR - Traceback (most recent call last):
  File "/home/aditya_user/time-forecast-app/processing/process.py", line 147, in run
    algo_obj.rmse_pred[Constants.HWES] = [rmse, predictions]
UnboundLocalError: local variable 'rmse' referenced before assignment

root - ERROR - Error while using ARIMA on ship_pt: ZTRD10037402, prod_hierarchy: ZTRD, part_number: 10037402
root - ERROR - Traceback (most recent call last):
  File "/home/aditya_user/time-forecast-app/processing/process.py", line 62, in run
    rmse, mape, pred = algo_obj.get_predictions_rmse_mape(algo_name)
  File "/home/aditya_user/time-forecast-app/processing/algorithms.py", line 146, in get_predictions_rmse_mape
    self.rmse2[min_algo] = rmse
AttributeError: 'Algorithms' object has no attribute 'rmse2'

root - ERROR - Error while using MOVING AVERAGE on ship_pt: ZTRD10037402, prod_hierarchy: ZTRD, part_number: 10037402
root - ERROR - Traceback (most recent call last):
  File "/home/aditya_user/time-forecast-app/processing/process.py", line 62, in run
    rmse, mape, pred = algo_obj.get_predictions_rmse_mape(algo_name)
  File "/home/aditya_user/time-forecast-app/processing/algorithms.py", line 146, in get_predictions_rmse_mape
    self.rmse2[min_algo] = rmse
AttributeError: 'Algorithms' object has no attribute 'rmse2'

root - ERROR - Error while using AR on ship_pt: ZTRD10037402, prod_hierarchy: ZTRD, part_number: 10037402
root - ERROR - Traceback (most recent call last):
  File "/home/aditya_user/time-forecast-app/processing/process.py", line 62, in run
    rmse, mape, pred = algo_obj.get_predictions_rmse_mape(algo_name)
  File "/home/aditya_user/time-forecast-app/processing/algorithms.py", line 146, in get_predictions_rmse_mape
    self.rmse2[min_algo] = rmse
AttributeError: 'Algorithms' object has no attribute 'rmse2'

root - ERROR - Error while using ARMA on ship_pt: ZTRD10037402, prod_hierarchy: ZTRD, part_number: 10037402
root - ERROR - Traceback (most recent call last):
  File "/home/aditya_user/time-forecast-app/processing/process.py", line 62, in run
    rmse, mape, pred = algo_obj.get_predictions_rmse_mape(algo_name)
  File "/home/aditya_user/time-forecast-app/processing/algorithms.py", line 146, in get_predictions_rmse_mape
    self.rmse2[min_algo] = rmse
AttributeError: 'Algorithms' object has no attribute 'rmse2'

root - ERROR - Error while using SARIMA on ship_pt: ZTRD10037402, prod_hierarchy: ZTRD, part_number: 10037402
root - ERROR - Traceback (most recent call last):
  File "/home/aditya_user/time-forecast-app/processing/process.py", line 62, in run
    rmse, mape, pred = algo_obj.get_predictions_rmse_mape(algo_name)
  File "/home/aditya_user/time-forecast-app/processing/algorithms.py", line 146, in get_predictions_rmse_mape
    self.rmse2[min_algo] = rmse
AttributeError: 'Algorithms' object has no attribute 'rmse2'

root - ERROR - Error while using SES on ship_pt: ZTRD10037402, prod_hierarchy: ZTRD, part_number: 10037402
root - ERROR - Traceback (most recent call last):
  File "/home/aditya_user/time-forecast-app/processing/process.py", line 62, in run
    rmse, mape, pred = algo_obj.get_predictions_rmse_mape(algo_name)
  File "/home/aditya_user/time-forecast-app/processing/algorithms.py", line 146, in get_predictions_rmse_mape
    self.rmse2[min_algo] = rmse
AttributeError: 'Algorithms' object has no attribute 'rmse2'

root - ERROR - Error while using HWES method on ship_pt: ZTRD10037402, prod_hierarchy: ZTRD, part_number: 10037402
root - ERROR - Traceback (most recent call last):
  File "/home/aditya_user/time-forecast-app/processing/process.py", line 147, in run
    algo_obj.rmse_pred[Constants.HWES] = [rmse, predictions]
UnboundLocalError: local variable 'rmse' referenced before assignment

root - ERROR - Error while using ARIMA on ship_pt: ZTRD10037404, prod_hierarchy: ZTRD, part_number: 10037404
root - ERROR - Traceback (most recent call last):
  File "/home/aditya_user/time-forecast-app/processing/process.py", line 62, in run
    rmse, mape, pred = algo_obj.get_predictions_rmse_mape(algo_name)
  File "/home/aditya_user/time-forecast-app/processing/algorithms.py", line 146, in get_predictions_rmse_mape
    self.rmse2[min_algo] = rmse
AttributeError: 'Algorithms' object has no attribute 'rmse2'

root - ERROR - Error while using MOVING AVERAGE on ship_pt: ZTRD10037404, prod_hierarchy: ZTRD, part_number: 10037404
root - ERROR - Traceback (most recent call last):
  File "/home/aditya_user/time-forecast-app/processing/process.py", line 62, in run
    rmse, mape, pred = algo_obj.get_predictions_rmse_mape(algo_name)
  File "/home/aditya_user/time-forecast-app/processing/algorithms.py", line 146, in get_predictions_rmse_mape
    self.rmse2[min_algo] = rmse
AttributeError: 'Algorithms' object has no attribute 'rmse2'

root - ERROR - Error while using AR on ship_pt: ZTRD10037404, prod_hierarchy: ZTRD, part_number: 10037404
root - ERROR - Traceback (most recent call last):
  File "/home/aditya_user/time-forecast-app/processing/process.py", line 62, in run
    rmse, mape, pred = algo_obj.get_predictions_rmse_mape(algo_name)
  File "/home/aditya_user/time-forecast-app/processing/algorithms.py", line 146, in get_predictions_rmse_mape
    self.rmse2[min_algo] = rmse
AttributeError: 'Algorithms' object has no attribute 'rmse2'

root - ERROR - Error while using ARMA on ship_pt: ZTRD10037404, prod_hierarchy: ZTRD, part_number: 10037404
root - ERROR - Traceback (most recent call last):
  File "/home/aditya_user/time-forecast-app/processing/process.py", line 62, in run
    rmse, mape, pred = algo_obj.get_predictions_rmse_mape(algo_name)
  File "/home/aditya_user/time-forecast-app/processing/algorithms.py", line 146, in get_predictions_rmse_mape
    self.rmse2[min_algo] = rmse
AttributeError: 'Algorithms' object has no attribute 'rmse2'

root - ERROR - Error while using SARIMA on ship_pt: ZTRD10037404, prod_hierarchy: ZTRD, part_number: 10037404
root - ERROR - Traceback (most recent call last):
  File "/home/aditya_user/time-forecast-app/processing/process.py", line 62, in run
    rmse, mape, pred = algo_obj.get_predictions_rmse_mape(algo_name)
  File "/home/aditya_user/time-forecast-app/processing/algorithms.py", line 146, in get_predictions_rmse_mape
    self.rmse2[min_algo] = rmse
AttributeError: 'Algorithms' object has no attribute 'rmse2'

root - ERROR - Error while using SES on ship_pt: ZTRD10037404, prod_hierarchy: ZTRD, part_number: 10037404
root - ERROR - Traceback (most recent call last):
  File "/home/aditya_user/time-forecast-app/processing/process.py", line 62, in run
    rmse, mape, pred = algo_obj.get_predictions_rmse_mape(algo_name)
  File "/home/aditya_user/time-forecast-app/processing/algorithms.py", line 146, in get_predictions_rmse_mape
    self.rmse2[min_algo] = rmse
AttributeError: 'Algorithms' object has no attribute 'rmse2'

root - ERROR - Error while using HWES method on ship_pt: ZTRD10037404, prod_hierarchy: ZTRD, part_number: 10037404
root - ERROR - Traceback (most recent call last):
  File "/home/aditya_user/time-forecast-app/processing/process.py", line 147, in run
    algo_obj.rmse_pred[Constants.HWES] = [rmse, predictions]
UnboundLocalError: local variable 'rmse' referenced before assignment

root - ERROR - Error while using ARIMA on ship_pt: ZTRD10037407, prod_hierarchy: ZTRD, part_number: 10037407
root - ERROR - Traceback (most recent call last):
  File "/home/aditya_user/time-forecast-app/processing/process.py", line 62, in run
    rmse, mape, pred = algo_obj.get_predictions_rmse_mape(algo_name)
  File "/home/aditya_user/time-forecast-app/processing/algorithms.py", line 146, in get_predictions_rmse_mape
    self.rmse2[min_algo] = rmse
AttributeError: 'Algorithms' object has no attribute 'rmse2'

root - ERROR - Error while using MOVING AVERAGE on ship_pt: ZTRD10037407, prod_hierarchy: ZTRD, part_number: 10037407
root - ERROR - Traceback (most recent call last):
  File "/home/aditya_user/time-forecast-app/processing/process.py", line 62, in run
    rmse, mape, pred = algo_obj.get_predictions_rmse_mape(algo_name)
  File "/home/aditya_user/time-forecast-app/processing/algorithms.py", line 146, in get_predictions_rmse_mape
    self.rmse2[min_algo] = rmse
AttributeError: 'Algorithms' object has no attribute 'rmse2'

root - ERROR - Error while using AR on ship_pt: ZTRD10037407, prod_hierarchy: ZTRD, part_number: 10037407
root - ERROR - Traceback (most recent call last):
  File "/home/aditya_user/time-forecast-app/processing/process.py", line 62, in run
    rmse, mape, pred = algo_obj.get_predictions_rmse_mape(algo_name)
  File "/home/aditya_user/time-forecast-app/processing/algorithms.py", line 146, in get_predictions_rmse_mape
    self.rmse2[min_algo] = rmse
AttributeError: 'Algorithms' object has no attribute 'rmse2'

root - ERROR - Error while using ARMA on ship_pt: ZTRD10037407, prod_hierarchy: ZTRD, part_number: 10037407
root - ERROR - Traceback (most recent call last):
  File "/home/aditya_user/time-forecast-app/processing/process.py", line 62, in run
    rmse, mape, pred = algo_obj.get_predictions_rmse_mape(algo_name)
  File "/home/aditya_user/time-forecast-app/processing/algorithms.py", line 146, in get_predictions_rmse_mape
    self.rmse2[min_algo] = rmse
AttributeError: 'Algorithms' object has no attribute 'rmse2'

root - ERROR - Error while using SARIMA on ship_pt: ZTRD10037407, prod_hierarchy: ZTRD, part_number: 10037407
root - ERROR - Traceback (most recent call last):
  File "/home/aditya_user/time-forecast-app/processing/process.py", line 62, in run
    rmse, mape, pred = algo_obj.get_predictions_rmse_mape(algo_name)
  File "/home/aditya_user/time-forecast-app/processing/algorithms.py", line 146, in get_predictions_rmse_mape
    self.rmse2[min_algo] = rmse
AttributeError: 'Algorithms' object has no attribute 'rmse2'

root - ERROR - Error while using SES on ship_pt: ZTRD10037407, prod_hierarchy: ZTRD, part_number: 10037407
root - ERROR - Traceback (most recent call last):
  File "/home/aditya_user/time-forecast-app/processing/process.py", line 62, in run
    rmse, mape, pred = algo_obj.get_predictions_rmse_mape(algo_name)
  File "/home/aditya_user/time-forecast-app/processing/algorithms.py", line 146, in get_predictions_rmse_mape
    self.rmse2[min_algo] = rmse
AttributeError: 'Algorithms' object has no attribute 'rmse2'

root - ERROR - Error while using HWES method on ship_pt: ZTRD10037407, prod_hierarchy: ZTRD, part_number: 10037407
root - ERROR - Traceback (most recent call last):
  File "/home/aditya_user/time-forecast-app/processing/process.py", line 147, in run
    algo_obj.rmse_pred[Constants.HWES] = [rmse, predictions]
UnboundLocalError: local variable 'rmse' referenced before assignment

root - ERROR - Error while using ARIMA on ship_pt: ZTRD10037410, prod_hierarchy: ZTRD, part_number: 10037410
root - ERROR - Traceback (most recent call last):
  File "/home/aditya_user/time-forecast-app/processing/process.py", line 62, in run
    rmse, mape, pred = algo_obj.get_predictions_rmse_mape(algo_name)
  File "/home/aditya_user/time-forecast-app/processing/algorithms.py", line 146, in get_predictions_rmse_mape
    self.rmse2[min_algo] = rmse
AttributeError: 'Algorithms' object has no attribute 'rmse2'

root - ERROR - Error while using MOVING AVERAGE on ship_pt: ZTRD10037410, prod_hierarchy: ZTRD, part_number: 10037410
root - ERROR - Traceback (most recent call last):
  File "/home/aditya_user/time-forecast-app/processing/process.py", line 62, in run
    rmse, mape, pred = algo_obj.get_predictions_rmse_mape(algo_name)
  File "/home/aditya_user/time-forecast-app/processing/algorithms.py", line 146, in get_predictions_rmse_mape
    self.rmse2[min_algo] = rmse
AttributeError: 'Algorithms' object has no attribute 'rmse2'

root - ERROR - Error while using AR on ship_pt: ZTRD10037410, prod_hierarchy: ZTRD, part_number: 10037410
root - ERROR - Traceback (most recent call last):
  File "/home/aditya_user/time-forecast-app/processing/process.py", line 62, in run
    rmse, mape, pred = algo_obj.get_predictions_rmse_mape(algo_name)
  File "/home/aditya_user/time-forecast-app/processing/algorithms.py", line 146, in get_predictions_rmse_mape
    self.rmse2[min_algo] = rmse
AttributeError: 'Algorithms' object has no attribute 'rmse2'

root - ERROR - Error while using ARMA on ship_pt: ZTRD10037410, prod_hierarchy: ZTRD, part_number: 10037410
root - ERROR - Traceback (most recent call last):
  File "/home/aditya_user/time-forecast-app/processing/process.py", line 62, in run
    rmse, mape, pred = algo_obj.get_predictions_rmse_mape(algo_name)
  File "/home/aditya_user/time-forecast-app/processing/algorithms.py", line 146, in get_predictions_rmse_mape
    self.rmse2[min_algo] = rmse
AttributeError: 'Algorithms' object has no attribute 'rmse2'

root - ERROR - Error while using SARIMA on ship_pt: ZTRD10037410, prod_hierarchy: ZTRD, part_number: 10037410
root - ERROR - Traceback (most recent call last):
  File "/home/aditya_user/time-forecast-app/processing/process.py", line 62, in run
    rmse, mape, pred = algo_obj.get_predictions_rmse_mape(algo_name)
  File "/home/aditya_user/time-forecast-app/processing/algorithms.py", line 146, in get_predictions_rmse_mape
    self.rmse2[min_algo] = rmse
AttributeError: 'Algorithms' object has no attribute 'rmse2'

root - ERROR - Error while using SES on ship_pt: ZTRD10037410, prod_hierarchy: ZTRD, part_number: 10037410
root - ERROR - Traceback (most recent call last):
  File "/home/aditya_user/time-forecast-app/processing/process.py", line 62, in run
    rmse, mape, pred = algo_obj.get_predictions_rmse_mape(algo_name)
  File "/home/aditya_user/time-forecast-app/processing/algorithms.py", line 146, in get_predictions_rmse_mape
    self.rmse2[min_algo] = rmse
AttributeError: 'Algorithms' object has no attribute 'rmse2'

root - ERROR - Error while using HWES method on ship_pt: ZTRD10037410, prod_hierarchy: ZTRD, part_number: 10037410
root - ERROR - Traceback (most recent call last):
  File "/home/aditya_user/time-forecast-app/processing/process.py", line 147, in run
    algo_obj.rmse_pred[Constants.HWES] = [rmse, predictions]
UnboundLocalError: local variable 'rmse' referenced before assignment

root - ERROR - Error while using ARIMA on ship_pt: ZTRD10100064, prod_hierarchy: ZTRD, part_number: 10100064
root - ERROR - Traceback (most recent call last):
  File "/home/aditya_user/time-forecast-app/processing/process.py", line 62, in run
    rmse, mape, pred = algo_obj.get_predictions_rmse_mape(algo_name)
  File "/home/aditya_user/time-forecast-app/processing/algorithms.py", line 146, in get_predictions_rmse_mape
    self.rmse2[min_algo] = rmse
AttributeError: 'Algorithms' object has no attribute 'rmse2'

root - ERROR - Error while using MOVING AVERAGE on ship_pt: ZTRD10100064, prod_hierarchy: ZTRD, part_number: 10100064
root - ERROR - Traceback (most recent call last):
  File "/home/aditya_user/time-forecast-app/processing/process.py", line 62, in run
    rmse, mape, pred = algo_obj.get_predictions_rmse_mape(algo_name)
  File "/home/aditya_user/time-forecast-app/processing/algorithms.py", line 146, in get_predictions_rmse_mape
    self.rmse2[min_algo] = rmse
AttributeError: 'Algorithms' object has no attribute 'rmse2'

root - ERROR - Error while using AR on ship_pt: ZTRD10100064, prod_hierarchy: ZTRD, part_number: 10100064
root - ERROR - Traceback (most recent call last):
  File "/home/aditya_user/time-forecast-app/processing/process.py", line 62, in run
    rmse, mape, pred = algo_obj.get_predictions_rmse_mape(algo_name)
  File "/home/aditya_user/time-forecast-app/processing/algorithms.py", line 146, in get_predictions_rmse_mape
    self.rmse2[min_algo] = rmse
AttributeError: 'Algorithms' object has no attribute 'rmse2'

root - ERROR - Error while using ARMA on ship_pt: ZTRD10100064, prod_hierarchy: ZTRD, part_number: 10100064
root - ERROR - Traceback (most recent call last):
  File "/home/aditya_user/time-forecast-app/processing/process.py", line 62, in run
    rmse, mape, pred = algo_obj.get_predictions_rmse_mape(algo_name)
  File "/home/aditya_user/time-forecast-app/processing/algorithms.py", line 129, in get_predictions_rmse_mape
    model_fit = model.fit(disp=0)
  File "/home/aditya_user/time-forecast-app/venv/lib/python3.7/site-packages/statsmodels/tsa/arima_model.py", line 986, in fit
    start_ar_lags)
  File "/home/aditya_user/time-forecast-app/venv/lib/python3.7/site-packages/statsmodels/tsa/arima_model.py", line 577, in _fit_start_params
    start_params = self._fit_start_params_hr(order, start_ar_lags)
  File "/home/aditya_user/time-forecast-app/venv/lib/python3.7/site-packages/statsmodels/tsa/arima_model.py", line 555, in _fit_start_params_hr
    raise ValueError("The computed initial AR coefficients are not "
ValueError: The computed initial AR coefficients are not stationary
You should induce stationarity, choose a different model order, or you can
pass your own start_params.

root - ERROR - Error while using SARIMA on ship_pt: ZTRD10100064, prod_hierarchy: ZTRD, part_number: 10100064
root - ERROR - Traceback (most recent call last):
  File "/home/aditya_user/time-forecast-app/processing/process.py", line 62, in run
    rmse, mape, pred = algo_obj.get_predictions_rmse_mape(algo_name)
  File "/home/aditya_user/time-forecast-app/processing/algorithms.py", line 146, in get_predictions_rmse_mape
    self.rmse2[min_algo] = rmse
AttributeError: 'Algorithms' object has no attribute 'rmse2'

root - ERROR - Error while using SES on ship_pt: ZTRD10100064, prod_hierarchy: ZTRD, part_number: 10100064
root - ERROR - Traceback (most recent call last):
  File "/home/aditya_user/time-forecast-app/processing/process.py", line 62, in run
    rmse, mape, pred = algo_obj.get_predictions_rmse_mape(algo_name)
  File "/home/aditya_user/time-forecast-app/processing/algorithms.py", line 146, in get_predictions_rmse_mape
    self.rmse2[min_algo] = rmse
AttributeError: 'Algorithms' object has no attribute 'rmse2'

root - ERROR - Error while using HWES method on ship_pt: ZTRD10100064, prod_hierarchy: ZTRD, part_number: 10100064
root - ERROR - Traceback (most recent call last):
  File "/home/aditya_user/time-forecast-app/processing/process.py", line 147, in run
    algo_obj.rmse_pred[Constants.HWES] = [rmse, predictions]
UnboundLocalError: local variable 'rmse' referenced before assignment

root - ERROR - Error while using ARIMA on ship_pt: ZTRD10100200, prod_hierarchy: ZTRD, part_number: 10100200
root - ERROR - Traceback (most recent call last):
  File "/home/aditya_user/time-forecast-app/processing/process.py", line 62, in run
    rmse, mape, pred = algo_obj.get_predictions_rmse_mape(algo_name)
  File "/home/aditya_user/time-forecast-app/processing/algorithms.py", line 146, in get_predictions_rmse_mape
    self.rmse2[min_algo] = rmse
AttributeError: 'Algorithms' object has no attribute 'rmse2'

root - ERROR - Error while using MOVING AVERAGE on ship_pt: ZTRD10100200, prod_hierarchy: ZTRD, part_number: 10100200
root - ERROR - Traceback (most recent call last):
  File "/home/aditya_user/time-forecast-app/processing/process.py", line 62, in run
    rmse, mape, pred = algo_obj.get_predictions_rmse_mape(algo_name)
  File "/home/aditya_user/time-forecast-app/processing/algorithms.py", line 146, in get_predictions_rmse_mape
    self.rmse2[min_algo] = rmse
AttributeError: 'Algorithms' object has no attribute 'rmse2'

root - ERROR - Error while using AR on ship_pt: ZTRD10100200, prod_hierarchy: ZTRD, part_number: 10100200
root - ERROR - Traceback (most recent call last):
  File "/home/aditya_user/time-forecast-app/processing/process.py", line 62, in run
    rmse, mape, pred = algo_obj.get_predictions_rmse_mape(algo_name)
  File "/home/aditya_user/time-forecast-app/processing/algorithms.py", line 146, in get_predictions_rmse_mape
    self.rmse2[min_algo] = rmse
AttributeError: 'Algorithms' object has no attribute 'rmse2'

root - ERROR - Error while using ARMA on ship_pt: ZTRD10100200, prod_hierarchy: ZTRD, part_number: 10100200
root - ERROR - Traceback (most recent call last):
  File "/home/aditya_user/time-forecast-app/processing/process.py", line 62, in run
    rmse, mape, pred = algo_obj.get_predictions_rmse_mape(algo_name)
  File "/home/aditya_user/time-forecast-app/processing/algorithms.py", line 146, in get_predictions_rmse_mape
    self.rmse2[min_algo] = rmse
AttributeError: 'Algorithms' object has no attribute 'rmse2'

root - ERROR - Error while using SARIMA on ship_pt: ZTRD10100200, prod_hierarchy: ZTRD, part_number: 10100200
root - ERROR - Traceback (most recent call last):
  File "/home/aditya_user/time-forecast-app/processing/process.py", line 62, in run
    rmse, mape, pred = algo_obj.get_predictions_rmse_mape(algo_name)
  File "/home/aditya_user/time-forecast-app/processing/algorithms.py", line 146, in get_predictions_rmse_mape
    self.rmse2[min_algo] = rmse
AttributeError: 'Algorithms' object has no attribute 'rmse2'

root - ERROR - Error while using SES on ship_pt: ZTRD10100200, prod_hierarchy: ZTRD, part_number: 10100200
root - ERROR - Traceback (most recent call last):
  File "/home/aditya_user/time-forecast-app/processing/process.py", line 62, in run
    rmse, mape, pred = algo_obj.get_predictions_rmse_mape(algo_name)
  File "/home/aditya_user/time-forecast-app/processing/algorithms.py", line 146, in get_predictions_rmse_mape
    self.rmse2[min_algo] = rmse
AttributeError: 'Algorithms' object has no attribute 'rmse2'

root - ERROR - Error while using HWES method on ship_pt: ZTRD10100200, prod_hierarchy: ZTRD, part_number: 10100200
root - ERROR - Traceback (most recent call last):
  File "/home/aditya_user/time-forecast-app/processing/process.py", line 147, in run
    algo_obj.rmse_pred[Constants.HWES] = [rmse, predictions]
UnboundLocalError: local variable 'rmse' referenced before assignment

django.request - WARNING - Not Found: /dashboard/344
root - ERROR - Error while using ARIMA on ship_pt: ﻿ZTRD, prod_hierarchy: 2 B X E, part_number: 10057034
root - ERROR - Traceback (most recent call last):
  File "/home/aditya_user/time-forecast-app/processing/process.py", line 62, in run
    rmse, mape, pred = algo_obj.get_predictions_rmse_mape(algo_name)
  File "/home/aditya_user/time-forecast-app/processing/algorithms.py", line 146, in get_predictions_rmse_mape
    self.rmse2[min_algo] = rmse
AttributeError: 'Algorithms' object has no attribute 'rmse2'

root - ERROR - Error while using MOVING AVERAGE on ship_pt: ﻿ZTRD, prod_hierarchy: 2 B X E, part_number: 10057034
root - ERROR - Traceback (most recent call last):
  File "/home/aditya_user/time-forecast-app/processing/process.py", line 62, in run
    rmse, mape, pred = algo_obj.get_predictions_rmse_mape(algo_name)
  File "/home/aditya_user/time-forecast-app/processing/algorithms.py", line 146, in get_predictions_rmse_mape
    self.rmse2[min_algo] = rmse
AttributeError: 'Algorithms' object has no attribute 'rmse2'

root - ERROR - Error while using AR on ship_pt: ﻿ZTRD, prod_hierarchy: 2 B X E, part_number: 10057034
root - ERROR - Traceback (most recent call last):
  File "/home/aditya_user/time-forecast-app/processing/process.py", line 62, in run
    rmse, mape, pred = algo_obj.get_predictions_rmse_mape(algo_name)
  File "/home/aditya_user/time-forecast-app/processing/algorithms.py", line 146, in get_predictions_rmse_mape
    self.rmse2[min_algo] = rmse
AttributeError: 'Algorithms' object has no attribute 'rmse2'

root - ERROR - Error while using ARMA on ship_pt: ﻿ZTRD, prod_hierarchy: 2 B X E, part_number: 10057034
root - ERROR - Traceback (most recent call last):
  File "/home/aditya_user/time-forecast-app/processing/process.py", line 62, in run
    rmse, mape, pred = algo_obj.get_predictions_rmse_mape(algo_name)
  File "/home/aditya_user/time-forecast-app/processing/algorithms.py", line 146, in get_predictions_rmse_mape
    self.rmse2[min_algo] = rmse
AttributeError: 'Algorithms' object has no attribute 'rmse2'

root - ERROR - Error while using SARIMA on ship_pt: ﻿ZTRD, prod_hierarchy: 2 B X E, part_number: 10057034
root - ERROR - Traceback (most recent call last):
  File "/home/aditya_user/time-forecast-app/processing/process.py", line 62, in run
    rmse, mape, pred = algo_obj.get_predictions_rmse_mape(algo_name)
  File "/home/aditya_user/time-forecast-app/processing/algorithms.py", line 146, in get_predictions_rmse_mape
    self.rmse2[min_algo] = rmse
AttributeError: 'Algorithms' object has no attribute 'rmse2'

root - ERROR - Error while using SES on ship_pt: ﻿ZTRD, prod_hierarchy: 2 B X E, part_number: 10057034
root - ERROR - Traceback (most recent call last):
  File "/home/aditya_user/time-forecast-app/processing/process.py", line 62, in run
    rmse, mape, pred = algo_obj.get_predictions_rmse_mape(algo_name)
  File "/home/aditya_user/time-forecast-app/processing/algorithms.py", line 146, in get_predictions_rmse_mape
    self.rmse2[min_algo] = rmse
AttributeError: 'Algorithms' object has no attribute 'rmse2'

root - ERROR - Error while using HWES method on ship_pt: ﻿ZTRD, prod_hierarchy: 2 B X E, part_number: 10057034
root - ERROR - Traceback (most recent call last):
  File "/home/aditya_user/time-forecast-app/processing/process.py", line 147, in run
    algo_obj.rmse_pred[Constants.HWES] = [rmse, predictions]
UnboundLocalError: local variable 'rmse' referenced before assignment

root - ERROR - Error while using ARIMA on ship_pt: ZTRD, prod_hierarchy: 2 B X F, part_number: 10057083
root - ERROR - Traceback (most recent call last):
  File "/home/aditya_user/time-forecast-app/processing/process.py", line 62, in run
    rmse, mape, pred = algo_obj.get_predictions_rmse_mape(algo_name)
  File "/home/aditya_user/time-forecast-app/processing/algorithms.py", line 146, in get_predictions_rmse_mape
    self.rmse2[min_algo] = rmse
AttributeError: 'Algorithms' object has no attribute 'rmse2'

root - ERROR - Error while using MOVING AVERAGE on ship_pt: ZTRD, prod_hierarchy: 2 B X F, part_number: 10057083
root - ERROR - Traceback (most recent call last):
  File "/home/aditya_user/time-forecast-app/processing/process.py", line 62, in run
    rmse, mape, pred = algo_obj.get_predictions_rmse_mape(algo_name)
  File "/home/aditya_user/time-forecast-app/processing/algorithms.py", line 146, in get_predictions_rmse_mape
    self.rmse2[min_algo] = rmse
AttributeError: 'Algorithms' object has no attribute 'rmse2'

root - ERROR - Error while using AR on ship_pt: ZTRD, prod_hierarchy: 2 B X F, part_number: 10057083
root - ERROR - Traceback (most recent call last):
  File "/home/aditya_user/time-forecast-app/processing/process.py", line 62, in run
    rmse, mape, pred = algo_obj.get_predictions_rmse_mape(algo_name)
  File "/home/aditya_user/time-forecast-app/processing/algorithms.py", line 146, in get_predictions_rmse_mape
    self.rmse2[min_algo] = rmse
AttributeError: 'Algorithms' object has no attribute 'rmse2'

root - ERROR - Error while using ARMA on ship_pt: ZTRD, prod_hierarchy: 2 B X F, part_number: 10057083
root - ERROR - Traceback (most recent call last):
  File "/home/aditya_user/time-forecast-app/processing/process.py", line 62, in run
    rmse, mape, pred = algo_obj.get_predictions_rmse_mape(algo_name)
  File "/home/aditya_user/time-forecast-app/processing/algorithms.py", line 146, in get_predictions_rmse_mape
    self.rmse2[min_algo] = rmse
AttributeError: 'Algorithms' object has no attribute 'rmse2'

root - ERROR - Error while using SARIMA on ship_pt: ZTRD, prod_hierarchy: 2 B X F, part_number: 10057083
root - ERROR - Traceback (most recent call last):
  File "/home/aditya_user/time-forecast-app/processing/process.py", line 62, in run
    rmse, mape, pred = algo_obj.get_predictions_rmse_mape(algo_name)
  File "/home/aditya_user/time-forecast-app/processing/algorithms.py", line 146, in get_predictions_rmse_mape
    self.rmse2[min_algo] = rmse
AttributeError: 'Algorithms' object has no attribute 'rmse2'

root - ERROR - Error while using SES on ship_pt: ZTRD, prod_hierarchy: 2 B X F, part_number: 10057083
root - ERROR - Traceback (most recent call last):
  File "/home/aditya_user/time-forecast-app/processing/process.py", line 62, in run
    rmse, mape, pred = algo_obj.get_predictions_rmse_mape(algo_name)
  File "/home/aditya_user/time-forecast-app/processing/algorithms.py", line 146, in get_predictions_rmse_mape
    self.rmse2[min_algo] = rmse
AttributeError: 'Algorithms' object has no attribute 'rmse2'

root - ERROR - Error while using HWES method on ship_pt: ZTRD, prod_hierarchy: 2 B X F, part_number: 10057083
root - ERROR - Traceback (most recent call last):
  File "/home/aditya_user/time-forecast-app/processing/process.py", line 147, in run
    algo_obj.rmse_pred[Constants.HWES] = [rmse, predictions]
UnboundLocalError: local variable 'rmse' referenced before assignment

root - ERROR - Error while using ARIMA on ship_pt: ZTRD, prod_hierarchy: 2 B Y C, part_number: 10076001
root - ERROR - Traceback (most recent call last):
  File "/home/aditya_user/time-forecast-app/processing/process.py", line 62, in run
    rmse, mape, pred = algo_obj.get_predictions_rmse_mape(algo_name)
  File "/home/aditya_user/time-forecast-app/processing/algorithms.py", line 146, in get_predictions_rmse_mape
    self.rmse2[min_algo] = rmse
AttributeError: 'Algorithms' object has no attribute 'rmse2'

root - ERROR - Error while using MOVING AVERAGE on ship_pt: ZTRD, prod_hierarchy: 2 B Y C, part_number: 10076001
root - ERROR - Traceback (most recent call last):
  File "/home/aditya_user/time-forecast-app/processing/process.py", line 62, in run
    rmse, mape, pred = algo_obj.get_predictions_rmse_mape(algo_name)
  File "/home/aditya_user/time-forecast-app/processing/algorithms.py", line 146, in get_predictions_rmse_mape
    self.rmse2[min_algo] = rmse
AttributeError: 'Algorithms' object has no attribute 'rmse2'

root - ERROR - Error while using AR on ship_pt: ZTRD, prod_hierarchy: 2 B Y C, part_number: 10076001
root - ERROR - Traceback (most recent call last):
  File "/home/aditya_user/time-forecast-app/processing/process.py", line 62, in run
    rmse, mape, pred = algo_obj.get_predictions_rmse_mape(algo_name)
  File "/home/aditya_user/time-forecast-app/processing/algorithms.py", line 146, in get_predictions_rmse_mape
    self.rmse2[min_algo] = rmse
AttributeError: 'Algorithms' object has no attribute 'rmse2'

root - ERROR - Error while using ARMA on ship_pt: ZTRD, prod_hierarchy: 2 B Y C, part_number: 10076001
root - ERROR - Traceback (most recent call last):
  File "/home/aditya_user/time-forecast-app/processing/process.py", line 62, in run
    rmse, mape, pred = algo_obj.get_predictions_rmse_mape(algo_name)
  File "/home/aditya_user/time-forecast-app/processing/algorithms.py", line 146, in get_predictions_rmse_mape
    self.rmse2[min_algo] = rmse
AttributeError: 'Algorithms' object has no attribute 'rmse2'

root - ERROR - Error while using SARIMA on ship_pt: ZTRD, prod_hierarchy: 2 B Y C, part_number: 10076001
root - ERROR - Traceback (most recent call last):
  File "/home/aditya_user/time-forecast-app/processing/process.py", line 62, in run
    rmse, mape, pred = algo_obj.get_predictions_rmse_mape(algo_name)
  File "/home/aditya_user/time-forecast-app/processing/algorithms.py", line 146, in get_predictions_rmse_mape
    self.rmse2[min_algo] = rmse
AttributeError: 'Algorithms' object has no attribute 'rmse2'

root - ERROR - Error while using SES on ship_pt: ZTRD, prod_hierarchy: 2 B Y C, part_number: 10076001
root - ERROR - Traceback (most recent call last):
  File "/home/aditya_user/time-forecast-app/processing/process.py", line 62, in run
    rmse, mape, pred = algo_obj.get_predictions_rmse_mape(algo_name)
  File "/home/aditya_user/time-forecast-app/processing/algorithms.py", line 146, in get_predictions_rmse_mape
    self.rmse2[min_algo] = rmse
AttributeError: 'Algorithms' object has no attribute 'rmse2'

root - ERROR - Error while using HWES method on ship_pt: ZTRD, prod_hierarchy: 2 B Y C, part_number: 10076001
root - ERROR - Traceback (most recent call last):
  File "/home/aditya_user/time-forecast-app/processing/process.py", line 147, in run
    algo_obj.rmse_pred[Constants.HWES] = [rmse, predictions]
UnboundLocalError: local variable 'rmse' referenced before assignment

root - ERROR - Error while using ARIMA on ship_pt: ZTRD, prod_hierarchy: 2 A I E, part_number: 10612503
root - ERROR - Traceback (most recent call last):
  File "/home/aditya_user/time-forecast-app/processing/process.py", line 62, in run
    rmse, mape, pred = algo_obj.get_predictions_rmse_mape(algo_name)
  File "/home/aditya_user/time-forecast-app/processing/algorithms.py", line 146, in get_predictions_rmse_mape
    self.rmse2[min_algo] = rmse
AttributeError: 'Algorithms' object has no attribute 'rmse2'

root - ERROR - Error while using MOVING AVERAGE on ship_pt: ZTRD, prod_hierarchy: 2 A I E, part_number: 10612503
root - ERROR - Traceback (most recent call last):
  File "/home/aditya_user/time-forecast-app/processing/process.py", line 62, in run
    rmse, mape, pred = algo_obj.get_predictions_rmse_mape(algo_name)
  File "/home/aditya_user/time-forecast-app/processing/algorithms.py", line 146, in get_predictions_rmse_mape
    self.rmse2[min_algo] = rmse
AttributeError: 'Algorithms' object has no attribute 'rmse2'

root - ERROR - Error while using AR on ship_pt: ZTRD, prod_hierarchy: 2 A I E, part_number: 10612503
root - ERROR - Traceback (most recent call last):
  File "/home/aditya_user/time-forecast-app/processing/process.py", line 62, in run
    rmse, mape, pred = algo_obj.get_predictions_rmse_mape(algo_name)
  File "/home/aditya_user/time-forecast-app/processing/algorithms.py", line 146, in get_predictions_rmse_mape
    self.rmse2[min_algo] = rmse
AttributeError: 'Algorithms' object has no attribute 'rmse2'

root - ERROR - Error while using ARMA on ship_pt: ZTRD, prod_hierarchy: 2 A I E, part_number: 10612503
root - ERROR - Traceback (most recent call last):
  File "/home/aditya_user/time-forecast-app/processing/process.py", line 62, in run
    rmse, mape, pred = algo_obj.get_predictions_rmse_mape(algo_name)
  File "/home/aditya_user/time-forecast-app/processing/algorithms.py", line 146, in get_predictions_rmse_mape
    self.rmse2[min_algo] = rmse
AttributeError: 'Algorithms' object has no attribute 'rmse2'

root - ERROR - Error while using SARIMA on ship_pt: ZTRD, prod_hierarchy: 2 A I E, part_number: 10612503
root - ERROR - Traceback (most recent call last):
  File "/home/aditya_user/time-forecast-app/processing/process.py", line 62, in run
    rmse, mape, pred = algo_obj.get_predictions_rmse_mape(algo_name)
  File "/home/aditya_user/time-forecast-app/processing/algorithms.py", line 146, in get_predictions_rmse_mape
    self.rmse2[min_algo] = rmse
AttributeError: 'Algorithms' object has no attribute 'rmse2'

root - ERROR - Error while using SES on ship_pt: ZTRD, prod_hierarchy: 2 A I E, part_number: 10612503
root - ERROR - Traceback (most recent call last):
  File "/home/aditya_user/time-forecast-app/processing/process.py", line 62, in run
    rmse, mape, pred = algo_obj.get_predictions_rmse_mape(algo_name)
  File "/home/aditya_user/time-forecast-app/processing/algorithms.py", line 146, in get_predictions_rmse_mape
    self.rmse2[min_algo] = rmse
AttributeError: 'Algorithms' object has no attribute 'rmse2'

root - ERROR - Error while using HWES method on ship_pt: ZTRD, prod_hierarchy: 2 A I E, part_number: 10612503
root - ERROR - Traceback (most recent call last):
  File "/home/aditya_user/time-forecast-app/processing/process.py", line 147, in run
    algo_obj.rmse_pred[Constants.HWES] = [rmse, predictions]
UnboundLocalError: local variable 'rmse' referenced before assignment

root - ERROR - Error while using ARIMA on ship_pt: ZTRD, prod_hierarchy: 2 A I F, part_number: 10612504
root - ERROR - Traceback (most recent call last):
  File "/home/aditya_user/time-forecast-app/processing/process.py", line 62, in run
    rmse, mape, pred = algo_obj.get_predictions_rmse_mape(algo_name)
  File "/home/aditya_user/time-forecast-app/processing/algorithms.py", line 146, in get_predictions_rmse_mape
    self.rmse2[min_algo] = rmse
AttributeError: 'Algorithms' object has no attribute 'rmse2'

root - ERROR - Error while using MOVING AVERAGE on ship_pt: ZTRD, prod_hierarchy: 2 A I F, part_number: 10612504
root - ERROR - Traceback (most recent call last):
  File "/home/aditya_user/time-forecast-app/processing/process.py", line 62, in run
    rmse, mape, pred = algo_obj.get_predictions_rmse_mape(algo_name)
  File "/home/aditya_user/time-forecast-app/processing/algorithms.py", line 146, in get_predictions_rmse_mape
    self.rmse2[min_algo] = rmse
AttributeError: 'Algorithms' object has no attribute 'rmse2'

root - ERROR - Error while using AR on ship_pt: ZTRD, prod_hierarchy: 2 A I F, part_number: 10612504
root - ERROR - Traceback (most recent call last):
  File "/home/aditya_user/time-forecast-app/processing/process.py", line 62, in run
    rmse, mape, pred = algo_obj.get_predictions_rmse_mape(algo_name)
  File "/home/aditya_user/time-forecast-app/processing/algorithms.py", line 146, in get_predictions_rmse_mape
    self.rmse2[min_algo] = rmse
AttributeError: 'Algorithms' object has no attribute 'rmse2'

root - ERROR - Error while using ARMA on ship_pt: ZTRD, prod_hierarchy: 2 A I F, part_number: 10612504
root - ERROR - Traceback (most recent call last):
  File "/home/aditya_user/time-forecast-app/processing/process.py", line 62, in run
    rmse, mape, pred = algo_obj.get_predictions_rmse_mape(algo_name)
  File "/home/aditya_user/time-forecast-app/processing/algorithms.py", line 146, in get_predictions_rmse_mape
    self.rmse2[min_algo] = rmse
AttributeError: 'Algorithms' object has no attribute 'rmse2'

root - ERROR - Error while using SARIMA on ship_pt: ZTRD, prod_hierarchy: 2 A I F, part_number: 10612504
root - ERROR - Traceback (most recent call last):
  File "/home/aditya_user/time-forecast-app/processing/process.py", line 62, in run
    rmse, mape, pred = algo_obj.get_predictions_rmse_mape(algo_name)
  File "/home/aditya_user/time-forecast-app/processing/algorithms.py", line 146, in get_predictions_rmse_mape
    self.rmse2[min_algo] = rmse
AttributeError: 'Algorithms' object has no attribute 'rmse2'

root - ERROR - Error while using SES on ship_pt: ZTRD, prod_hierarchy: 2 A I F, part_number: 10612504
root - ERROR - Traceback (most recent call last):
  File "/home/aditya_user/time-forecast-app/processing/process.py", line 62, in run
    rmse, mape, pred = algo_obj.get_predictions_rmse_mape(algo_name)
  File "/home/aditya_user/time-forecast-app/processing/algorithms.py", line 146, in get_predictions_rmse_mape
    self.rmse2[min_algo] = rmse
AttributeError: 'Algorithms' object has no attribute 'rmse2'

root - ERROR - Error while using HWES method on ship_pt: ZTRD, prod_hierarchy: 2 A I F, part_number: 10612504
root - ERROR - Traceback (most recent call last):
  File "/home/aditya_user/time-forecast-app/processing/process.py", line 147, in run
    algo_obj.rmse_pred[Constants.HWES] = [rmse, predictions]
UnboundLocalError: local variable 'rmse' referenced before assignment

